Workbook

Sheet comp
C2: number of errors | D2: =COUNTIF(M5:M327, "recheck") -> 8
D4: diameter | E4: qty | F4: cut length (m) | G4: commercial length | H4: net wt. kg | I4: set | J4: total length m | K4: bars | L4: number of cut length per std. length (m) | M4: check | O4: qty std pcs from cutting list
C5: C1V1 | D5: 32 | E5: 14 | F5: 7 | G5: 7.5 | H5: =((22/(7*4))*(D5^2)/(1000^2))*J5*$B$24 -> 0 | I5: 5 | J5: =E5*F5 -> 98 | K5: =IF(G5=0,0,ROUNDUP((E5/L5)*I5,0)) -> 70 | L5: =ROUNDDOWN(G5/F5, 0) -> 1 | M5: =IF(K5=O5, "MATCH", "RECHECK") -> MATCH | O5: 70
C6: C1V2 | D6: 32 | E6: 14 | F6: 7.87 | G6: 9 | H6: =((22/(7*4))*(D6^2)/(1000^2))*J6*$B$24 -> 0 | I6: 5 | J6: =E6*F6 -> 110.18 | K6: =IF(G6=0,0,ROUNDUP((E6/L6)*I6,0)) -> 70 | L6: =ROUNDDOWN(G6/F6, 0) -> 1 | M6: =IF(K6=O6, "MATCH", "RECHECK") -> MATCH | O6: 70
C7: C1V3 | D7: 32 | E7: 14 | F7: 8.61 | G7: 9 | H7: =((22/(7*4))*(D7^2)/(1000^2))*J7*$B$24 -> 0 | I7: 5 | J7: =E7*F7 -> 120.54 | K7: =IF(G7=0,0,ROUNDUP((E7/L7)*I7,0)) -> 70 | L7: =ROUNDDOWN(G7/F7, 0) -> 1 | M7: =IF(K7=O7, "MATCH", "RECHECK") -> MATCH | O7: 70
C8: C1V4 | D8: 32 | E8: 14 | F8: 11.23 | G8: 12 | H8: =((22/(7*4))*(D8^2)/(1000^2))*J8*$B$24 -> 0 | I8: 5 | J8: =E8*F8 -> 157.22 | K8: =IF(G8=0,0,ROUNDUP((E8/L8)*I8,0)) -> 70 | L8: =ROUNDDOWN(G8/F8, 0) -> 1 | M8: =IF(K8=O8, "MATCH", "RECHECK") -> MATCH | O8: 70
C9: C1T1 | D9: 12 | E9: 215 | F9: 2.75 | G9: 6 | H9: =((22/(7*4))*(D9^2)/(1000^2))*J9*$B$24 -> 0 | I9: 5 | J9: =E9*F9 -> 591.25 | K9: =IF(G9=0,0,ROUNDUP((E9/L9)*I9,0)) -> 538 | L9: =ROUNDDOWN(G9/F9, 0) -> 2 | M9: =IF(K9=O9, "MATCH", "RECHECK") -> MATCH | O9: 538
C10: C1T2 | D10: 12 | E10: 186 | F10: 2.07 | G10: 6 | H10: =((22/(7*4))*(D10^2)/(1000^2))*J10*$B$24 -> 0 | I10: 5 | J10: =E10*F10 -> 385.02 | K10: =IF(G10=0,0,ROUNDUP((E10/L10)*I10,0)) -> 465 | L10: =ROUNDDOWN(G10/F10, 0) -> 2 | M10: =IF(K10=O10, "MATCH", "RECHECK") -> MATCH | O10: 465
C11: C1T3 | D11: 12 | E11: 372 | F11: 0.8 | G11: 6 | H11: =((22/(7*4))*(D11^2)/(1000^2))*J11*$B$24 -> 0 | I11: 5 | J11: =E11*F11 -> 297.6 | K11: =IF(G11=0,0,ROUNDUP((E11/L11)*I11,0)) -> 266 | L11: =ROUNDDOWN(G11/F11, 0) -> 7 | M11: =IF(K11=O11, "MATCH", "RECHECK") -> MATCH | O11: 266
C12: C1T4 | D12: 16 | E12: 162 | F12: 2.83 | G12: 6 | H12: =((22/(7*4))*(D12^2)/(1000^2))*J12*$B$24 -> 0 | I12: 5 | J12: =E12*F12 -> 458.46 | K12: =IF(G12=0,0,ROUNDUP((E12/L12)*I12,0)) -> 405 | L12: =ROUNDDOWN(G12/F12, 0) -> 2 | M12: =IF(K12=O12, "MATCH", "RECHECK") -> MATCH | O12: 405
C13: C1T5 | D13: 16 | E13: 81 | F13: 2.15 | G13: 6 | H13: =((22/(7*4))*(D13^2)/(1000^2))*J13*$B$24 -> 0 | I13: 5 | J13: =E13*F13 -> 174.15 | K13: =IF(G13=0,0,ROUNDUP((E13/L13)*I13,0)) -> 203 | L13: =ROUNDDOWN(G13/F13, 0) -> 2 | M13: =IF(K13=O13, "MATCH", "RECHECK") -> MATCH | O13: 203
C14: C1T6 | D14: 16 | E14: 81 | F14: 0.86 | G14: 6 | H14: =((22/(7*4))*(D14^2)/(1000^2))*J14*$B$24 -> 0 | I14: 5 | J14: =E14*F14 -> 69.66 | K14: =IF(G14=0,0,ROUNDUP((E14/L14)*I14,0)) -> 68 | L14: =ROUNDDOWN(G14/F14, 0) -> 6 | M14: =IF(K14=O14, "MATCH", "RECHECK") -> MATCH | O14: 68
C15: C1T7 | D15: 12 | E15: 82 | F15: 2.16 | G15: 6 | H15: =((22/(7*4))*(D15^2)/(1000^2))*J15*$B$24 -> 0 | I15: 5 | J15: =E15*F15 -> 177.12 | K15: =IF(G15=0,0,ROUNDUP((E15/L15)*I15,0)) -> 205 | L15: =ROUNDDOWN(G15/F15, 0) -> 2 | M15: =IF(K15=O15, "MATCH", "RECHECK") -> MATCH | O15: 205
C16: C1T8 | D16: 12 | E16: 205 | F16: 2.05 | G16: 6 | H16: =((22/(7*4))*(D16^2)/(1000^2))*J16*$B$24 -> 0 | I16: 5 | J16: =E16*F16 -> 420.25 | K16: =IF(G16=0,0,ROUNDUP((E16/L16)*I16,0)) -> 513 | L16: =ROUNDDOWN(G16/F16, 0) -> 2 | M16: =IF(K16=O16, "MATCH", "RECHECK") -> MATCH | O16: 513
C17: C2V1 | D17: 32 | E17: 14 | F17: 8.51 | G17: 9 | H17: =((22/(7*4))*(D15^2)/(1000^2))*J17*$B$24 -> 0 | I17: 4 | J17: =E17*F17 -> 119.14 | K17: =IF(G17=0,0,ROUNDUP((E17/L17)*I17,0)) -> 56 | L17: =ROUNDDOWN(G17/F17, 0) -> 1 | M17: =IF(K17=O17, "MATCH", "RECHECK") -> MATCH | O17: 56
C18: C2V2 | D18: 25 | E18: 14 | F18: 11.26 | G18: 12 | H18: =((22/(7*4))*(D16^2)/(1000^2))*J18*$B$24 -> 0 | I18: 4 | J18: =E18*F18 -> 157.64 | K18: =IF(G18=0,0,ROUNDUP((E18/L18)*I18,0)) -> 56 | L18: =ROUNDDOWN(G18/F18, 0) -> 1 | M18: =IF(K18=O18, "MATCH", "RECHECK") -> MATCH | O18: 56
C19: C2V3 | D19: 32 | E19: 14 | F19: 6.96 | G19: 7.5 | H19: =((22/(7*4))*(D19^2)/(1000^2))*J19*$B$24 -> 0 | I19: 4 | J19: =E19*F19 -> 97.44 | K19: =IF(G19=0,0,ROUNDUP((E19/L19)*I19,0)) -> 56 | L19: =ROUNDDOWN(G19/F19, 0) -> 1 | M19: =IF(K19=O19, "MATCH", "RECHECK") -> MATCH | O19: 56
C20: C2V4 | D20: 25 | E20: 14 | F20: 11.95 | G20: 12 | H20: =((22/(7*4))*(D20^2)/(1000^2))*J20*$B$24 -> 0 | I20: 4 | J20: =E20*F20 -> 167.3 | K20: =IF(G20=0,0,ROUNDUP((E20/L20)*I20,0)) -> 56 | L20: =ROUNDDOWN(G20/F20, 0) -> 1 | M20: =IF(K20=O20, "MATCH", "RECHECK") -> MATCH | O20: 56
C21: C2V5 | D21: 32 | E21: 4 | F21: 5.97 | G21: 6 | H21: =((22/(7*4))*(D21^2)/(1000^2))*J21*$B$24 -> 0 | I21: 4 | J21: =E21*F21 -> 23.88 | K21: =IF(G21=0,0,ROUNDUP((E21/L21)*I21,0)) -> 16 | L21: =ROUNDDOWN(G21/F21, 0) -> 1 | M21: =IF(K21=O21, "MATCH", "RECHECK") -> MATCH | O21: 16
C22: C2V6 | D22: 25 | E22: 14 | F22: 1.36 | G22: 6 | H22: =((22/(7*4))*(D22^2)/(1000^2))*J22*$B$24 -> 0 | I22: 4 | J22: =E22*F22 -> 19.04 | K22: =IF(G22=0,0,ROUNDUP((E22/L22)*I22,0)) -> 14 | L22: =ROUNDDOWN(G22/F22, 0) -> 4 | M22: =IF(K22=O22, "MATCH", "RECHECK") -> MATCH | O22: 14
C23: C2T1 | D23: 12 | E23: 63 | F23: 2.75 | G23: 6 | H23: =((22/(7*4))*(D23^2)/(1000^2))*J23*$B$24 -> 0 | I23: 4 | J23: =E23*F23 -> 173.25 | K23: =IF(G23=0,0,ROUNDUP((E23/L23)*I23,0)) -> 126 | L23: =ROUNDDOWN(G23/F23, 0) -> 2 | M23: =IF(K23=O23, "MATCH", "RECHECK") -> MATCH | O23: 126
C24: C2T2 | D24: 12 | E24: 63 | F24: 2.16 | G24: 6 | H24: =((22/(7*4))*(D24^2)/(1000^2))*J24*$B$24 -> 0 | I24: 4 | J24: =E24*F24 -> 136.08 | K24: =IF(G24=0,0,ROUNDUP((E24/L24)*I24,0)) -> 126 | L24: =ROUNDDOWN(G24/F24, 0) -> 2 | M24: =IF(K24=O24, "MATCH", "RECHECK") -> MATCH | O24: 126
C25: C2T3 | D25: 12 | E25: 63 | F25: 0.8 | G25: 6 | H25: =((22/(7*4))*(D25^2)/(1000^2))*J25*$B$24 -> 0 | I25: 4 | J25: =E25*F25 -> 50.4 | K25: =IF(G25=0,0,ROUNDUP((E25/L25)*I25,0)) -> 36 | L25: =ROUNDDOWN(G25/F25, 0) -> 7 | M25: =IF(K25=O25, "MATCH", "RECHECK") -> MATCH | O25: 36
C26: C2T4 | D26: 12 | E26: 55 | F26: 2.75 | G26: 6 | H26: =((22/(7*4))*(D26^2)/(1000^2))*J26*$B$24 -> 0 | I26: 4 | J26: =E26*F26 -> 151.25 | K26: =IF(G26=0,0,ROUNDUP((E26/L26)*I26,0)) -> 110 | L26: =ROUNDDOWN(G26/F26, 0) -> 2 | M26: =IF(K26=O26, "MATCH", "RECHECK") -> MATCH | O26: 110
C27: C2T5 | D27: 12 | E27: 110 | F27: 2.06 | G27: 6 | H27: =((22/(7*4))*(D27^2)/(1000^2))*J27*$B$24 -> 0 | I27: 4 | J27: =E27*F27 -> 226.6 | K27: =IF(G27=0,0,ROUNDUP((E27/L27)*I27,0)) -> 220 | L27: =ROUNDDOWN(G27/F27, 0) -> 2 | M27: =IF(K27=O27, "MATCH", "RECHECK") -> MATCH | O27: 220
C28: C2T6 | D28: 12 | E28: 110 | F28: 0.52 | G28: 6 | H28: =((22/(7*4))*(D28^2)/(1000^2))*J28*$B$24 -> 0 | I28: 4 | J28: =E28*F28 -> 57.2 | K28: =IF(G28=0,0,ROUNDUP((E28/L28)*I28,0)) -> 40 | L28: =ROUNDDOWN(G28/F28, 0) -> 11 | M28: =IF(K28=O28, "MATCH", "RECHECK") -> MATCH | O28: 40
C29: C2T7 | D29: 10 | E29: 110 | F29: 2.72 | G29: 6 | H29: =((22/(7*4))*(D29^2)/(1000^2))*J29*$B$24 -> 0 | I29: 4 | J29: =E29*F29 -> 299.2 | K29: =IF(G29=0,0,ROUNDUP((E29/L29)*I29,0)) -> 220 | L29: =ROUNDDOWN(G29/F29, 0) -> 2 | M29: =IF(K29=O29, "MATCH", "RECHECK") -> MATCH | O29: 220
C30: C2T8 | D30: 10 | E30: 220 | F30: 2.02 | G30: 6 | H30: =((22/(7*4))*(D30^2)/(1000^2))*J30*$B$24 -> 0 | I30: 4 | J30: =E30*F30 -> 444.4 | K30: =IF(G30=0,0,ROUNDUP((E30/L30)*I30,0)) -> 440 | L30: =ROUNDDOWN(G30/F30, 0) -> 2 | M30: =IF(K30=O30, "MATCH", "RECHECK") -> MATCH | O30: 440
... C254: C18T1 | D254: 10 | E254: 63 | F254: 2.72 | G254: 6 | H254: =((22/(7*4))*(D254^2)/(1000^2))*J254*$B$24 -> 0 | I254: 1 | J254: =E254*F254 -> 171.36 | K254: =IF(G254=0,0,ROUNDUP((E254/L254)*I254,0)) -> 32 | L254: =ROUNDDOWN(G254/F254, 0) -> 2 | M254: =IF(K254=O254, "MATCH", "RECHECK") -> MATCH | O254: 32
C255: C18T2 | D255: 10 | E255: 126 | F255: 1.82 | G255: 6 | H255: =((22/(7*4))*(D254^2)/(1000^2))*J255*$B$24 -> 0 | I255: 1 | J255: =E255*F255 -> 229.32 | K255: =IF(G255=0,0,ROUNDUP((E255/L255)*I255,0)) -> 42 | L255: =ROUNDDOWN(G255/F255, 0) -> 3 | M255: =IF(K255=O255, "MATCH", "RECHECK") -> MATCH | O255: 42
C256: C18T3 | D256: 10 | E256: 63 | F256: 2.02 | G256: 6 | H256: =((22/(7*4))*(D255^2)/(1000^2))*J256*$B$24 -> 0 | I256: 1 | J256: =E256*F256 -> 127.26 | K256: =IF(G256=0,0,ROUNDUP((E256/L256)*I256,0)) -> 32 | L256: =ROUNDDOWN(G256/F256, 0) -> 2 | M256: =IF(K256=O256, "MATCH", "RECHECK") -> MATCH | O256: 32
C257: C18T4 | D257: 10 | E257: 252 | F257: 0.77 | G257: 6 | H257: =((22/(7*4))*(D256^2)/(1000^2))*J257*$B$24 -> 0 | I257: 1 | J257: =E257*F257 -> 194.04 | K257: =IF(G257=0,0,ROUNDUP((E257/L257)*I257,0)) -> 36 | L257: =ROUNDDOWN(G257/F257, 0) -> 7 | M257: =IF(K257=O257, "MATCH", "RECHECK") -> MATCH | O257: 36
C258: C18T5 | D258: 12 | E258: 195 | F258: 2.77 | G258: 7.5 | H258: =((22/(7*4))*(D257^2)/(1000^2))*J258*$B$24 -> 0 | I258: 1 | J258: =E258*F258 -> 540.15 | K258: =IF(G258=0,0,ROUNDUP((E258/L258)*I258,0)) -> 98 | L258: =ROUNDDOWN(G258/F258, 0) -> 2 | M258: =IF(K258=O258, "MATCH", "RECHECK") -> MATCH | O258: 98
C259: C18T6 | D259: 12 | E259: 324 | F259: 2.08 | G259: 6 | H259: =((22/(7*4))*(D258^2)/(1000^2))*J259*$B$24 -> 0 | I259: 1 | J259: =E259*F259 -> 673.92 | K259: =IF(G259=0,0,ROUNDUP((E259/L259)*I259,0)) -> 162 | L259: =ROUNDDOWN(G259/F259, 0) -> 2 | M259: =IF(K259=O259, "MATCH", "RECHECK") -> MATCH | O259: 162
C260: C18T7 | D260: 12 | E260: 324 | F260: 0.8 | G260: 6 | H260: =((22/(7*4))*(D258^2)/(1000^2))*J260*$B$24 -> 0 | I260: 1 | J260: =E260*F260 -> 259.2 | K260: =IF(G260=0,0,ROUNDUP((E260/L260)*I260,0)) -> 47 | L260: =ROUNDDOWN(G260/F260, 0) -> 7 | M260: =IF(K260=O260, "MATCH", "RECHECK") -> MATCH | O260: 47
C261: C18T8 | D261: 12 | E261: 66 | F261: 1.66 | G261: 6 | H261: =((22/(7*4))*(D259^2)/(1000^2))*J261*$B$24 -> 0 | I261: 1 | J261: =E261*F261 -> 109.56 | K261: =IF(G261=0,0,ROUNDUP((E261/L261)*I261,0)) -> 22 | L261: =ROUNDDOWN(G261/F261, 0) -> 3 | M261: =IF(K261=O261, "MATCH", "RECHECK") -> MATCH | O261: 22
C262: C19V1 | D262: 32 | E262: 18 | F262: 4.23 | G262: 6 | H262: =((22/(7*4))*(D262^2)/(1000^2))*J262*$B$24 -> 0 | I262: 1 | J262: =E262*F262 -> 76.14 | K262: =IF(G262=0,0,ROUNDUP((E262/L262)*I262,0)) -> 18 | L262: =ROUNDDOWN(G262/F262, 0) -> 1 | M262: =IF(K262=O262, "MATCH", "RECHECK") -> MATCH | O262: 18
C263: C19V2 | D263: 32 | E263: 18 | F263: 12 | G263: 12 | H263: =((22/(7*4))*(D263^2)/(1000^2))*J263*$B$24 -> 0 | I263: 1 | J263: =E263*F263 -> 216 | K263: =IF(G263=0,0,ROUNDUP((E263/L263)*I263,0)) -> 18 | L263: =ROUNDDOWN(G263/F263, 0) -> 1 | M263: =IF(K263=O263, "MATCH", "RECHECK") -> MATCH | O263: 18
C264: C19V3 | D264: 25 | E264: 10 | F264: 4.31 | G264: 6 | H264: =((22/(7*4))*(D264^2)/(1000^2))*J264*$B$24 -> 0 | I264: 1 | J264: =E264*F264 -> 43.1 | K264: =IF(G264=0,0,ROUNDUP((E264/L264)*I264,0)) -> 10 | L264: =ROUNDDOWN(G264/F264, 0) -> 1 | M264: =IF(K264=O264, "MATCH", "RECHECK") -> MATCH | O264: 10
C265: C19V4 | D265: 32 | E265: 18 | F265: 8.53 | G265: 9 | H265: =((22/(7*4))*(D265^2)/(1000^2))*J265*$B$24 -> 0 | I265: 1 | J265: =E265*F265 -> 153.54 | K265: =IF(G265=0,0,ROUNDUP((E265/L265)*I265,0)) -> 18 | L265: =ROUNDDOWN(G265/F265, 0) -> 1 | M265: =IF(K265=O265, "MATCH", "RECHECK") -> MATCH | O265: 18
...

Sheet backup
D2: vertical bars
D3: diameter | E3: qty | F3: cut length | G3: commercial length | H3: net wt. kg | J3: total length m | K3: bars | L3: number of cut length per std. length
C4: c21 | D4: 32 | E4: 14 | F4: 7 | G4: 7.5 | H4: =((22/(7*4))*(D4^2)/(1000^2))*J4*solver!$B$24 -> 618.9568 | J4: =E4*F4 -> 98 | K4: =IF(G4=0,0,ROUNDUP(E4/L4,0)) -> 14 | L4: =ROUNDDOWN(G4/F4, 0) -> 1
D5: 25 | E5: 10 | F5: 11.95 | G5: 12 | H5: =((22/(7*4))*(D5^2)/(1000^2))*J5*solver!$B$24 -> 460.66183 | J5: =E5*F5 -> 119.5 | K5: =IF(G5=0,0,ROUNDUP(E5/L5,0)) -> 10 | L5: =ROUNDDOWN(G5/F5, 0) -> 1
D6: 25 | E6: 10 | F6: 1.86 | G6: 7.5 | H6: =((22/(7*4))*(D6^2)/(1000^2))*J6*solver!$B$24 -> 71.701339 | J6: =E6*F6 -> 18.6 | K6: =IF(G6=0,0,ROUNDUP(E6/L6,0)) -> 3 | L6: =ROUNDDOWN(G6/F6, 0) -> 4
D7: 32 | E7: 14 | F7: 8.29 | G7: 9 | H7: =((22/(7*4))*(D7^2)/(1000^2))*J7*solver!$B$24 -> 733.0217 | J7: =E7*F7 -> 116.06 | K7: =IF(G7=0,0,ROUNDUP(E7/L7,0)) -> 14 | L7: =ROUNDDOWN(G7/F7, 0) -> 1
D8: 25 | E8: 10 | F8: 11.02 | G8: 12 | H8: =((22/(7*4))*(D8^2)/(1000^2))*J8*solver!$B$24 -> 424.81116 | J8: =E8*F8 -> 110.2 | K8: =IF(G8=0,0,ROUNDUP(E8/L8,0)) -> 10 | L8: =ROUNDDOWN(G8/F8, 0) -> 1
D9: 25 | E9: 4 | F9: 8.31 | G9: 9 | H9: =((22/(7*4))*(D9^2)/(1000^2))*J9*solver!$B$24 -> 128.13723 | J9: =E9*F9 -> 33.24 | K9: =IF(G9=0,0,ROUNDUP(E9/L9,0)) -> 4 | L9: =ROUNDDOWN(G9/F9, 0) -> 1
D10: 25 | E10: 4 | F10: 7.03 | G10: 7.5 | H10: =((22/(7*4))*(D10^2)/(1000^2))*J10*solver!$B$24 -> 108.40009 | J10: =E10*F10 -> 28.12 | K10: =IF(G10=0,0,ROUNDUP(E10/L10,0)) -> 4 | L10: =ROUNDDOWN(G10/F10, 0) -> 1
D11: 16 | E11: 20 | F11: 4.255 | G11: 6 | H11: =((22/(7*4))*(D11^2)/(1000^2))*J11*solver!$B$24 -> 134.37047 | J11: =E11*F11 -> 85.1 | K11: =IF(G11=0,0,ROUNDUP(E11/L11,0)) -> 20 | L11: =ROUNDDOWN(G11/F11, 0) -> 1
D12: 10 | E12: 201 | F12: 2.12 | G12: 6 | H12: =((22/(7*4))*(D12^2)/(1000^2))*J12*solver!$B$24 -> 262.82473 | J12: =E12*F12 -> 426.12 | K12: =IF(G12=0,0,ROUNDUP(E12/L12,0)) -> 101 | L12: =ROUNDDOWN(G12/F12, 0) -> 2
D13: 10 | E13: 126 | F13: 1.61 | G13: 7.5 | H13: =((22/(7*4))*(D13^2)/(1000^2))*J13*solver!$B$24 -> 125.12115 | J13: =E13*F13 -> 202.86 | K13: =IF(G13=0,0,ROUNDUP(E13/L13,0)) -> 32 | L13: =ROUNDDOWN(G13/F13, 0) -> 4
D14: 10 | E14: 126 | F14: 0.62 | G14: 6 | H14: =((22/(7*4))*(D14^2)/(1000^2))*J14*solver!$B$24 -> 48.1833 | J14: =E14*F14 -> 78.12 | K14: =IF(G14=0,0,ROUNDUP(E14/L14,0)) -> 14 | L14: =ROUNDDOWN(G14/F14, 0) -> 9
D15: 10 | E15: 56 | F15: 1.6 | G15: 7.5 | H15: =((22/(7*4))*(D15^2)/(1000^2))*J15*solver!$B$24 -> 55.264 | J15: =E15*F15 -> 89.6 | K15: =IF(G15=0,0,ROUNDUP(E15/L15,0)) -> 14 | L15: =ROUNDDOWN(G15/F15, 0) -> 4
D16: 10 | E16: 166 | F16: 0.62 | G16: 7.5 | H16: =((22/(7*4))*(D16^2)/(1000^2))*J16*solver!$B$24 -> 63.479586 | J16: =E16*F16 -> 102.92 | K16: =IF(G16=0,0,ROUNDUP(E16/L16,0)) -> 14 | L16: =ROUNDDOWN(G16/F16, 0) -> 12
... D18: 10 | E18: 40 | F18: 1.4 | G18: 6 | H18: =((22/(7*4))*(D18^2)/(1000^2))*J18*solver!$B$24 -> 34.54 | J18: =E18*F18 -> 56 | K18: =IF(G18=0,0,ROUNDUP(E18/L18,0)) -> 10 | L18: =ROUNDDOWN(G18/F18, 0) -> 4
D19: 10 | E19: 80 | F19: 0.95 | G19: 6 | H19: =((22/(7*4))*(D19^2)/(1000^2))*J19*solver!$B$24 -> 46.875714 | J19: =E19*F19 -> 76 | K19: =IF(G19=0,0,ROUNDUP(E19/L19,0)) -> 14 | L19: =ROUNDDOWN(G19/F19, 0) -> 6 | M19: checked
C20: c22 | D20: 32 | E20: 14 | F20: 7 | G20: 9 | H20: =((22/(7*4))*(D20^2)/(1000^2))*J20*solver!$B$24 -> 618.9568 | J20: =E20*F20 -> 98 | K20: =IF(G20=0,0,ROUNDUP(E20/L20,0)) -> 14 | L20: =ROUNDDOWN(G20/F20, 0) -> 1
D21: 25 | E21: 6 | F21: 11.95 | G21: 12 | H21: =((22/(7*4))*(D21^2)/(1000^2))*J21*solver!$B$24 -> 276.3971 | J21: =E21*F21 -> 71.7 | K21: =IF(G21=0,0,ROUNDUP(E21/L21,0)) -> 6 | L21: =ROUNDDOWN(G21/F21, 0) -> 1
D22: 32 | E22: 14 | F22: 8.31 | G22: 9 | H22: =((22/(7*4))*(D22^2)/(1000^2))*J22*solver!$B$24 -> 734.79014 | J22: =E22*F22 -> 116.34 | K22: =IF(G22=0,0,ROUNDUP(E22/L22,0)) -> 14 | L22: =ROUNDDOWN(G22/F22, 0) -> 1
D23: 25 | E23: 6 | F23: 11.11 | G23: 12 | H23: =((22/(7*4))*(D23^2)/(1000^2))*J23*solver!$B$24 -> 256.96835 | J23: =E23*F23 -> 66.66 | K23: =IF(G23=0,0,ROUNDUP(E23/L23,0)) -> 6 | L23: =ROUNDDOWN(G23/F23, 0) -> 1
D24: 25 | E24: 8 | F24: 8.31 | G24: 9 | H24: =((22/(7*4))*(D24^2)/(1000^2))*J24*solver!$B$24 -> 256.27446 | J24: =E24*F24 -> 66.48 | K24: =IF(G24=0,0,ROUNDUP(E24/L24,0)) -> 8 | L24: =ROUNDDOWN(G24/F24, 0) -> 1
D25: 25 | E25: 8 | F25: 7.06 | G25: 7.5 | H25: =((22/(7*4))*(D25^2)/(1000^2))*J25*solver!$B$24 -> 217.72536 | J25: =E25*F25 -> 56.48 | K25: =IF(G25=0,0,ROUNDUP(E25/L25,0)) -> 8 | L25: =ROUNDDOWN(G25/F25, 0) -> 1
D26: 25 | E26: 6 | F26: 1.66 | G26: 6 | H26: =((22/(7*4))*(D26^2)/(1000^2))*J26*solver!$B$24 -> 38.394911 | J26: =E26*F26 -> 9.96 | K26: =IF(G26=0,0,ROUNDUP(E26/L26,0)) -> 2 | L26: =ROUNDDOWN(G26/F26, 0) -> 3
D27: 16 | E27: 12 | F27: 4.08 | G27: 9 | H27: =((22/(7*4))*(D27^2)/(1000^2))*J27*solver!$B$24 -> 77.306441 | J27: =E27*F27 -> 48.96 | K27: =IF(G27=0,0,ROUNDUP(E27/L27,0)) -> 6 | L27: =ROUNDDOWN(G27/F27, 0) -> 2
D28: 10 | E28: 200 | F28: 2.12 | G28: 7.5 | H28: =((22/(7*4))*(D28^2)/(1000^2))*J28*solver!$B$24 -> 261.51714 | J28: =E28*F28 -> 424 | K28: =IF(G28=0,0,ROUNDUP(E28/L28,0)) -> 67 | L28: =ROUNDDOWN(G28/F28, 0) -> 3
D29: 10 | E29: 126 | F29: 1.61 | G29: 7.5 | H29: =((22/(7*4))*(D29^2)/(1000^2))*J29*solver!$B$24 -> 125.12115 | J29: =E29*F29 -> 202.86 | K29: =IF(G29=0,0,ROUNDUP(E29/L29,0)) -> 32 | L29: =ROUNDDOWN(G29/F29, 0) -> 4
D30: 10 | E30: 318 | F30: 0.62 | G30: 6 | H30: =((22/(7*4))*(D30^2)/(1000^2))*J30*solver!$B$24 -> 121.60547 | J30: =E30*F30 -> 197.16 | K30: =IF(G30=0,0,ROUNDUP(E30/L30,0)) -> 36 | L30: =ROUNDDOWN(G30/F30, 0) -> 9
D31: 10 | E31: 192 | F31: 1.6 | G31: 7.5 | H31: =((22/(7*4))*(D31^2)/(1000^2))*J31*solver!$B$24 -> 189.47657 | J31: =E31*F31 -> 307.2 | K31: =IF(G31=0,0,ROUNDUP(E31/L31,0)) -> 48 | L31: =ROUNDDOWN(G31/F31, 0) -> 4
D32: 10 | E32: 82 | F32: 1.67 | G32: 7.5 | H32: =((22/(7*4))*(D32^2)/(1000^2))*J32*solver!$B$24 -> 84.462636 | J32: =E32*F32 -> 136.94 | K32: =IF(G32=0,0,ROUNDUP(E32/L32,0)) -> 21 | L32: =ROUNDDOWN(G32/F32, 0) -> 4
D33: 10 | E33: 40 | F33: 1.4 | G33: 6 | H33: =((22/(7*4))*(D33^2)/(1000^2))*J33*solver!$B$24 -> 34.54 | J33: =E33*F33 -> 56 | K33: =IF(G33=0,0,ROUNDUP(E33/L33,0)) -> 10 | L33: =ROUNDDOWN(G33/F33, 0) -> 4
D34: 10 | E34: 80 | F34: 1.02 | G34: 6 | H34: =((22/(7*4))*(D34^2)/(1000^2))*J34*solver!$B$24 -> 50.329714 | J34: =E34*F34 -> 81.6 | K34: =IF(G34=0,0,ROUNDUP(E34/L34,0)) -> 16 | L34: =ROUNDDOWN(G34/F34, 0) -> 5 | M34: checked
C35: c23 | D35: 32 | E35: 14 | F35: 7 | G35: 7.5 | H35: =((22/(7*4))*(D35^2)/(1000^2))*J35*solver!$B$24 -> 618.9568 | J35: =E35*F35 -> 98 | K35: =IF(G35=0,0,ROUNDUP(E35/L35,0)) -> 14 | L35: =ROUNDDOWN(G35/F35, 0) -> 1
D36: 25 | E36: 10 | F36: 11.95 | G36: 12 | H36: =((22/(7*4))*(D36^2)/(1000^2))*J36*solver!$B$24 -> 460.66183 | J36: =E36*F36 -> 119.5 | K36: =IF(G36=0,0,ROUNDUP(E36/L36,0)) -> 10 | L36: =ROUNDDOWN(G36/F36, 0) -> 1
D37: 32 | E37: 14 | F37: 8.31 | G37: 9 | H37: =((22/(7*4))*(D37^2)/(1000^2))*J37*solver!$B$24 -> 734.79014 | J37: =E37*F37 -> 116.34 | K37: =IF(G37=0,0,ROUNDUP(E37/L37,0)) -> 14 | L37: =ROUNDDOWN(G37/F37, 0) -> 1
D38: 25 | E38: 10 | F38: 11.06 | G38: 12 | H38: =((22/(7*4))*(D38^2)/(1000^2))*J38*solver!$B$24 -> 426.35313 | J38: =E38*F38 -> 110.6 | K38: =IF(G38=0,0,ROUNDUP(E38/L38,0)) -> 10 | L38: =ROUNDDOWN(G38/F38, 0) -> 1
D39: 25 | E39: 4 | F39: 8.31 | G39: 9 | H39: =((22/(7*4))*(D39^2)/(1000^2))*J39*solver!$B$24 -> 128.13723 | J39: =E39*F39 -> 33.24 | K39: =IF(G39=0,0,ROUNDUP(E39/L39,0)) -> 4 | L39: =ROUNDDOWN(G39/F39, 0) -> 1
D40: 25 | E40: 4 | F40: 7.06 | G40: 7.5 | H40: =((22/(7*4))*(D40^2)/(1000^2))*J40*solver!$B$24 -> 108.86268 | J40: =E40*F40 -> 28.24 | K40: =IF(G40=0,0,ROUNDUP(E40/L40,0)) -> 4 | L40: =ROUNDDOWN(G40/F40, 0) -> 1
D41: 16 | E41: 12 | F41: 4.08 | G41: 6 | H41: =((22/(7*4))*(D41^2)/(1000^2))*J41*solver!$B$24 -> 77.306441 | J41: =E41*F41 -> 48.96 | K41: =IF(G41=0,0,ROUNDUP(E41/L41,0)) -> 12 | L41: =ROUNDDOWN(G41/F41, 0) -> 1
D42: 25 | E42: 4 | F42: 1.66 | G42: 7.5 | H42: =((22/(7*4))*(D42^2)/(1000^2))*J42*solver!$B$24 -> 25.596607 | J42: =E42*F42 -> 6.64 | K42: =IF(G42=0,0,ROUNDUP(E42/L42,0)) -> 1 | L42: =ROUNDDOWN(G42/F42, 0) -> 4
...

Sheet solver
G6: INPUT | M6: diameter | N6: qty | O6: cut length | P6: commercial length | Q6: net wt. kg | R6: set | S6: total length m | T6: bars | U6: number of cut length per std. length | V6: check | X6: qty std pcs
G7: Column Height | H7: 7 | L7: C1V1 | M7: 32 | N7: 14 | O7: 7 | P7: 7.5 | Q7: =((22/(7*4))*(M7^2)/(1000^2))*S7*$B$24 -> 618.9568 | R7: 5 | S7: =N7*O7 -> 98 | T7: =IF(P7=0,0,ROUNDUP((N7/U7)*R7,0)) -> 70 | U7: =ROUNDDOWN(P7/O7, 0) -> 1 | V7: =IF(T7=X7, "MATCH", "RECHECK") -> MATCH | X7: 70
G8: Number of Columns | H8: 1 | L8: C1V2 | M8: 32 | N8: 14 | O8: 7.87 | P8: 9 | Q8: =((22/(7*4))*(M8^2)/(1000^2))*S8*$B$24 -> 695.88429 | R8: 5 | S8: =N8*O8 -> 110.18 | T8: =IF(P8=0,0,ROUNDUP((N8/U8)*R8,0)) -> 70 | U8: =ROUNDDOWN(P8/O8, 0) -> 1 | V8: =IF(T8=X8, "MATCH", "RECHECK") -> MATCH | X8: 70
G9: Reinforcement bar Diameter required | L9: C1V3 | M9: 32 | N9: 14 | O9: 8.61 | P9: 9 | Q9: =((22/(7*4))*(M9^2)/(1000^2))*S9*$B$24 -> 761.31686 | R9: 5 | S9: =N9*O9 -> 120.54 | T9: =IF(P9=0,0,ROUNDUP((N9/U9)*R9,0)) -> 70 | U9: =ROUNDDOWN(P9/O9, 0) -> 1 | V9: =IF(T9=X9, "MATCH", "RECHECK") -> MATCH | X9: 70
G10: Column Dimension 1 L | L10: C1V4 | M10: 32 | N10: 14 | O10: 11.23 | P10: 12 | Q10: =((22/(7*4))*(M10^2)/(1000^2))*S10*$B$24 -> 992.98355 | R10: 5 | S10: =N10*O10 -> 157.22 | T10: =IF(P10=0,0,ROUNDUP((N10/U10)*R10,0)) -> 70 | U10: =ROUNDDOWN(P10/O10, 0) -> 1 | V10: =IF(T10=X10, "MATCH", "RECHECK") -> MATCH | X10: 70
G11: Column Dimension 2 W | L11: C1T1 | M11: 12 | N11: 215 | O11: 2.75 | P11: 6 | Q11: =((22/(7*4))*(M11^2)/(1000^2))*S11*$B$24 -> 525.13136 | R11: 5 | S11: =N11*O11 -> 591.25 | T11: =IF(P11=0,0,ROUNDUP((N11/U11)*R11,0)) -> 538 | U11: =ROUNDDOWN(P11/O11, 0) -> 2 | V11: =IF(T11=X11, "MATCH", "RECHECK") -> MATCH | X11: 538
G12: Number of Vertical Bars | H12: 14 | L12: C1T2 | M12: 12 | N12: 186 | O12: 2.07 | P12: 6 | Q12: =((22/(7*4))*(M12^2)/(1000^2))*S12*$B$24 -> 341.96376 | R12: 5 | S12: =N12*O12 -> 385.02 | T12: =IF(P12=0,0,ROUNDUP((N12/U12)*R12,0)) -> 465 | U12: =ROUNDDOWN(P12/O12, 0) -> 2 | V12: =IF(T12=X12, "MATCH", "RECHECK") -> MATCH | X12: 465
G13: Stirrup bar diameter required | L13: C1T3 | M13: 12 | N13: 372 | O13: 0.8 | P13: 6 | Q13: =((22/(7*4))*(M13^2)/(1000^2))*S13*$B$24 -> 264.31982 | R13: 5 | S13: =N13*O13 -> 297.6 | T13: =IF(P13=0,0,ROUNDUP((N13/U13)*R13,0)) -> 266 | U13: =ROUNDDOWN(P13/O13, 0) -> 7 | V13: =IF(T13=X13, "MATCH", "RECHECK") -> MATCH | X13: 266
G14: stirrup spacing | L14: C1T4 | M14: 16 | N14: 162 | O14: 2.83 | P14: 6 | Q14: =((22/(7*4))*(M14^2)/(1000^2))*S14*$B$24 -> 723.89524 | R14: 5 | S14: =N14*O14 -> 458.46 | T14: =IF(P14=0,0,ROUNDUP((N14/U14)*R14,0)) -> 405 | U14: =ROUNDDOWN(P14/O14, 0) -> 2 | V14: =IF(T14=X14, "MATCH", "RECHECK") -> MATCH | X14: 405
L15: C1T5 | M15: 16 | N15: 81 | O15: 2.15 | P15: 6 | Q15: =((22/(7*4))*(M15^2)/(1000^2))*S15*$B$24 -> 274.97787 | R15: 5 | S15: =N15*O15 -> 174.15 | T15: =IF(P15=0,0,ROUNDUP((N15/U15)*R15,0)) -> 203 | U15: =ROUNDDOWN(P15/O15, 0) -> 2 | V15: =IF(T15=X15, "MATCH", "RECHECK") -> MATCH | X15: 203
G16: Use End Hook: | H16: 0.455 | L16: C1T6 | M16: 16 | N16: 81 | O16: 0.86 | P16: 6 | Q16: =((22/(7*4))*(M16^2)/(1000^2))*S16*$B$24 -> 109.99115 | R16: 5 | S16: =N16*O16 -> 69.66 | T16: =IF(P16=0,0,ROUNDUP((N16/U16)*R16,0)) -> 68 | U16: =ROUNDDOWN(P16/O16, 0) -> 6 | V16: =IF(T16=X16, "MATCH", "RECHECK") -> MATCH | X16: 68
G17: commercial length of bar | H17: 7.5 | L17: C1T7 | M17: 12 | N17: 82 | O17: 2.16 | P17: 6 | Q17: =((22/(7*4))*(M17^2)/(1000^2))*S17*$B$24 -> 157.31292 | R17: 5 | S17: =N17*O17 -> 177.12 | T17: =IF(P17=0,0,ROUNDUP((N17/U17)*R17,0)) -> 205 | U17: =ROUNDDOWN(P17/O17, 0) -> 2 | V17: =IF(T17=X17, "MATCH", "RECHECK") -> MATCH | X17: 205
G18: Total length of each bars should be more than or equal to: | H18: 7 | L18: C1T8 | M18: 12 | N18: 205 | O18: 2.05 | P18: 6 | Q18: =((22/(7*4))*(M18^2)/(1000^2))*S18*$B$24 -> 373.25404 | R18: 5 | S18: =N18*O18 -> 420.25 | T18: =IF(P18=0,0,ROUNDUP((N18/U18)*R18,0)) -> 513 | U18: =ROUNDDOWN(P18/O18, 0) -> 2 | V18: =IF(T18=X18, "MATCH", "RECHECK") -> MATCH | X18: 513
G19: Total Number of Vertical Bars | H19: =(H7+H16)*H12*H8 -> 104.37 | L19: C2V1 | M19: 32 | N19: 14 | O19: 8.51 | P19: 9 | Q19: =((22/(7*4))*(M17^2)/(1000^2))*S19*$B$24 -> 105.81674 | R19: 4 | S19: =N19*O19 -> 119.14 | T19: =IF(P19=0,0,ROUNDUP((N19/U19)*R19,0)) -> 56 | U19: =ROUNDDOWN(P19/O19, 0) -> 1 | V19: =IF(T19=X19, "MATCH", "RECHECK") -> MATCH | X19: 56
L20: C2V2 | M20: 25 | N20: 14 | O20: 11.26 | P20: 12 | Q20: =((22/(7*4))*(M18^2)/(1000^2))*S20*$B$24 -> 140.01134 | R20: 4 | S20: =N20*O20 -> 157.64 | T20: =IF(P20=0,0,ROUNDUP((N20/U20)*R20,0)) -> 56 | U20: =ROUNDDOWN(P20/O20, 0) -> 1 | V20: =IF(T20=X20, "MATCH", "RECHECK") -> MATCH | X20: 56
G21: Cut Length of each stirrups: | L21: C2V3 | M21: 32 | N21: 14 | O21: 6.96 | P21: 7.5 | Q21: =((22/(7*4))*(M21^2)/(1000^2))*S21*$B$24 -> 615.4199 | R21: 4 | S21: =N21*O21 -> 97.44 | T21: =IF(P21=0,0,ROUNDUP((N21/U21)*R21,0)) -> 56 | U21: =ROUNDDOWN(P21/O21, 0) -> 1 | V21: =IF(T21=X21, "MATCH", "RECHECK") -> MATCH | X21: 56
G22: Number of Stirrups per Column: | L22: C2V4 | M22: 25 | N22: 14 | O22: 11.95 | P22: 12 | Q22: =((22/(7*4))*(M22^2)/(1000^2))*S22*$B$24 -> 644.92656 | R22: 4 | S22: =N22*O22 -> 167.3 | T22: =IF(P22=0,0,ROUNDUP((N22/U22)*R22,0)) -> 56 | U22: =ROUNDDOWN(P22/O22, 0) -> 1 | V22: =IF(T22=X22, "MATCH", "RECHECK") -> MATCH | X22: 56
G23: Total Number of Bars used for stirrups : | H23: =IF(H17=0,0,(H22*H21*H8)/H17) -> 0 | L23: C2V5 | M23: 32 | N23: 4 | O23: 5.97 | P23: 6 | Q23: =((22/(7*4))*(M23^2)/(1000^2))*S23*$B$24 -> 150.82335 | R23: 4 | S23: =N23*O23 -> 23.88 | T23: =IF(P23=0,0,ROUNDUP((N23/U23)*R23,0)) -> 16 | U23: =ROUNDDOWN(P23/O23, 0) -> 1 | V23: =IF(T23=X23, "MATCH", "RECHECK") -> MATCH | X23: 16
A24: density of rebar | B24: 7850 | C24: kg/m^3 | G24: #16 TIE WIRE USED: | H24: =(H8*H22*H12*0.015) -> 0 | L24: C2V6 | M24: 25 | N24: 14 | O24: 1.36 | P24: 6 | Q24: =((22/(7*4))*(M24^2)/(1000^2))*S24*$B$24 -> 73.3975 | R24: 4 | S24: =N24*O24 -> 19.04 | T24: =IF(P24=0,0,ROUNDUP((N24/U24)*R24,0)) -> 14 | U24: =ROUNDDOWN(P24/O24, 0) -> 4 | V24: =IF(T24=X24, "MATCH", "RECHECK") -> MATCH | X24: 14
L25: C2T1 | M25: 12 | N25: 63 | O25: 2.75 | P25: 6 | Q25: =((22/(7*4))*(M25^2)/(1000^2))*S25*$B$24 -> 153.8757 | R25: 4 | S25: =N25*O25 -> 173.25 | T25: =IF(P25=0,0,ROUNDUP((N25/U25)*R25,0)) -> 126 | U25: =ROUNDDOWN(P25/O25, 0) -> 2 | V25: =IF(T25=X25, "MATCH", "RECHECK") -> MATCH | X25: 126
G26: Diameter of main bar | L26: C2T2 | M26: 12 | N26: 63 | O26: 2.16 | P26: 6 | Q26: =((22/(7*4))*(M26^2)/(1000^2))*S26*$B$24 -> 120.86237 | R26: 4 | S26: =N26*O26 -> 136.08 | T26: =IF(P26=0,0,ROUNDUP((N26/U26)*R26,0)) -> 126 | U26: =ROUNDDOWN(P26/O26, 0) -> 2 | V26: =IF(T26=X26, "MATCH", "RECHECK") -> MATCH | X26: 126
G27: Volume of rebar | H27: =(22/7*4)*(H26^2)*(H19*H17) -> 0 | L27: C2T3 | M27: 12 | N27: 63 | O27: 0.8 | P27: 6 | Q27: =((22/(7*4))*(M27^2)/(1000^2))*S27*$B$24 -> 44.76384 | R27: 4 | S27: =N27*O27 -> 50.4 | T27: =IF(P27=0,0,ROUNDUP((N27/U27)*R27,0)) -> 36 | U27: =ROUNDDOWN(P27/O27, 0) -> 7 | V27: =IF(T27=X27, "MATCH", "RECHECK") -> MATCH | X27: 36
G28: Net wt. | H28: =B24*H27 -> 0 | L28: C2T4 | M28: 12 | N28: 55 | O28: 2.75 | P28: 6 | Q28: =((22/(7*4))*(M28^2)/(1000^2))*S28*$B$24 -> 134.33593 | R28: 4 | S28: =N28*O28 -> 151.25 | T28: =IF(P28=0,0,ROUNDUP((N28/U28)*R28,0)) -> 110 | U28: =ROUNDDOWN(P28/O28, 0) -> 2 | V28: =IF(T28=X28, "MATCH", "RECHECK") -> MATCH | X28: 110
L29: C2T5 | M29: 12 | N29: 110 | O29: 2.06 | P29: 6 | Q29: =((22/(7*4))*(M29^2)/(1000^2))*S29*$B$24 -> 201.25965 | R29: 4 | S29: =N29*O29 -> 226.6 | T29: =IF(P29=0,0,ROUNDUP((N29/U29)*R29,0)) -> 220 | U29: =ROUNDDOWN(P29/O29, 0) -> 2 | V29: =IF(T29=X29, "MATCH", "RECHECK") -> MATCH | X29: 220
L30: C2T6 | M30: 12 | N30: 110 | O30: 0.52 | P30: 6 | Q30: =((22/(7*4))*(M30^2)/(1000^2))*S30*$B$24 -> 50.803406 | R30: 4 | S30: =N30*O30 -> 57.2 | T30: =IF(P30=0,0,ROUNDUP((N30/U30)*R30,0)) -> 40 | U30: =ROUNDDOWN(P30/O30, 0) -> 11 | V30: =IF(T30=X30, "MATCH", "RECHECK") -> MATCH | X30: 40
L31: C2T7 | M31: 10 | N31: 110 | O31: 2.72 | P31: 6 | Q31: =((22/(7*4))*(M31^2)/(1000^2))*S31*$B$24 -> 184.54229 | R31: 4 | S31: =N31*O31 -> 299.2 | T31: =IF(P31=0,0,ROUNDUP((N31/U31)*R31,0)) -> 220 | U31: =ROUNDDOWN(P31/O31, 0) -> 2 | V31: =IF(T31=X31, "MATCH", "RECHECK") -> MATCH | X31: 220
L32: C2T8 | M32: 10 | N32: 220 | O32: 2.02 | P32: 6 | Q32: =((22/(7*4))*(M32^2)/(1000^2))*S32*$B$24 -> 274.09957 | R32: 4 | S32: =N32*O32 -> 444.4 | T32: =IF(P32=0,0,ROUNDUP((N32/U32)*R32,0)) -> 440 | U32: =ROUNDDOWN(P32/O32, 0) -> 2 | V32: =IF(T32=X32, "MATCH", "RECHECK") -> MATCH | X32: 440
L33: C2T9 | M33: 10 | N33: 220 | O33: 0.77 | P33: 6 | Q33: =((22/(7*4))*(M33^2)/(1000^2))*S33*$B$24 -> 104.4835 | R33: 4 | S33: =N33*O33 -> 169.4 | T33: =IF(P33=0,0,ROUNDUP((N33/U33)*R33,0)) -> 126 | U33: =ROUNDDOWN(P33/O33, 0) -> 7 | V33: =IF(T33=X33, "MATCH", "RECHECK") -> MATCH | X33: 126
L34: C3V1 | M34: 32 | N34: 14 | O34: 8.23 | P34: 9 | Q34: =((22/(7*4))*(M34^2)/(1000^2))*S34*$B$24 -> 727.71635 | R34: 2 | S34: =N34*O34 -> 115.22 | T34: =IF(P34=0,0,ROUNDUP((N34/U34)*R34,0)) -> 28 | U34: =ROUNDDOWN(P34/O34, 0) -> 1 | V34: =IF(T34=X34, "MATCH", "RECHECK") -> MATCH | X34: 28
L35: C3V2 | M35: 25 | N35: 14 | O35: 11.06 | P35: 12 | Q35: =((22/(7*4))*(M35^2)/(1000^2))*S35*$B$24 -> 596.89438 | R35: 2 | S35: =N35*O35 -> 154.84 | T35: =IF(P35=0,0,ROUNDUP((N35/U35)*R35,0)) -> 28 | U35: =ROUNDDOWN(P35/O35, 0) -> 1 | V35: =IF(T35=X35, "MATCH", "RECHECK") -> MATCH | X35: 28
L36: C3V3 | M36: 32 | N36: 14 | O36: 7.06 | P36: 7.5 | Q36: =((22/(7*4))*(M36^2)/(1000^2))*S36*$B$24 -> 624.26214 | R36: 2 | S36: =N36*O36 -> 98.84 | T36: =IF(P36=0,0,ROUNDUP((N36/U36)*R36,0)) -> 28 | U36: =ROUNDDOWN(P36/O36, 0) -> 1 | V36: =IF(T36=X36, "MATCH", "RECHECK") -> MATCH | X36: 28
L37: C3V4 | M37: 25 | N37: 14 | O37: 11.95 | P37: 12 | Q37: =((22/(7*4))*(M37^2)/(1000^2))*S37*$B$24 -> 644.92656 | R37: 2 | S37: =N37*O37 -> 167.3 | T37: =IF(P37=0,0,ROUNDUP((N37/U37)*R37,0)) -> 28 | U37: =ROUNDDOWN(P37/O37, 0) -> 1 | V37: =IF(T37=X37, "MATCH", "RECHECK") -> MATCH | X37: 28
L38: C3V5 | M38: 25 | N38: 14 | O38: 1.16 | P38: 6 | Q38: =((22/(7*4))*(M38^2)/(1000^2))*S38*$B$24 -> 62.60375 | R38: 2 | S38: =N38*O38 -> 16.24 | T38: =IF(P38=0,0,ROUNDUP((N38/U38)*R38,0)) -> 6 | U38: =ROUNDDOWN(P38/O38, 0) -> 5 | V38: =IF(T38=X38, "MATCH", "RECHECK") -> MATCH | X38: 6
L39: C3V6 | M39: 16 | N39: 12 | O39: 4.08 | P39: 6 | Q39: =((22/(7*4))*(M39^2)/(1000^2))*S39*$B$24 -> 77.306441 | R39: 2 | S39: =N39*O39 -> 48.96 | T39: =IF(P39=0,0,ROUNDUP((N39/U39)*R39,0)) -> 24 | U39: =ROUNDDOWN(P39/O39, 0) -> 1 | V39: =IF(T39=X39, "MATCH", "RECHECK") -> MATCH | X39: 24
L40: C3T1 | M40: 12 | N40: 121 | O40: 2.75 | P40: 6 | Q40: =((22/(7*4))*(M40^2)/(1000^2))*S40*$B$24 -> 295.53904 | R40: 2 | S40: =N40*O40 -> 332.75 | T40: =IF(P40=0,0,ROUNDUP((N40/U40)*R40,0)) -> 121 | U40: =ROUNDDOWN(P40/O40, 0) -> 2 | V40: =IF(T40=X40, "MATCH", "RECHECK") -> MATCH | X40: 121
... L256: C18T1 | M256: 10 | N256: 63 | O256: 2.72 | P256: 6 | Q256: =((22/(7*4))*(M256^2)/(1000^2))*S256*$B$24 -> 105.6924 | R256: 1 | S256: =N256*O256 -> 171.36 | T256: =IF(P256=0,0,ROUNDUP((N256/U256)*R256,0)) -> 32 | U256: =ROUNDDOWN(P256/O256, 0) -> 2 | V256: =IF(T256=X256, "MATCH", "RECHECK") -> MATCH | X256: 32
L257: C18T2 | M257: 10 | N257: 126 | O257: 1.82 | P257: 6 | Q257: =((22/(7*4))*(M256^2)/(1000^2))*S257*$B$24 -> 141.4413 | R257: 1 | S257: =N257*O257 -> 229.32 | T257: =IF(P257=0,0,ROUNDUP((N257/U257)*R257,0)) -> 42 | U257: =ROUNDDOWN(P257/O257, 0) -> 3 | V257: =IF(T257=X257, "MATCH", "RECHECK") -> MATCH | X257: 42
L258: C18T3 | M258: 10 | N258: 63 | O258: 2.02 | P258: 6 | Q258: =((22/(7*4))*(M257^2)/(1000^2))*S258*$B$24 -> 78.49215 | R258: 1 | S258: =N258*O258 -> 127.26 | T258: =IF(P258=0,0,ROUNDUP((N258/U258)*R258,0)) -> 32 | U258: =ROUNDDOWN(P258/O258, 0) -> 2 | V258: =IF(T258=X258, "MATCH", "RECHECK") -> MATCH | X258: 32
L259: C18T4 | M259: 10 | N259: 252 | O259: 0.77 | P259: 6 | Q259: =((22/(7*4))*(M258^2)/(1000^2))*S259*$B$24 -> 119.6811 | R259: 1 | S259: =N259*O259 -> 194.04 | T259: =IF(P259=0,0,ROUNDUP((N259/U259)*R259,0)) -> 36 | U259: =ROUNDDOWN(P259/O259, 0) -> 7 | V259: =IF(T259=X259, "MATCH", "RECHECK") -> MATCH | X259: 36
L260: C18T5 | M260: 12 | N260: 195 | O260: 2.77 | P260: 7.5 | Q260: =((22/(7*4))*(M259^2)/(1000^2))*S260*$B$24 -> 333.1568 | R260: 1 | S260: =N260*O260 -> 540.15 | T260: =IF(P260=0,0,ROUNDUP((N260/U260)*R260,0)) -> 98 | U260: =ROUNDDOWN(P260/O260, 0) -> 2 | V260: =IF(T260=X260, "MATCH", "RECHECK") -> MATCH | X260: 98
...
