Workbook

Sheet LABOR PRODUCTIVITY
A1: ACTIVITIES | C1: OUTPUT PER HOUR | I1: MANHOUR EQUIVALENT
I2: ='MANHOUR EQUIVALENT'!F15 -> 58.680556 | J2: =CONCATENATE("per hour in area of ",'MANHOUR EQUIVALENT'!D10) -> per hour in area of CAR
I3: EQUIVALENT LABOR COST
A4: ITEM NO. | B4: WORK DESCRIPTION | C4: 3 WORKER PRODUCTIVITY RATE
C5: SLOW | D5: UNIT | E5: AVERAGE | F5: UNIT | G5: FAST | H5: UNIT | I5: =C5 -> SLOW | J5: PESOS PER | K5: AVERAGE | L5: PESOS PER | M5: =G5 -> FAST | N5: PESOS PER
A7: A. | B7: FORM WORKS INSTALLATION
B8: WALL ON THE GROUND | C8: =IFERROR(1/CALCULATIONS!U8,0) -> 0.25 | D8: =CONCATENATE(CALCULATIONS!T8,CALCULATIONS!X8) -> SQ.M.per hour | E8: =IFERROR(1/CALCULATIONS!V8,0) -> 0.5 | F8: =CONCATENATE(CALCULATIONS!T8,CALCULATIONS!X8) -> SQ.M.per hour | G8: =IFERROR(1/CALCULATIONS!W8,0) -> 0.625 | H8: =CONCATENATE(CALCULATIONS!T8,CALCULATIONS!X8) -> SQ.M.per hour | I8: =CALCULATIONS!U8*$I$2 -> 234.72222 | J8: =CONCATENATE(CALCULATIONS!Y8,CALCULATIONS!T8) -> per SQ.M. | K8: =CALCULATIONS!V8*$I$2 -> 117.36111 | L8: =CONCATENATE(CALCULATIONS!Y8,CALCULATIONS!T8) -> per SQ.M. | M8: =CALCULATIONS!W8*$I$2 -> 93.888889 | N8: =CONCATENATE(CALCULATIONS!Y8,CALCULATIONS!T8) -> per SQ.M.
B9: WALL ABOVER GROUND | C9: =IFERROR(1/CALCULATIONS!U9,0) -> 0.21276596 | D9: =CONCATENATE(CALCULATIONS!T9,CALCULATIONS!X9) -> SQ.M.per hour | E9: =IFERROR(1/CALCULATIONS!V9,0) -> 0.42553191 | F9: =CONCATENATE(CALCULATIONS!T9,CALCULATIONS!X9) -> SQ.M.per hour | G9: =IFERROR(1/CALCULATIONS!W9,0) -> 0.53191489 | H9: =CONCATENATE(CALCULATIONS!T9,CALCULATIONS!X9) -> SQ.M.per hour | I9: =CALCULATIONS!U9*$I$2 -> 275.79861 | J9: =CONCATENATE(CALCULATIONS!Y9,CALCULATIONS!T9) -> per SQ.M. | K9: =CALCULATIONS!V9*$I$2 -> 137.89931 | L9: =CONCATENATE(CALCULATIONS!Y9,CALCULATIONS!T9) -> per SQ.M. | M9: =CALCULATIONS!W9*$I$2 -> 110.31944 | N9: =CONCATENATE(CALCULATIONS!Y9,CALCULATIONS!T9) -> per SQ.M.
B10: BEAMS | C10: =IFERROR(1/CALCULATIONS!U10,0) -> 0.16233766 | D10: =CONCATENATE(CALCULATIONS!T10,CALCULATIONS!X10) -> SQ.M.per hour | E10: =IFERROR(1/CALCULATIONS!V10,0) -> 0.32467532 | F10: =CONCATENATE(CALCULATIONS!T10,CALCULATIONS!X10) -> SQ.M.per hour | G10: =IFERROR(1/CALCULATIONS!W10,0) -> 0.40650407 | H10: =CONCATENATE(CALCULATIONS!T10,CALCULATIONS!X10) -> SQ.M.per hour | I10: =CALCULATIONS!U10*$I$2 -> 361.47222 | J10: =CONCATENATE(CALCULATIONS!Y10,CALCULATIONS!T10) -> per SQ.M. | K10: =CALCULATIONS!V10*$I$2 -> 180.73611 | L10: =CONCATENATE(CALCULATIONS!Y10,CALCULATIONS!T10) -> per SQ.M. | M10: =CALCULATIONS!W10*$I$2 -> 144.35417 | N10: =CONCATENATE(CALCULATIONS!Y10,CALCULATIONS!T10) -> per SQ.M.
B11: COLUMN | C11: =IFERROR(1/CALCULATIONS!U11,0) -> 0.21276596 | D11: =CONCATENATE(CALCULATIONS!T11,CALCULATIONS!X11) -> SQ.M.per hour | E11: =IFERROR(1/CALCULATIONS!V11,0) -> 0.42553191 | F11: =CONCATENATE(CALCULATIONS!T11,CALCULATIONS!X11) -> SQ.M.per hour | G11: =IFERROR(1/CALCULATIONS!W11,0) -> 0.53191489 | H11: =CONCATENATE(CALCULATIONS!T11,CALCULATIONS!X11) -> SQ.M.per hour | I11: =CALCULATIONS!U11*$I$2 -> 275.79861 | J11: =CONCATENATE(CALCULATIONS!Y11,CALCULATIONS!T11) -> per SQ.M. | K11: =CALCULATIONS!V11*$I$2 -> 137.89931 | L11: =CONCATENATE(CALCULATIONS!Y11,CALCULATIONS!T11) -> per SQ.M. | M11: =CALCULATIONS!W11*$I$2 -> 110.31944 | N11: =CONCATENATE(CALCULATIONS!Y11,CALCULATIONS!T11) -> per SQ.M.
B12: SUSPENDED SLAB | C12: =IFERROR(1/CALCULATIONS!U12,0) -> 0 | D12: =CONCATENATE(CALCULATIONS!T12,CALCULATIONS!X12) | E12: =IFERROR(1/CALCULATIONS!V12,0) -> 0 | F12: =CONCATENATE(CALCULATIONS!T12,CALCULATIONS!X12) | G12: =IFERROR(1/CALCULATIONS!W12,0) -> 0 | H12: =CONCATENATE(CALCULATIONS!T12,CALCULATIONS!X12) | I12: =CALCULATIONS!U12*$I$2 -> 0 | J12: =CONCATENATE(CALCULATIONS!Y12,CALCULATIONS!T12) | K12: =CALCULATIONS!V12*$I$2 -> 0 | L12: =CONCATENATE(CALCULATIONS!Y12,CALCULATIONS!T12) | M12: =CALCULATIONS!W12*$I$2 -> 0 | N12: =CONCATENATE(CALCULATIONS!Y12,CALCULATIONS!T12)
B13: 0 TO 18' | C13: =IFERROR(1/CALCULATIONS!U13,0) -> 0.2994012 | D13: =CONCATENATE(CALCULATIONS!T13,CALCULATIONS!X13) -> SQ.M.per hour | E13: =IFERROR(1/CALCULATIONS!V13,0) -> 0.5988024 | F13: =CONCATENATE(CALCULATIONS!T13,CALCULATIONS!X13) -> SQ.M.per hour | G13: =IFERROR(1/CALCULATIONS!W13,0) -> 0.74626866 | H13: =CONCATENATE(CALCULATIONS!T13,CALCULATIONS!X13) -> SQ.M.per hour | I13: =CALCULATIONS!U13*$I$2 -> 195.99306 | J13: =CONCATENATE(CALCULATIONS!Y13,CALCULATIONS!T13) -> per SQ.M. | K13: =CALCULATIONS!V13*$I$2 -> 97.996528 | L13: =CONCATENATE(CALCULATIONS!Y13,CALCULATIONS!T13) -> per SQ.M. | M13: =CALCULATIONS!W13*$I$2 -> 78.631944 | N13: =CONCATENATE(CALCULATIONS!Y13,CALCULATIONS!T13) -> per SQ.M.
B14: 18' TO 36' UP | C14: =IFERROR(1/CALCULATIONS!U14,0) -> 0.15015015 | D14: =CONCATENATE(CALCULATIONS!T14,CALCULATIONS!X14) -> SQ.M.per hour | E14: =IFERROR(1/CALCULATIONS!V14,0) -> 0.3003003 | F14: =CONCATENATE(CALCULATIONS!T14,CALCULATIONS!X14) -> SQ.M.per hour | G14: =IFERROR(1/CALCULATIONS!W14,0) -> 0.37593985 | H14: =CONCATENATE(CALCULATIONS!T14,CALCULATIONS!X14) -> SQ.M.per hour | I14: =CALCULATIONS!U14*$I$2 -> 390.8125 | J14: =CONCATENATE(CALCULATIONS!Y14,CALCULATIONS!T14) -> per SQ.M. | K14: =CALCULATIONS!V14*$I$2 -> 195.40625 | L14: =CONCATENATE(CALCULATIONS!Y14,CALCULATIONS!T14) -> per SQ.M. | M14: =CALCULATIONS!W14*$I$2 -> 156.09028 | N14: =CONCATENATE(CALCULATIONS!Y14,CALCULATIONS!T14) -> per SQ.M.
B15: ELEVATED AND SHORED SLAB FORMING | C15: =IFERROR(1/CALCULATIONS!U15,0) -> 0 | D15: =CONCATENATE(CALCULATIONS!T15,CALCULATIONS!X15) | E15: =IFERROR(1/CALCULATIONS!V15,0) -> 0 | F15: =CONCATENATE(CALCULATIONS!T15,CALCULATIONS!X15) | G15: =IFERROR(1/CALCULATIONS!W15,0) -> 0 | H15: =CONCATENATE(CALCULATIONS!T15,CALCULATIONS!X15) | I15: =CALCULATIONS!U15*$I$2 -> 0 | J15: =CONCATENATE(CALCULATIONS!Y15,CALCULATIONS!T15) | K15: =CALCULATIONS!V15*$I$2 -> 0 | L15: =CONCATENATE(CALCULATIONS!Y15,CALCULATIONS!T15) | M15: =CALCULATIONS!W15*$I$2 -> 0 | N15: =CONCATENATE(CALCULATIONS!Y15,CALCULATIONS!T15)
B16: FORMING ONLY | C16: =IFERROR(1/CALCULATIONS!U16,0) -> 0.058139535 | D16: =CONCATENATE(CALCULATIONS!T16,CALCULATIONS!X16) -> SQ.M.per hour | E16: =IFERROR(1/CALCULATIONS!V16,0) -> 0.11111111 | F16: =CONCATENATE(CALCULATIONS!T16,CALCULATIONS!X16) -> SQ.M.per hour | G16: =IFERROR(1/CALCULATIONS!W16,0) -> 0.14534884 | H16: =CONCATENATE(CALCULATIONS!T16,CALCULATIONS!X16) -> SQ.M.per hour | I16: =CALCULATIONS!U16*$I$2 -> 1009.3056 | J16: =CONCATENATE(CALCULATIONS!Y16,CALCULATIONS!T16) -> per SQ.M. | K16: =CALCULATIONS!V16*$I$2 -> 528.125 | L16: =CONCATENATE(CALCULATIONS!Y16,CALCULATIONS!T16) -> per SQ.M. | M16: =CALCULATIONS!W16*$I$2 -> 403.72222 | N16: =CONCATENATE(CALCULATIONS!Y16,CALCULATIONS!T16) -> per SQ.M.
B17: FORMING AND SHORING | C17: =IFERROR(1/CALCULATIONS!U17,0) -> 0.045454545 | D17: =CONCATENATE(CALCULATIONS!T17,CALCULATIONS!X17) -> SQ.M.per hour | E17: =IFERROR(1/CALCULATIONS!V17,0) -> 0.090909091 | F17: =CONCATENATE(CALCULATIONS!T17,CALCULATIONS!X17) -> SQ.M.per hour | G17: =IFERROR(1/CALCULATIONS!W17,0) -> 0.11363636 | H17: =CONCATENATE(CALCULATIONS!T17,CALCULATIONS!X17) -> SQ.M.per hour | I17: =CALCULATIONS!U17*$I$2 -> 1290.9722 | J17: =CONCATENATE(CALCULATIONS!Y17,CALCULATIONS!T17) -> per SQ.M. | K17: =CALCULATIONS!V17*$I$2 -> 645.48611 | L17: =CONCATENATE(CALCULATIONS!Y17,CALCULATIONS!T17) -> per SQ.M. | M17: =CALCULATIONS!W17*$I$2 -> 516.38889 | N17: =CONCATENATE(CALCULATIONS!Y17,CALCULATIONS!T17) -> per SQ.M.
B18: WOOD WALL AND PARTITION | C18: =IFERROR(1/CALCULATIONS!U18,0) -> 1 | D18: =CONCATENATE(CALCULATIONS!T18,CALCULATIONS!X18) -> SQ.M.per hour | E18: =IFERROR(1/CALCULATIONS!V18,0) -> 1.6666667 | F18: =CONCATENATE(CALCULATIONS!T18,CALCULATIONS!X18) -> SQ.M.per hour | G18: =IFERROR(1/CALCULATIONS!W18,0) -> 2.5 | H18: =CONCATENATE(CALCULATIONS!T18,CALCULATIONS!X18) -> SQ.M.per hour | I18: =CALCULATIONS!U18*$I$2 -> 58.680556 | J18: =CONCATENATE(CALCULATIONS!Y18,CALCULATIONS!T18) -> per SQ.M. | K18: =CALCULATIONS!V18*$I$2 -> 35.208333 | L18: =CONCATENATE(CALCULATIONS!Y18,CALCULATIONS!T18) -> per SQ.M. | M18: =CALCULATIONS!W18*$I$2 -> 23.472222 | N18: =CONCATENATE(CALCULATIONS!Y18,CALCULATIONS!T18) -> per SQ.M.
C19: =IFERROR(1/CALCULATIONS!U19,0) -> 0 | D19: =CONCATENATE(CALCULATIONS!T19,CALCULATIONS!X19) | E19: =IFERROR(1/CALCULATIONS!V19,0) -> 0 | F19: =CONCATENATE(CALCULATIONS!T19,CALCULATIONS!X19) | G19: =IFERROR(1/CALCULATIONS!W19,0) -> 0 | H19: =CONCATENATE(CALCULATIONS!T19,CALCULATIONS!X19) | I19: =CALCULATIONS!U19*$I$2 -> 0 | J19: =CONCATENATE(CALCULATIONS!Y19,CALCULATIONS!T19) | K19: =CALCULATIONS!V19*$I$2 -> 0 | L19: =CONCATENATE(CALCULATIONS!Y19,CALCULATIONS!T19) | M19: =CALCULATIONS!W19*$I$2 -> 0 | N19: =CONCATENATE(CALCULATIONS!Y19,CALCULATIONS!T19)
A20: B. | B20: FORMWORKS FABRICATION | C20: =IFERROR(1/CALCULATIONS!U20,0) -> 0.46511628 | D20: =CONCATENATE(CALCULATIONS!T20,CALCULATIONS!X20) -> SQ.M.per hour | E20: =IFERROR(1/CALCULATIONS!V20,0) -> 0.92592593 | F20: =CONCATENATE(CALCULATIONS!T20,CALCULATIONS!X20) -> SQ.M.per hour | G20: =IFERROR(1/CALCULATIONS!W20,0) -> 1.1627907 | H20: =CONCATENATE(CALCULATIONS!T20,CALCULATIONS!X20) -> SQ.M.per hour | I20: =CALCULATIONS!U20*$I$2 -> 126.16319 | J20: =CONCATENATE(CALCULATIONS!Y20,CALCULATIONS!T20) -> per SQ.M. | K20: =CALCULATIONS!V20*$I$2 -> 63.375 | L20: =CONCATENATE(CALCULATIONS!Y20,CALCULATIONS!T20) -> per SQ.M. | M20: =CALCULATIONS!W20*$I$2 -> 50.465278 | N20: =CONCATENATE(CALCULATIONS!Y20,CALCULATIONS!T20) -> per SQ.M.
C21: =IFERROR(1/CALCULATIONS!U21,0) -> 0 | D21: =CONCATENATE(CALCULATIONS!T21,CALCULATIONS!X21) | E21: =IFERROR(1/CALCULATIONS!V21,0) -> 0 | F21: =CONCATENATE(CALCULATIONS!T21,CALCULATIONS!X21) | G21: =IFERROR(1/CALCULATIONS!W21,0) -> 0 | H21: =CONCATENATE(CALCULATIONS!T21,CALCULATIONS!X21) | I21: =CALCULATIONS!U21*$I$2 -> 0 | J21: =CONCATENATE(CALCULATIONS!Y21,CALCULATIONS!T21) | K21: =CALCULATIONS!V21*$I$2 -> 0 | L21: =CONCATENATE(CALCULATIONS!Y21,CALCULATIONS!T21) | M21: =CALCULATIONS!W21*$I$2 -> 0 | N21: =CONCATENATE(CALCULATIONS!Y21,CALCULATIONS!T21)
A22: C. | B22: STRIPPING OF FORMS | C22: =IFERROR(1/CALCULATIONS!U22,0) -> 0 | D22: =CONCATENATE(CALCULATIONS!T22,CALCULATIONS!X22) | E22: =IFERROR(1/CALCULATIONS!V22,0) -> 0 | F22: =CONCATENATE(CALCULATIONS!T22,CALCULATIONS!X22) | G22: =IFERROR(1/CALCULATIONS!W22,0) -> 0 | H22: =CONCATENATE(CALCULATIONS!T22,CALCULATIONS!X22) | I22: =CALCULATIONS!U22*$I$2 -> 0 | J22: =CONCATENATE(CALCULATIONS!Y22,CALCULATIONS!T22) | K22: =CALCULATIONS!V22*$I$2 -> 0 | L22: =CONCATENATE(CALCULATIONS!Y22,CALCULATIONS!T22) | M22: =CALCULATIONS!W22*$I$2 -> 0 | N22: =CONCATENATE(CALCULATIONS!Y22,CALCULATIONS!T22)
B23: WALL ON GROUND | C23: =IFERROR(1/CALCULATIONS!U23,0) -> 2 | D23: =CONCATENATE(CALCULATIONS!T23,CALCULATIONS!X23) -> SQ.M.per hour | E23: =IFERROR(1/CALCULATIONS!V23,0) -> 4 | F23: =CONCATENATE(CALCULATIONS!T23,CALCULATIONS!X23) -> SQ.M.per hour | G23: =IFERROR(1/CALCULATIONS!W23,0) -> 5 | H23: =CONCATENATE(CALCULATIONS!T23,CALCULATIONS!X23) -> SQ.M.per hour | I23: =CALCULATIONS!U23*$I$2 -> 29.340278 | J23: =CONCATENATE(CALCULATIONS!Y23,CALCULATIONS!T23) -> per SQ.M. | K23: =CALCULATIONS!V23*$I$2 -> 14.670139 | L23: =CONCATENATE(CALCULATIONS!Y23,CALCULATIONS!T23) -> per SQ.M. | M23: =CALCULATIONS!W23*$I$2 -> 11.736111 | N23: =CONCATENATE(CALCULATIONS!Y23,CALCULATIONS!T23) -> per SQ.M.
B24: WALL ABOVE 10' | C24: =IFERROR(1/CALCULATIONS!U24,0) -> 0.3875969 | D24: =CONCATENATE(CALCULATIONS!T24,CALCULATIONS!X24) -> SQ.M.per hour | E24: =IFERROR(1/CALCULATIONS!V24,0) -> 0.7751938 | F24: =CONCATENATE(CALCULATIONS!T24,CALCULATIONS!X24) -> SQ.M.per hour | G24: =IFERROR(1/CALCULATIONS!W24,0) -> 0.97087379 | H24: =CONCATENATE(CALCULATIONS!T24,CALCULATIONS!X24) -> SQ.M.per hour | I24: =CALCULATIONS!U24*$I$2 -> 151.39583 | J24: =CONCATENATE(CALCULATIONS!Y24,CALCULATIONS!T24) -> per SQ.M. | K24: =CALCULATIONS!V24*$I$2 -> 75.697917 | L24: =CONCATENATE(CALCULATIONS!Y24,CALCULATIONS!T24) -> per SQ.M. | M24: =CALCULATIONS!W24*$I$2 -> 60.440972 | N24: =CONCATENATE(CALCULATIONS!Y24,CALCULATIONS!T24) -> per SQ.M.
B25: BEAMS | C25: =IFERROR(1/CALCULATIONS!U25,0) -> 0.48543689 | D25: =CONCATENATE(CALCULATIONS!T25,CALCULATIONS!X25) -> SQ.M.per hour | E25: =IFERROR(1/CALCULATIONS!V25,0) -> 0.97087379 | F25: =CONCATENATE(CALCULATIONS!T25,CALCULATIONS!X25) -> SQ.M.per hour | G25: =IFERROR(1/CALCULATIONS!W25,0) -> 1.2195122 | H25: =CONCATENATE(CALCULATIONS!T25,CALCULATIONS!X25) -> SQ.M.per hour | I25: =CALCULATIONS!U25*$I$2 -> 120.88194 | J25: =CONCATENATE(CALCULATIONS!Y25,CALCULATIONS!T25) -> per SQ.M. | K25: =CALCULATIONS!V25*$I$2 -> 60.440972 | L25: =CONCATENATE(CALCULATIONS!Y25,CALCULATIONS!T25) -> per SQ.M. | M25: =CALCULATIONS!W25*$I$2 -> 48.118056 | N25: =CONCATENATE(CALCULATIONS!Y25,CALCULATIONS!T25) -> per SQ.M.
B26: COLUMNS | C26: =IFERROR(1/CALCULATIONS!U26,0) -> 0.58823529 | D26: =CONCATENATE(CALCULATIONS!T26,CALCULATIONS!X26) -> SQ.M.per hour | E26: =IFERROR(1/CALCULATIONS!V26,0) -> 1.1764706 | F26: =CONCATENATE(CALCULATIONS!T26,CALCULATIONS!X26) -> SQ.M.per hour | G26: =IFERROR(1/CALCULATIONS!W26,0) -> 1.4705882 | H26: =CONCATENATE(CALCULATIONS!T26,CALCULATIONS!X26) -> SQ.M.per hour | I26: =CALCULATIONS!U26*$I$2 -> 99.756944 | J26: =CONCATENATE(CALCULATIONS!Y26,CALCULATIONS!T26) -> per SQ.M. | K26: =CALCULATIONS!V26*$I$2 -> 49.878472 | L26: =CONCATENATE(CALCULATIONS!Y26,CALCULATIONS!T26) -> per SQ.M. | M26: =CALCULATIONS!W26*$I$2 -> 39.902778 | N26: =CONCATENATE(CALCULATIONS!Y26,CALCULATIONS!T26) -> per SQ.M.
B27: SUSPENDED SLAB | C27: =IFERROR(1/CALCULATIONS!U27,0) -> 0 | D27: =CONCATENATE(CALCULATIONS!T27,CALCULATIONS!X27) -> SQ.M.per hour | E27: =IFERROR(1/CALCULATIONS!V27,0) -> 0 | F27: =CONCATENATE(CALCULATIONS!T27,CALCULATIONS!X27) -> SQ.M.per hour | G27: =IFERROR(1/CALCULATIONS!W27,0) -> 0 | H27: =CONCATENATE(CALCULATIONS!T27,CALCULATIONS!X27) -> SQ.M.per hour | I27: =CALCULATIONS!U27*$I$2 -> 0 | J27: =CONCATENATE(CALCULATIONS!Y27,CALCULATIONS!T27) -> per SQ.M. | K27: =CALCULATIONS!V27*$I$2 -> 0 | L27: =CONCATENATE(CALCULATIONS!Y27,CALCULATIONS!T27) -> per SQ.M. | M27: =CALCULATIONS!W27*$I$2 -> 0 | N27: =CONCATENATE(CALCULATIONS!Y27,CALCULATIONS!T27) -> per SQ.M.
B28: 0 TO 18' | C28: =IFERROR(1/CALCULATIONS!U28,0) -> 0.5988024 | D28: =CONCATENATE(CALCULATIONS!T28,CALCULATIONS!X28) -> SQ.M.per hour | E28: =IFERROR(1/CALCULATIONS!V28,0) -> 1.2048193 | F28: =CONCATENATE(CALCULATIONS!T28,CALCULATIONS!X28) -> SQ.M.per hour | G28: =IFERROR(1/CALCULATIONS!W28,0) -> 1.4925373 | H28: =CONCATENATE(CALCULATIONS!T28,CALCULATIONS!X28) -> SQ.M.per hour | I28: =CALCULATIONS!U28*$I$2 -> 97.996528 | J28: =CONCATENATE(CALCULATIONS!Y28,CALCULATIONS!T28) -> per SQ.M. | K28: =CALCULATIONS!V28*$I$2 -> 48.704861 | L28: =CONCATENATE(CALCULATIONS!Y28,CALCULATIONS!T28) -> per SQ.M. | M28: =CALCULATIONS!W28*$I$2 -> 39.315972 | N28: =CONCATENATE(CALCULATIONS!Y28,CALCULATIONS!T28) -> per SQ.M.
B29: 18' TO 36' UP | C29: =IFERROR(1/CALCULATIONS!U29,0) -> 0.46296296 | D29: =CONCATENATE(CALCULATIONS!T29,CALCULATIONS!X29) -> SQ.M.per hour | E29: =IFERROR(1/CALCULATIONS!V29,0) -> 0.92592593 | F29: =CONCATENATE(CALCULATIONS!T29,CALCULATIONS!X29) -> SQ.M.per hour | G29: =IFERROR(1/CALCULATIONS!W29,0) -> 1.1627907 | H29: =CONCATENATE(CALCULATIONS!T29,CALCULATIONS!X29) -> SQ.M.per hour | I29: =CALCULATIONS!U29*$I$2 -> 126.75 | J29: =CONCATENATE(CALCULATIONS!Y29,CALCULATIONS!T29) -> per SQ.M. | K29: =CALCULATIONS!V29*$I$2 -> 63.375 | L29: =CONCATENATE(CALCULATIONS!Y29,CALCULATIONS!T29) -> per SQ.M. | M29: =CALCULATIONS!W29*$I$2 -> 50.465278 | N29: =CONCATENATE(CALCULATIONS!Y29,CALCULATIONS!T29) -> per SQ.M.
B30: ELEVATED AND SHORED SLAB FORMING | C30: =IFERROR(1/CALCULATIONS!U30,0) -> 0 | D30: =CONCATENATE(CALCULATIONS!T30,CALCULATIONS!X30) -> SQ.M.per hour | E30: =IFERROR(1/CALCULATIONS!V30,0) -> 0 | F30: =CONCATENATE(CALCULATIONS!T30,CALCULATIONS!X30) -> SQ.M.per hour | G30: =IFERROR(1/CALCULATIONS!W30,0) -> 0 | H30: =CONCATENATE(CALCULATIONS!T30,CALCULATIONS!X30) -> SQ.M.per hour | I30: =CALCULATIONS!U30*$I$2 -> 0 | J30: =CONCATENATE(CALCULATIONS!Y30,CALCULATIONS!T30) -> per SQ.M. | K30: =CALCULATIONS!V30*$I$2 -> 0 | L30: =CONCATENATE(CALCULATIONS!Y30,CALCULATIONS!T30) -> per SQ.M. | M30: =CALCULATIONS!W30*$I$2 -> 0 | N30: =CONCATENATE(CALCULATIONS!Y30,CALCULATIONS!T30) -> per SQ.M.
B31: STRIP OF FORMS | C31: =IFERROR(1/CALCULATIONS!U31,0) -> 0.14285714 | D31: =CONCATENATE(CALCULATIONS!T31,CALCULATIONS!X31) -> SQ.M.per hour | E31: =IFERROR(1/CALCULATIONS!V31,0) -> 0.28571429 | F31: =CONCATENATE(CALCULATIONS!T31,CALCULATIONS!X31) -> SQ.M.per hour | G31: =IFERROR(1/CALCULATIONS!W31,0) -> 0.35714286 | H31: =CONCATENATE(CALCULATIONS!T31,CALCULATIONS!X31) -> SQ.M.per hour | I31: =CALCULATIONS!U31*$I$2 -> 410.76389 | J31: =CONCATENATE(CALCULATIONS!Y31,CALCULATIONS!T31) -> per SQ.M. | K31: =CALCULATIONS!V31*$I$2 -> 205.38194 | L31: =CONCATENATE(CALCULATIONS!Y31,CALCULATIONS!T31) -> per SQ.M. | M31: =CALCULATIONS!W31*$I$2 -> 164.30556 | N31: =CONCATENATE(CALCULATIONS!Y31,CALCULATIONS!T31) -> per SQ.M.
B32: FLOOR SLAB AT GRADE STRIP OF FORMS | C32: =IFERROR(1/CALCULATIONS!U32,0) -> 0.17857143 | D32: =CONCATENATE(CALCULATIONS!T32,CALCULATIONS!X32) -> SQ.M.per hour | E32: =IFERROR(1/CALCULATIONS!V32,0) -> 0.35714286 | F32: =CONCATENATE(CALCULATIONS!T32,CALCULATIONS!X32) -> SQ.M.per hour | G32: =IFERROR(1/CALCULATIONS!W32,0) -> 0.44642857 | H32: =CONCATENATE(CALCULATIONS!T32,CALCULATIONS!X32) -> SQ.M.per hour | I32: =CALCULATIONS!U32*$I$2 -> 328.61111 | J32: =CONCATENATE(CALCULATIONS!Y32,CALCULATIONS!T32) -> per SQ.M. | K32: =CALCULATIONS!V32*$I$2 -> 164.30556 | L32: =CONCATENATE(CALCULATIONS!Y32,CALCULATIONS!T32) -> per SQ.M. | N32: =CONCATENATE(CALCULATIONS!Y32,CALCULATIONS!T32) -> per SQ.M.
C33: =IFERROR(1/CALCULATIONS!U33,0) -> 0 | D33: =CONCATENATE(CALCULATIONS!T33,CALCULATIONS!X33) | E33: =IFERROR(1/CALCULATIONS!V33,0) -> 0 | F33: =CONCATENATE(CALCULATIONS!T33,CALCULATIONS!X33) | G33: =IFERROR(1/CALCULATIONS!W33,0) -> 0 | H33: =CONCATENATE(CALCULATIONS!T33,CALCULATIONS!X33) | I33: =CALCULATIONS!U33*$I$2 -> 0 | J33: =CONCATENATE(CALCULATIONS!Y33,CALCULATIONS!T33) | K33: =CALCULATIONS!V33*$I$2 -> 0 | L33: =CONCATENATE(CALCULATIONS!Y33,CALCULATIONS!T33) | M33: =CALCULATIONS!W33*$I$2 -> 0 | N33: =CONCATENATE(CALCULATIONS!Y33,CALCULATIONS!T33)
A34: D | B34: INSTALLION OF CARPENTRY WORKS | C34: =IFERROR(1/CALCULATIONS!U34,0) -> 0 | D34: =CONCATENATE(CALCULATIONS!T34,CALCULATIONS!X34) | E34: =IFERROR(1/CALCULATIONS!V34,0) -> 0 | F34: =CONCATENATE(CALCULATIONS!T34,CALCULATIONS!X34) | G34: =IFERROR(1/CALCULATIONS!W34,0) -> 0 | H34: =CONCATENATE(CALCULATIONS!T34,CALCULATIONS!X34) | I34: =CALCULATIONS!U34*$I$2 -> 0 | J34: =CONCATENATE(CALCULATIONS!Y34,CALCULATIONS!T34) | K34: =CALCULATIONS!V34*$I$2 -> 0 | L34: =CONCATENATE(CALCULATIONS!Y34,CALCULATIONS!T34) | M34: =CALCULATIONS!W34*$I$2 -> 0 | N34: =CONCATENATE(CALCULATIONS!Y34,CALCULATIONS!T34)
B35: PLYWOOD PARTITION | C35: =IFERROR(1/CALCULATIONS!U35,0) -> 0.5 | D35: =CONCATENATE(CALCULATIONS!T35,CALCULATIONS!X35) -> PCper hour | E35: =IFERROR(1/CALCULATIONS!V35,0) -> 1 | F35: =CONCATENATE(CALCULATIONS!T35,CALCULATIONS!X35) -> PCper hour | G35: =IFERROR(1/CALCULATIONS!W35,0) -> 1.25 | H35: =CONCATENATE(CALCULATIONS!T35,CALCULATIONS!X35) -> PCper hour | I35: =CALCULATIONS!U35*$I$2 -> 117.36111 | J35: =CONCATENATE(CALCULATIONS!Y35,CALCULATIONS!T35) -> per PC | K35: =CALCULATIONS!V35*$I$2 -> 58.680556 | L35: =CONCATENATE(CALCULATIONS!Y35,CALCULATIONS!T35) -> per PC | M35: =CALCULATIONS!W35*$I$2 -> 46.944444 | N35: =CONCATENATE(CALCULATIONS!Y35,CALCULATIONS!T35) -> per PC
B36: T & G FLOORING AND SHORING | C36: =IFERROR(1/CALCULATIONS!U36,0) -> 3.4482759 | D36: =CONCATENATE(CALCULATIONS!T36,CALCULATIONS!X36) -> B.F.per hour | E36: =IFERROR(1/CALCULATIONS!V36,0) -> 7.1428571 | F36: =CONCATENATE(CALCULATIONS!T36,CALCULATIONS!X36) -> B.F.per hour | G36: =IFERROR(1/CALCULATIONS!W36,0) -> 9.0909091 | H36: =CONCATENATE(CALCULATIONS!T36,CALCULATIONS!X36) -> B.F.per hour | I36: =CALCULATIONS!U36*$I$2 -> 17.017361 | J36: =CONCATENATE(CALCULATIONS!Y36,CALCULATIONS!T36) -> per B.F. | K36: =CALCULATIONS!V36*$I$2 -> 8.2152778 | L36: =CONCATENATE(CALCULATIONS!Y36,CALCULATIONS!T36) -> per B.F. | M36: =CALCULATIONS!W36*$I$2 -> 6.4548611 | N36: =CONCATENATE(CALCULATIONS!Y36,CALCULATIONS!T36) -> per B.F.
B37: CEILING FRAME | C37: =IFERROR(1/CALCULATIONS!U37,0) -> 3.3333333 | D37: =CONCATENATE(CALCULATIONS!T37,CALCULATIONS!X37) -> B.F.per hour | E37: =IFERROR(1/CALCULATIONS!V37,0) -> 2.7777778 | F37: =CONCATENATE(CALCULATIONS!T37,CALCULATIONS!X37) -> B.F.per hour | G37: =IFERROR(1/CALCULATIONS!W37,0) -> 3.4482759 | H37: =CONCATENATE(CALCULATIONS!T37,CALCULATIONS!X37) -> B.F.per hour | I37: =CALCULATIONS!U37*$I$2 -> 17.604167 | J37: =CONCATENATE(CALCULATIONS!Y37,CALCULATIONS!T37) -> per B.F. | K37: =CALCULATIONS!V37*$I$2 -> 21.125 | L37: =CONCATENATE(CALCULATIONS!Y37,CALCULATIONS!T37) -> per B.F. | M37: =CALCULATIONS!W37*$I$2 -> 17.017361 | N37: =CONCATENATE(CALCULATIONS!Y37,CALCULATIONS!T37) -> per B.F.
B38: SIDING FRAME | C38: =IFERROR(1/CALCULATIONS!U38,0) -> 1.8867925 | D38: =CONCATENATE(CALCULATIONS!T38,CALCULATIONS!X38) -> B.F.per hour | E38: =IFERROR(1/CALCULATIONS!V38,0) -> 3.7037037 | F38: =CONCATENATE(CALCULATIONS!T38,CALCULATIONS!X38) -> B.F.per hour | G38: =IFERROR(1/CALCULATIONS!W38,0) -> 4.7619048 | H38: =CONCATENATE(CALCULATIONS!T38,CALCULATIONS!X38) -> B.F.per hour | I38: =CALCULATIONS!U38*$I$2 -> 31.100694 | J38: =CONCATENATE(CALCULATIONS!Y38,CALCULATIONS!T38) -> per B.F. | K38: =CALCULATIONS!V38*$I$2 -> 15.84375 | L38: =CONCATENATE(CALCULATIONS!Y38,CALCULATIONS!T38) -> per B.F. | M38: =CALCULATIONS!W38*$I$2 -> 12.322917 | N38: =CONCATENATE(CALCULATIONS!Y38,CALCULATIONS!T38) -> per B.F.
B39: FLOORING FRAME | C39: =IFERROR(1/CALCULATIONS!U39,0) -> 0.51546392 | D39: =CONCATENATE(CALCULATIONS!T39,CALCULATIONS!X39) -> B.F.per hour | E39: =IFERROR(1/CALCULATIONS!V39,0) -> 1.0309278 | F39: =CONCATENATE(CALCULATIONS!T39,CALCULATIONS!X39) -> B.F.per hour | G39: =IFERROR(1/CALCULATIONS!W39,0) -> 1.2987013 | H39: =CONCATENATE(CALCULATIONS!T39,CALCULATIONS!X39) -> B.F.per hour | I39: =CALCULATIONS!U39*$I$2 -> 113.84028 | J39: =CONCATENATE(CALCULATIONS!Y39,CALCULATIONS!T39) -> per B.F. | K39: =CALCULATIONS!V39*$I$2 -> 56.920139 | L39: =CONCATENATE(CALCULATIONS!Y39,CALCULATIONS!T39) -> per B.F. | M39: =CALCULATIONS!W39*$I$2 -> 45.184028 | N39: =CONCATENATE(CALCULATIONS!Y39,CALCULATIONS!T39) -> per B.F.
B40: WOODEN POSS ERECTION | C40: =IFERROR(1/CALCULATIONS!U40,0) -> 1.1764706 | D40: =CONCATENATE(CALCULATIONS!T40,CALCULATIONS!X40) -> B.F.per hour | E40: =IFERROR(1/CALCULATIONS!V40,0) -> 2.3255814 | F40: =CONCATENATE(CALCULATIONS!T40,CALCULATIONS!X40) -> B.F.per hour | G40: =IFERROR(1/CALCULATIONS!W40,0) -> 2.9411765 | H40: =CONCATENATE(CALCULATIONS!T40,CALCULATIONS!X40) -> B.F.per hour | I40: =CALCULATIONS!U40*$I$2 -> 49.878472 | J40: =CONCATENATE(CALCULATIONS!Y40,CALCULATIONS!T40) -> per B.F. | K40: =CALCULATIONS!V40*$I$2 -> 25.232639 | L40: =CONCATENATE(CALCULATIONS!Y40,CALCULATIONS!T40) -> per B.F. | M40: =CALCULATIONS!W40*$I$2 -> 19.951389 | N40: =CONCATENATE(CALCULATIONS!Y40,CALCULATIONS!T40) -> per B.F.
B41: TRUSS FABRICATION | C41: =IFERROR(1/CALCULATIONS!U41,0) -> 1.4285714 | D41: =CONCATENATE(CALCULATIONS!T41,CALCULATIONS!X41) -> B.F.per hour | E41: =IFERROR(1/CALCULATIONS!V41,0) -> 2.8571429 | F41: =CONCATENATE(CALCULATIONS!T41,CALCULATIONS!X41) -> B.F.per hour | G41: =IFERROR(1/CALCULATIONS!W41,0) -> 3.5714286 | H41: =CONCATENATE(CALCULATIONS!T41,CALCULATIONS!X41) -> B.F.per hour | I41: =CALCULATIONS!U41*$I$2 -> 41.076389 | J41: =CONCATENATE(CALCULATIONS!Y41,CALCULATIONS!T41) -> per B.F. | K41: =CALCULATIONS!V41*$I$2 -> 20.538194 | L41: =CONCATENATE(CALCULATIONS!Y41,CALCULATIONS!T41) -> per B.F. | M41: =CALCULATIONS!W41*$I$2 -> 16.430556 | N41: =CONCATENATE(CALCULATIONS!Y41,CALCULATIONS!T41) -> per B.F.
...

Sheet MANHOUR EQUIVALENT
B1: MANHOUR EQUIVALENT RATE | H1: Table of Rates
H2: Area | I2: Position
I3: Foreman | J3: Skilled | K3: Labor
H4: NCR | I4: =K4*$L$6 -> 926.25 | J4: =K4*$L$5 -> 748.125 | K4: 570
H5: CAR | I5: =K5*$L$6 -> 650 | J5: =K5*$L$5 -> 525 | K5: 400 | L5: =525/K5 -> 1.3125
H6: Region 1 | I6: =K6*$L$6 -> 650 | J6: =K6*$L$5 -> 525 | K6: 400 | L6: =650/K7 -> 1.625
H7: Region 2 | I7: =K7*$L$6 -> 650 | J7: =K7*$L$5 -> 525 | K7: 400
H8: Region 3 | I8: =K8*$L$6 -> 747.5 | J8: =K8*$L$5 -> 603.75 | K8: 460
D9: (Drop-Down List) | H9: Region 4A | I9: =K9*$L$6 -> 763.75 | J9: =K9*$L$5 -> 616.875 | K9: 470
B10: CHOOSE RATE : | D10: CAR | E10: Total Daily Rate | F10: Hourly Pay | H10: Region 4B | I10: =K10*$L$6 -> 576.875 | J10: =K10*$L$5 -> 465.9375 | K10: 355
B11: Position | C11: Quantity | D11: Rate | H11: Region 5 | I11: =K11*$L$6 -> 593.125 | J11: =K11*$L$5 -> 479.0625 | K11: 365
B12: Foreman | C12: 1 | D12: =VLOOKUP($D$10,$H$1:$K$20,2,FALSE) -> 650 | E12: =C12*D12 -> 650 | F12: =E12/8 -> 81.25 | H12: Region 6 | I12: =K12*$L$6 -> 731.25 | J12: =K12*$L$5 -> 590.625 | K12: 450
B13: Skilled | C13: 3 | D13: =VLOOKUP($D$10,$H$1:$K$20,3,FALSE) -> 525 | E13: =C13*D13 -> 1575 | F13: =E13/8 -> 196.875 | H13: Region 7 | I13: =K13*$L$6 -> 706.875 | J13: =K13*$L$5 -> 570.9375 | K13: 435
B14: Labor | C14: 5 | D14: =VLOOKUP($D$10,$H$1:$K$20,4,FALSE) -> 400 | E14: =C14*D14 -> 2000 | F14: =E14/8 -> 250 | H14: Region 8 | I14: =K14*$L$6 -> 609.375 | J14: =K14*$L$5 -> 492.1875 | K14: 375
E15: Total Rate per Manhour = | F15: =SUM(F12:F14)/SUM(C12:C14) -> 58.680556 | H15: Region 9 | I15: =K15*$L$6 -> 570.375 | J15: =K15*$L$5 -> 460.6875 | K15: 351
H16: Region 10 | I16: =K16*$L$6 -> 658.125 | J16: =K16*$L$5 -> 531.5625 | K16: 405
B17: NOTE : You can change the quantities of the manpower per position and their respective rates in the Table. | H17: Region 11 | I17: =K17*$L$6 -> 719.875 | J17: =K17*$L$5 -> 581.4375 | K17: 443
H18: Region 12 | I18: =K18*$L$6 -> 598 | J18: =K18*$L$5 -> 483 | K18: 368
H19: Region 13 | I19: =K19*$L$6 -> 568.75 | J19: =K19*$L$5 -> 459.375 | K19: 350
H20: BARMM | I20: =K20*$L$6 -> 554.125 | J20: =K20*$L$5 -> 447.5625 | K20: 341

Sheet LABOR CALCULATOR
A1: ACTIVITIES | C1: INPUT HERE | E1: choose labor productivity rate BELOW | F1: TOTAL COST
E3: LABOR PRODUCTIVITY
A4: ITEM NO. | B4: WORK DESCRIPTION | C4: QUANTITY | D4: UNIT | E4: FAST
E5: RATE PER UNIT
C6: SLOW | D6: AVERAGE | E6: FAST
A7: A. | B7: FORM WORKS INSTALLATION
B8: WALL ON THE GROUND | C8: 20 | D8: =CALCULATIONS!T8 -> SQ.M. | E8: =IF($E$4="LOW",'LABOR PRODUCTIVITY'!I8,IF($E$4="AVERAGE",'LABOR PRODUCTIVITY'!K8,'LABOR PRODUCTIVITY'!M8)) -> 93.888889 | F8: =C8*E8 -> 1877.7778
B9: WALL ABOVER GROUND | C9: 20 | D9: =CALCULATIONS!T9 -> SQ.M. | E9: =IF($E$4="LOW",'LABOR PRODUCTIVITY'!I9,IF($E$4="AVERAGE",'LABOR PRODUCTIVITY'!K9,'LABOR PRODUCTIVITY'!M9)) -> 110.31944 | F9: =C9*E9 -> 2206.3889
B10: BEAMS | D10: =CALCULATIONS!T10 -> SQ.M. | E10: =IF($E$4="LOW",'LABOR PRODUCTIVITY'!I10,IF($E$4="AVERAGE",'LABOR PRODUCTIVITY'!K10,'LABOR PRODUCTIVITY'!M10)) -> 144.35417 | F10: =C10*E10 -> 0
B11: COLUMN | D11: =CALCULATIONS!T11 -> SQ.M. | E11: =IF($E$4="LOW",'LABOR PRODUCTIVITY'!I11,IF($E$4="AVERAGE",'LABOR PRODUCTIVITY'!K11,'LABOR PRODUCTIVITY'!M11)) -> 110.31944 | F11: =C11*E11 -> 0
B12: SUSPENDED SLAB | D12: =CALCULATIONS!T12 | E12: =IF($E$4="LOW",'LABOR PRODUCTIVITY'!I12,IF($E$4="AVERAGE",'LABOR PRODUCTIVITY'!K12,'LABOR PRODUCTIVITY'!M12)) -> 0 | F12: =C12*E12 -> 0
B13: 0 TO 18' | D13: =CALCULATIONS!T13 -> SQ.M. | E13: =IF($E$4="LOW",'LABOR PRODUCTIVITY'!I13,IF($E$4="AVERAGE",'LABOR PRODUCTIVITY'!K13,'LABOR PRODUCTIVITY'!M13)) -> 78.631944 | F13: =C13*E13 -> 0
B14: 18' TO 36' UP | D14: =CALCULATIONS!T14 -> SQ.M. | E14: =IF($E$4="LOW",'LABOR PRODUCTIVITY'!I14,IF($E$4="AVERAGE",'LABOR PRODUCTIVITY'!K14,'LABOR PRODUCTIVITY'!M14)) -> 156.09028 | F14: =C14*E14 -> 0
B15: ELEVATED AND SHORED SLAB FORMING | D15: =CALCULATIONS!T15 | E15: =IF($E$4="LOW",'LABOR PRODUCTIVITY'!I15,IF($E$4="AVERAGE",'LABOR PRODUCTIVITY'!K15,'LABOR PRODUCTIVITY'!M15)) -> 0 | F15: =C15*E15 -> 0
B16: FORMING ONLY | D16: =CALCULATIONS!T16 -> SQ.M. | E16: =IF($E$4="LOW",'LABOR PRODUCTIVITY'!I16,IF($E$4="AVERAGE",'LABOR PRODUCTIVITY'!K16,'LABOR PRODUCTIVITY'!M16)) -> 403.72222 | F16: =C16*E16 -> 0
B17: FORMING AND SHORING | D17: =CALCULATIONS!T17 -> SQ.M. | E17: =IF($E$4="LOW",'LABOR PRODUCTIVITY'!I17,IF($E$4="AVERAGE",'LABOR PRODUCTIVITY'!K17,'LABOR PRODUCTIVITY'!M17)) -> 516.38889 | F17: =C17*E17 -> 0
B18: WOOD WALL AND PARTITION | D18: =CALCULATIONS!T18 -> SQ.M. | E18: =IF($E$4="LOW",'LABOR PRODUCTIVITY'!I18,IF($E$4="AVERAGE",'LABOR PRODUCTIVITY'!K18,'LABOR PRODUCTIVITY'!M18)) -> 23.472222 | F18: =C18*E18 -> 0
D19: =CALCULATIONS!T19 | E19: =IF($E$4="LOW",'LABOR PRODUCTIVITY'!I19,IF($E$4="AVERAGE",'LABOR PRODUCTIVITY'!K19,'LABOR PRODUCTIVITY'!M19)) -> 0 | F19: =C19*E19 -> 0
A20: B. | B20: FORMWORKS FABRICATION | D20: =CALCULATIONS!T20 -> SQ.M. | E20: =IF($E$4="LOW",'LABOR PRODUCTIVITY'!I20,IF($E$4="AVERAGE",'LABOR PRODUCTIVITY'!K20,'LABOR PRODUCTIVITY'!M20)) -> 50.465278 | F20: =C20*E20 -> 0
D21: =CALCULATIONS!T21 | E21: =IF($E$4="LOW",'LABOR PRODUCTIVITY'!I21,IF($E$4="AVERAGE",'LABOR PRODUCTIVITY'!K21,'LABOR PRODUCTIVITY'!M21)) -> 0 | F21: =C21*E21 -> 0
A22: C. | B22: STRIPPING OF FORMS | D22: =CALCULATIONS!T22 | E22: =IF($E$4="LOW",'LABOR PRODUCTIVITY'!I22,IF($E$4="AVERAGE",'LABOR PRODUCTIVITY'!K22,'LABOR PRODUCTIVITY'!M22)) -> 0 | F22: =C22*E22 -> 0
B23: WALL ON GROUND | D23: =CALCULATIONS!T23 -> SQ.M. | E23: =IF($E$4="LOW",'LABOR PRODUCTIVITY'!I23,IF($E$4="AVERAGE",'LABOR PRODUCTIVITY'!K23,'LABOR PRODUCTIVITY'!M23)) -> 11.736111 | F23: =C23*E23 -> 0
B24: WALL ABOVE 10' | D24: =CALCULATIONS!T24 -> SQ.M. | E24: =IF($E$4="LOW",'LABOR PRODUCTIVITY'!I24,IF($E$4="AVERAGE",'LABOR PRODUCTIVITY'!K24,'LABOR PRODUCTIVITY'!M24)) -> 60.440972 | F24: =C24*E24 -> 0
B25: BEAMS | D25: =CALCULATIONS!T25 -> SQ.M. | E25: =IF($E$4="LOW",'LABOR PRODUCTIVITY'!I25,IF($E$4="AVERAGE",'LABOR PRODUCTIVITY'!K25,'LABOR PRODUCTIVITY'!M25)) -> 48.118056 | F25: =C25*E25 -> 0
B26: COLUMNS | D26: =CALCULATIONS!T26 -> SQ.M. | E26: =IF($E$4="LOW",'LABOR PRODUCTIVITY'!I26,IF($E$4="AVERAGE",'LABOR PRODUCTIVITY'!K26,'LABOR PRODUCTIVITY'!M26)) -> 39.902778 | F26: =C26*E26 -> 0
B27: SUSPENDED SLAB | D27: =CALCULATIONS!T27 -> SQ.M. | E27: =IF($E$4="LOW",'LABOR PRODUCTIVITY'!I27,IF($E$4="AVERAGE",'LABOR PRODUCTIVITY'!K27,'LABOR PRODUCTIVITY'!M27)) -> 0 | F27: =C27*E27 -> 0
B28: 0 TO 18' | D28: =CALCULATIONS!T28 -> SQ.M. | E28: =IF($E$4="LOW",'LABOR PRODUCTIVITY'!I28,IF($E$4="AVERAGE",'LABOR PRODUCTIVITY'!K28,'LABOR PRODUCTIVITY'!M28)) -> 39.315972 | F28: =C28*E28 -> 0
B29: 18' TO 36' UP | D29: =CALCULATIONS!T29 -> SQ.M. | E29: =IF($E$4="LOW",'LABOR PRODUCTIVITY'!I29,IF($E$4="AVERAGE",'LABOR PRODUCTIVITY'!K29,'LABOR PRODUCTIVITY'!M29)) -> 50.465278 | F29: =C29*E29 -> 0
B30: ELEVATED AND SHORED SLAB FORMING | D30: =CALCULATIONS!T30 -> SQ.M. | E30: =IF($E$4="LOW",'LABOR PRODUCTIVITY'!I30,IF($E$4="AVERAGE",'LABOR PRODUCTIVITY'!K30,'LABOR PRODUCTIVITY'!M30)) -> 0 | F30: =C30*E30 -> 0
B31: STRIP OF FORMS | D31: =CALCULATIONS!T31 -> SQ.M. | E31: =IF($E$4="LOW",'LABOR PRODUCTIVITY'!I31,IF($E$4="AVERAGE",'LABOR PRODUCTIVITY'!K31,'LABOR PRODUCTIVITY'!M31)) -> 164.30556 | F31: =C31*E31 -> 0
B32: FLOOR SLAB AT GRADE STRIP OF FORMS | D32: =CALCULATIONS!T32 -> SQ.M. | E32: =IF($E$4="LOW",'LABOR PRODUCTIVITY'!I32,IF($E$4="AVERAGE",'LABOR PRODUCTIVITY'!K32,'LABOR PRODUCTIVITY'!M32)) | F32: =C32*E32 -> #VALUE!
D33: =CALCULATIONS!T33 | E33: =IF($E$4="LOW",'LABOR PRODUCTIVITY'!I33,IF($E$4="AVERAGE",'LABOR PRODUCTIVITY'!K33,'LABOR PRODUCTIVITY'!M33)) -> 0 | F33: =C33*E33 -> 0
A34: D | B34: INSTALLION OF CARPENTRY WORKS | D34: =CALCULATIONS!T34 | E34: =IF($E$4="LOW",'LABOR PRODUCTIVITY'!I34,IF($E$4="AVERAGE",'LABOR PRODUCTIVITY'!K34,'LABOR PRODUCTIVITY'!M34)) -> 0 | F34: =C34*E34 -> 0
B35: PLYWOOD PARTITION | D35: =CALCULATIONS!T35 -> PC | E35: =IF($E$4="LOW",'LABOR PRODUCTIVITY'!I35,IF($E$4="AVERAGE",'LABOR PRODUCTIVITY'!K35,'LABOR PRODUCTIVITY'!M35)) -> 46.944444 | F35: =C35*E35 -> 0
B36: T & G FLOORING AND SHORING | D36: =CALCULATIONS!T36 -> B.F. | E36: =IF($E$4="LOW",'LABOR PRODUCTIVITY'!I36,IF($E$4="AVERAGE",'LABOR PRODUCTIVITY'!K36,'LABOR PRODUCTIVITY'!M36)) -> 6.4548611 | F36: =C36*E36 -> 0
B37: CEILING FRAME | D37: =CALCULATIONS!T37 -> B.F. | E37: =IF($E$4="LOW",'LABOR PRODUCTIVITY'!I37,IF($E$4="AVERAGE",'LABOR PRODUCTIVITY'!K37,'LABOR PRODUCTIVITY'!M37)) -> 17.017361 | F37: =C37*E37 -> 0
B38: SIDING FRAME | D38: =CALCULATIONS!T38 -> B.F. | E38: =IF($E$4="LOW",'LABOR PRODUCTIVITY'!I38,IF($E$4="AVERAGE",'LABOR PRODUCTIVITY'!K38,'LABOR PRODUCTIVITY'!M38)) -> 12.322917 | F38: =C38*E38 -> 0
B39: FLOORING FRAME | D39: =CALCULATIONS!T39 -> B.F. | E39: =IF($E$4="LOW",'LABOR PRODUCTIVITY'!I39,IF($E$4="AVERAGE",'LABOR PRODUCTIVITY'!K39,'LABOR PRODUCTIVITY'!M39)) -> 45.184028 | F39: =C39*E39 -> 0
B40: WOODEN POSS ERECTION | D40: =CALCULATIONS!T40 -> B.F. | E40: =IF($E$4="LOW",'LABOR PRODUCTIVITY'!I40,IF($E$4="AVERAGE",'LABOR PRODUCTIVITY'!K40,'LABOR PRODUCTIVITY'!M40)) -> 19.951389 | F40: =C40*E40 -> 0
B41: TRUSS FABRICATION | D41: =CALCULATIONS!T41 -> B.F. | E41: =IF($E$4="LOW",'LABOR PRODUCTIVITY'!I41,IF($E$4="AVERAGE",'LABOR PRODUCTIVITY'!K41,'LABOR PRODUCTIVITY'!M41)) -> 16.430556 | F41: =C41*E41 -> 0
...

Sheet CALCULATIONS
C1: MANHOUR EQUIVALENT | M1: OUTPUT PER HOUR
C2: ='MANHOUR EQUIVALENT'!F15 -> 58.680556 | D2: =CONCATENATE("per hour in area of ",'MANHOUR EQUIVALENT'!D10) -> per hour in area of CAR
C3: EQUIVALENT LABOR COST
B4: LOW | J4: MANHOURS PER QUANTITY (M.H./UNIT) | M4: 3 WORKER PRODUCTIVITY RATE | U4: MANHOURS PER QUANTITY (M.H./UNIT)
B5: AVERAGE | C5: LOW | D5: PESOS PER | E5: AVERAGE | F5: PESOS PER | G5: HIGH | H5: PESOS PER | I5: UNIT | J5: LOW | K5: AVERAGE | L5: HIGH | M5: LOW | N5: UNIT | O5: AVERAGE | P5: UNIT | Q5: HIGH | R5: UNIT | T5: UNIT | U5: LOW | V5: AVERAGE | W5: HIGH
B6: HIGH
C8: =J8*$C$2 -> 234.72222 | D8: =CONCATENATE(" per ",I8) -> per SQ.M. | E8: =K8*$C$2 -> 117.36111 | F8: =CONCATENATE(" per ",I8) -> per SQ.M. | G8: =L8*$C$2 -> 93.888889 | H8: =CONCATENATE(" per ",I8) -> per SQ.M. | I8: SQ.M. | J8: 4 | K8: 2 | L8: 1.6 | M8: =1/J8 -> 0.25 | N8: =CONCATENATE(I8," per hour") -> SQ.M. per hour | O8: =1/K8 -> 0.5 | P8: =CONCATENATE(I8," per hour") -> SQ.M. per hour | Q8: =1/L8 -> 0.625 | R8: =CONCATENATE(I8," per hour") -> SQ.M. per hour | T8: SQ.M. | U8: 4 | V8: 2 | W8: 1.6 | X8: =IF(T8>0,"per hour","") -> per hour | Y8: =IF(T8>0,"per ","") -> per
C9: =J9*$C$2 -> 275.79861 | E9: =K9*$C$2 -> 137.89931 | G9: =L9*$C$2 -> 110.31944 | I9: SQ.M. | J9: 4.7 | K9: 2.35 | L9: 1.88 | T9: SQ.M. | U9: 4.7 | V9: 2.35 | W9: 1.88 | X9: =IF(T9>0,"per hour","") -> per hour | Y9: =IF(T9>0,"per ","") -> per
C10: =J10*$C$2 -> 361.47222 | E10: =K10*$C$2 -> 180.73611 | G10: =L10*$C$2 -> 144.35417 | I10: SQ.M. | J10: 6.16 | K10: 3.08 | L10: 2.46 | T10: SQ.M. | U10: 6.16 | V10: 3.08 | W10: 2.46 | X10: =IF(T10>0,"per hour","") -> per hour | Y10: =IF(T10>0,"per ","") -> per
C11: =J11*$C$2 -> 275.79861 | E11: =K11*$C$2 -> 137.89931 | G11: =L11*$C$2 -> 110.31944 | I11: SQ.M. | J11: 4.7 | K11: 2.35 | L11: 1.88 | T11: SQ.M. | U11: 4.7 | V11: 2.35 | W11: 1.88 | X11: =IF(T11>0,"per hour","") -> per hour | Y11: =IF(T11>0,"per ","") -> per
C12: =J12*$C$2 -> 0 | E12: =K12*$C$2 -> 0 | G12: =L12*$C$2 -> 0 | X12: =IF(T12>0,"per hour","") | Y12: =IF(T12>0,"per ","")
C13: =J13*$C$2 -> 195.99306 | E13: =K13*$C$2 -> 97.996528 | G13: =L13*$C$2 -> 78.631944 | I13: SQ.M. | J13: 3.34 | K13: 1.67 | L13: 1.34 | T13: SQ.M. | U13: 3.34 | V13: 1.67 | W13: 1.34 | X13: =IF(T13>0,"per hour","") -> per hour | Y13: =IF(T13>0,"per ","") -> per
C14: =J14*$C$2 -> 390.8125 | E14: =K14*$C$2 -> 195.40625 | G14: =L14*$C$2 -> 156.09028 | I14: SQ.M. | J14: 6.66 | K14: 3.33 | L14: 2.66 | T14: SQ.M. | U14: 6.66 | V14: 3.33 | W14: 2.66 | X14: =IF(T14>0,"per hour","") -> per hour | Y14: =IF(T14>0,"per ","") -> per
C15: =J15*$C$2 -> 0 | E15: =K15*$C$2 -> 0 | G15: =L15*$C$2 -> 0 | X15: =IF(T15>0,"per hour","") | Y15: =IF(T15>0,"per ","")
C16: =J16*$C$2 -> 1009.3056 | E16: =K16*$C$2 -> 528.125 | G16: =L16*$C$2 -> 403.72222 | I16: SQ.M. | J16: 17.2 | K16: 9 | L16: 6.88 | T16: SQ.M. | U16: 17.2 | V16: 9 | W16: 6.88 | X16: =IF(T16>0,"per hour","") -> per hour | Y16: =IF(T16>0,"per ","") -> per
C17: =J17*$C$2 -> 1290.9722 | E17: =K17*$C$2 -> 645.48611 | G17: =L17*$C$2 -> 516.38889 | I17: SQ.M. | J17: 22 | K17: 11 | L17: 8.8 | T17: SQ.M. | U17: 22 | V17: 11 | W17: 8.8 | X17: =IF(T17>0,"per hour","") -> per hour | Y17: =IF(T17>0,"per ","") -> per
C18: =J18*$C$2 -> 58.680556 | E18: =K18*$C$2 -> 35.208333 | G18: =L18*$C$2 -> 23.472222 | I18: SQ.M. | J18: 1 | K18: 0.6 | L18: 0.4 | T18: SQ.M. | U18: 1 | V18: 0.6 | W18: 0.4 | X18: =IF(T18>0,"per hour","") -> per hour | Y18: =IF(T18>0,"per ","") -> per
C19: =J19*$C$2 -> 0 | E19: =K19*$C$2 -> 0 | G19: =L19*$C$2 -> 0 | X19: =IF(T19>0,"per hour","") | Y19: =IF(T19>0,"per ","")
C20: =J20*$C$2 -> 126.16319 | E20: =K20*$C$2 -> 63.375 | G20: =L20*$C$2 -> 50.465278 | I20: SQ.M. | J20: 2.15 | K20: 1.08 | L20: 0.86 | T20: SQ.M. | U20: 2.15 | V20: 1.08 | W20: 0.86 | X20: =IF(T20>0,"per hour","") -> per hour | Y20: =IF(T20>0,"per ","") -> per
C21: =J21*$C$2 -> 0 | E21: =K21*$C$2 -> 0 | G21: =L21*$C$2 -> 0 | X21: =IF(T21>0,"per hour","") | Y21: =IF(T21>0,"per ","")
C22: =J22*$C$2 -> 0 | E22: =K22*$C$2 -> 0 | G22: =L22*$C$2 -> 0 | X22: =IF(T22>0,"per hour","") | Y22: =IF(T22>0,"per ","")
C23: =J23*$C$2 -> 29.340278 | E23: =K23*$C$2 -> 14.670139 | G23: =L23*$C$2 -> 11.736111 | I23: SQ.M. | J23: 0.5 | K23: 0.25 | L23: 0.2 | T23: SQ.M. | U23: 0.5 | V23: 0.25 | W23: 0.2 | X23: =IF(T23>0,"per hour","") -> per hour | Y23: =IF(T23>0,"per ","") -> per
C24: =J24*$C$2 -> 151.39583 | E24: =K24*$C$2 -> 75.697917 | G24: =L24*$C$2 -> 60.440972 | I24: SQ.M. | J24: 2.58 | K24: 1.29 | L24: 1.03 | T24: SQ.M. | U24: 2.58 | V24: 1.29 | W24: 1.03 | X24: =IF(T24>0,"per hour","") -> per hour | Y24: =IF(T24>0,"per ","") -> per
C25: =J25*$C$2 -> 120.88194 | E25: =K25*$C$2 -> 60.440972 | G25: =L25*$C$2 -> 48.118056 | I25: SQ.M. | J25: 2.06 | K25: 1.03 | L25: 0.82 | T25: SQ.M. | U25: 2.06 | V25: 1.03 | W25: 0.82 | X25: =IF(T25>0,"per hour","") -> per hour | Y25: =IF(T25>0,"per ","") -> per
C26: =J26*$C$2 -> 99.756944 | E26: =K26*$C$2 -> 49.878472 | G26: =L26*$C$2 -> 39.902778 | I26: SQ.M. | J26: 1.7 | K26: 0.85 | L26: 0.68 | T26: SQ.M. | U26: 1.7 | V26: 0.85 | W26: 0.68 | X26: =IF(T26>0,"per hour","") -> per hour | Y26: =IF(T26>0,"per ","") -> per
C27: =J27*$C$2 -> 0 | E27: =K27*$C$2 -> 0 | G27: =L27*$C$2 -> 0 | I27: SQ.M. | T27: SQ.M. | X27: =IF(T27>0,"per hour","") -> per hour | Y27: =IF(T27>0,"per ","") -> per
C28: =J28*$C$2 -> 97.996528 | E28: =K28*$C$2 -> 48.704861 | G28: =L28*$C$2 -> 39.315972 | I28: SQ.M. | J28: 1.67 | K28: 0.83 | L28: 0.67 | T28: SQ.M. | U28: 1.67 | V28: 0.83 | W28: 0.67 | X28: =IF(T28>0,"per hour","") -> per hour | Y28: =IF(T28>0,"per ","") -> per
C29: =J29*$C$2 -> 126.75 | E29: =K29*$C$2 -> 63.375 | G29: =L29*$C$2 -> 50.465278 | I29: SQ.M. | J29: 2.16 | K29: 1.08 | L29: 0.86 | T29: SQ.M. | U29: 2.16 | V29: 1.08 | W29: 0.86 | X29: =IF(T29>0,"per hour","") -> per hour | Y29: =IF(T29>0,"per ","") -> per
C30: =J30*$C$2 -> 0 | E30: =K30*$C$2 -> 0 | G30: =L30*$C$2 -> 0 | I30: SQ.M. | T30: SQ.M. | X30: =IF(T30>0,"per hour","") -> per hour | Y30: =IF(T30>0,"per ","") -> per
C31: =J31*$C$2 -> 410.76389 | E31: =K31*$C$2 -> 205.38194 | G31: =L31*$C$2 -> 164.30556 | I31: SQ.M. | J31: 7 | K31: 3.5 | L31: 2.8 | T31: SQ.M. | U31: 7 | V31: 3.5 | W31: 2.8 | X31: =IF(T31>0,"per hour","") -> per hour | Y31: =IF(T31>0,"per ","") -> per
C32: =J32*$C$2 -> 328.61111 | E32: =K32*$C$2 -> 164.30556 | G32: =L32*$C$2 -> 131.44444 | I32: SQ.M. | J32: 5.6 | K32: 2.8 | L32: 2.24 | T32: SQ.M. | U32: 5.6 | V32: 2.8 | W32: 2.24 | X32: =IF(T32>0,"per hour","") -> per hour | Y32: =IF(T32>0,"per ","") -> per
C33: =J33*$C$2 -> 0 | E33: =K33*$C$2 -> 0 | G33: =L33*$C$2 -> 0 | X33: =IF(T33>0,"per hour","") | Y33: =IF(T33>0,"per ","")
C34: =J34*$C$2 -> 0 | E34: =K34*$C$2 -> 0 | G34: =L34*$C$2 -> 0 | X34: =IF(T34>0,"per hour","") | Y34: =IF(T34>0,"per ","")
C35: =J35*$C$2 -> 117.36111 | E35: =K35*$C$2 -> 58.680556 | G35: =L35*$C$2 -> 46.944444 | I35: PC | J35: 2 | K35: 1 | L35: 0.8 | T35: PC | U35: 2 | V35: 1 | W35: 0.8 | X35: =IF(T35>0,"per hour","") -> per hour | Y35: =IF(T35>0,"per ","") -> per
C36: =J36*$C$2 -> 17.017361 | E36: =K36*$C$2 -> 8.2152778 | G36: =L36*$C$2 -> 6.4548611 | I36: B.F. | J36: 0.29 | K36: 0.14 | L36: 0.11 | T36: B.F. | U36: 0.29 | V36: 0.14 | W36: 0.11 | X36: =IF(T36>0,"per hour","") -> per hour | Y36: =IF(T36>0,"per ","") -> per
C37: =J37*$C$2 -> 17.604167 | E37: =K37*$C$2 -> 21.125 | G37: =L37*$C$2 -> 17.017361 | I37: B.F. | J37: 0.3 | K37: 0.36 | L37: 0.29 | T37: B.F. | U37: 0.3 | V37: 0.36 | W37: 0.29 | X37: =IF(T37>0,"per hour","") -> per hour | Y37: =IF(T37>0,"per ","") -> per
C38: =J38*$C$2 -> 31.100694 | E38: =K38*$C$2 -> 15.84375 | G38: =L38*$C$2 -> 12.322917 | I38: B.F. | J38: 0.53 | K38: 0.27 | L38: 0.21 | T38: B.F. | U38: 0.53 | V38: 0.27 | W38: 0.21 | X38: =IF(T38>0,"per hour","") -> per hour | Y38: =IF(T38>0,"per ","") -> per
C39: =J39*$C$2 -> 113.84028 | E39: =K39*$C$2 -> 56.920139 | G39: =L39*$C$2 -> 45.184028 | I39: B.F. | J39: 1.94 | K39: 0.97 | L39: 0.77 | T39: B.F. | U39: 1.94 | V39: 0.97 | W39: 0.77 | X39: =IF(T39>0,"per hour","") -> per hour | Y39: =IF(T39>0,"per ","") -> per
C40: =J40*$C$2 -> 49.878472 | E40: =K40*$C$2 -> 25.232639 | G40: =L40*$C$2 -> 19.951389 | I40: B.F. | J40: 0.85 | K40: 0.43 | L40: 0.34 | T40: B.F. | U40: 0.85 | V40: 0.43 | W40: 0.34 | X40: =IF(T40>0,"per hour","") -> per hour | Y40: =IF(T40>0,"per ","") -> per
C41: =J41*$C$2 -> 41.076389 | E41: =K41*$C$2 -> 20.538194 | G41: =L41*$C$2 -> 16.430556 | I41: B.F. | J41: 0.7 | K41: 0.35 | L41: 0.28 | T41: B.F. | U41: 0.7 | V41: 0.35 | W41: 0.28 | X41: =IF(T41>0,"per hour","") -> per hour | Y41: =IF(T41>0,"per ","") -> per
...

Sheet EST. SHEET
A1: UNIT COST DERIVATION FORM
A3: PROJECT TITLE:
A4: LOCATION:
A5: ITEM NO. | C5: ITEM OF WORK:
A6: ESTIMATED QUANTITIES: | C6: UNIT:
A7: A. | B7: MATERIALS:
B8: DESCRIPTION | C8: QTY. | D8: UNIT | E8: UNIT COST | F8: AMOUNT
A24: B. | B24: LABOR/MANPOWER:
A25: NO. | B25: DESCRIPTION | C25: NO. | D25: NO.-DAYS | E25: DAILY RATE | F25: AMOUNT
A38: C. | B38: EQUIPMENT/TOOLS:
A39: NO. | B39: DESCRIPTION | C39: NO. | D39: NO.-DAYS | E39: HOURLY RATE | F39: AMOUNT
A56: D | B56: TOTAL DIRECT COST (A+B+C)
A57: E | B57: O.C.M. (% of D)
A58: F | B58: CONTRACTIRS PROFIT (% OF D)
A59: G | B59: VAT (10% Oof B+C)
A60: H | B60: TOTAL COST (D+E+F+G)
A61: I | B61: UNIT COST ( DIRECT)

Sheet EQUIPMENT
A1: PROBABLE OUTPUT OF HEAVY EQUIPMENT
B3: EQUIPMENT | C3: PROBABLE OUTPUT
G5: Clearing & Grubbing | H5: Lot Grading (Cut & Fill) m3 | J5: Trench Excavation | L5: Disposal of Unsuitable Materials m3-km | N5: Road way Excavation (m3) | P5: Embankment/Imported Backfill (m3) | R5: Subgrade Preparation (m2) | T5: Aggregate Sub-base Course (m3) | V5: Aggregate Base Course (m3) | X5: Bituminous Asphalt Pavement (MT) | Z5: Concrete Pavement (m3)
A6: A.1 | B6: EXCAVATOR 200
B7: Excavation | C7: 45 | D7: cu.m./hr. | E7: =1/C7 -> 0.022222222 | F7: hr/m³
B8: Clearing & Grubbing | C8: 150 | D8: sq.m./hr | E8: =1/C8 -> 0.0066666667 | F8: hr/m²
A9: A.1 | B9: DOZER 165 HP
B10: Cutting & Stockpiling | C10: 30 | D10: cu.m./hr. | E10: =1/C10 -> 0.033333333 | F10: hr/m³
B11: Clearing & Grubbing | C11: 300 | D11: sq.m./hr | E11: =1/C11 -> 0.0033333333 | F11: hr/m²
A12: A.2 | B12: DOZER D65P-7 | G12: 300 | H12: 30 | I12: m3/hr | N12: 29.41 | O12: m3/hr
B13: Stripping | C13: 200 | D13: sq.m./hr | E13: =1/C13 -> 0.005 | F13: hr/m²
B14: Excavation | C14: 25 | D14: cu.m./hr. | E14: =1/C14 -> 0.04 | F14: hr/m³
B15: Quarrying | C15: 50 | D15: cu.m./hr. | E15: =1/C15 -> 0.02 | F15: hr/m³
B16: Pushing | C16: 3 | D16: sq.m./hr | E16: =1/C16 -> 0.33333333 | F16: hr/m²
A18: B.1 | B18: LOADER -1.91 CU.M.
B19: Loading | C19: 70 | D19: cu.m./hr. | E19: =1/C19 -> 0.014285714 | F19: hr/m³ | L19: 125 | M19: m3/hr
A20: B.2 | B20: LOADER 950 | H20: 232.55 | I20: m3/hr
A22: C. | B22: DUMP TRUCK - 10 CU.M. | H22: 232.55 | I22: m3/hr | L22: 125 | M22: m3/hr
B23: Hauling (dist. = 600M) | C23: 90 | D23: cu.m./hr. | E23: =1/C23 -> 0.011111111 | F23: hr/m³
A25: D. | B25: GRADER- 130G | H25: 384.62 | I25: m3/hr | P25: 142.86 | Q25: m3/hr | R25: 769.23 | S25: sq.m./hr | T25: 76.92 | U25: m3/hr | V25: 115.38 | W25: m3/hr
B26: 10 Passes | C26: 700 | D26: sq.m./hr | E26: =1/C26 -> 0.0014285714 | F26: hr/m²
B27: Subgrading | C27: 300 | D27: sq.m./hr | E27: =1/C27 -> 0.0033333333 | F27: hr/m²
B28: Spreading | C28: 40 | D28: cu.m./hr. | E28: =1/C28 -> 0.025 | F28: hr/m³
A30: E.1 | B30: ROLLER VIBRATORY | T30: 58.82 | U30: m3/hr | V30: 88.23 | W30: m3/hr | X30: 65 | Y30: MT/hr
B31: 10 Passes | C31: 600 | D31: sq.m./hr | E31: =1/C31 -> 0.0016666667 | F31: hr/m²
B32: SHEETS FOOT ROLLER
B33: Static Rolling 12 passes-15m3 lift
B34: Vibratory Rolling-4 pases-15m3 lift | C34: 135 | D34: cu.m./hr. | E34: =1/C34 -> 0.0074074074 | F34: hr/m³
B35: No.3W Road Roller-static rolling
B36: 4 passes-15 m3 lift | C36: 24 | D36: cu.m./hr. | E36: =1/C36 -> 0.041666667 | F36: hr/m³
B37: Tractor Drawn Roller (1-d)
B38: Static Rolling 6 passes-20m3 lift | C38: 240 | D38: cu.m./hr. | E38: =1/C38 -> 0.0041666667 | F38: hr/m³
B39: Tandem Roller-static rolling
B40: 6 passes-20 m3 lift | C40: 24 | D40: cu.m./hr. | E40: =1/C40 -> 0.041666667 | F40: hr/m³
A42: E.2 | B42: VIBRATORY COMPACTOR CA25D | H42: 303.03 | I42: m3/hr | P42: 125 | Q42: m3/hr | R42: 588.23 | S42: sq.m./hr
A44: G. | B44: WATER TRUCK - 10 CU.M. | H44: 769.23 | I44: m3/hr | P44: 333.33 | Q44: m3/hr | R44: 1666.67 | S44: sq.m./hr | T44: 166.67 | U44: m3/hr | V44: 250 | W44: m3/hr
B45: Watering | C45: 1600 | D45: sq.m./hr | E45: =1/C45 -> 0.000625 | F45: hr/m²
B47: ASPHALT PAVER | X47: 32.5 | Y47: MT/hr
B48: ASPHALT DISTRIBUTOR | C48: SPRAYING PHALT | X48: 300 | Y48: SQ.M.
B49: PLATE COMPACTOR
...

Sheet BONUS DATA - STEEL ERECTION
A1: A. | B1: STRIPPING OF METAL FORMS
B3: MANHOURS PER SQ. METER OF CONTACT AREA
C4: WOOD SHORES 215 TO 316 FLOORS
C5: FORM HEIGHT | E5: LOW | F5: AVERAGE | G5: HIGH
C6: (METER)
C7: 3 TO 4 | E7: 0.58 | F7: 0.22 | G7: 0.16
C8: 4 TO 5 | E8: 0.59 | F8: 0.23 | G8: 0.16
C9: 5 TO 6 | E9: 0.6 | F9: 0.23 | G9: 0.17
C10: 6 TO 7 | E10: 0.61 | F10: 0.24 | G10: 0.17
C11: 7 TO 8 | E11: 0.64 | F11: 0.25 | G11: 0.18
C13: WOOD SHORES 368 TO 419 FLOORS
C14: 3 TO 4 | E14: 0.6 | F14: 0.23 | G14: 0.17
C15: 4 TO 5 | E15: 0.61 | F15: 0.24 | G15: 0.17
C16: 5 TO 6 | E16: 0.64 | F16: 0.25 | G16: 0.18
C17: 6 TO 7 | E17: 0.66 | F17: 0.25 | G17: 0.18
C18: 7 TO 8 | E18: 0.68 | F18: 0.26 | G18: 0.19
B20: CREW: | H20: TOOLS:
B21: 1 | C21: CARPENTER LEAD MAN | E21: 8 | H21: ONE LOT CARPENTRY TOOLS
B22: 3 | C22: CARPENTERS | E22: 24 | H22: 8 | I22: TOOLS HOUR
B23: 6 | C23: HELPERS | E23: 48
B24: =SUM(B21:B23) -> 10 | C24: MANDAYS | E24: =SUM(E21:E23) -> 80 | F24: MANHOURS
A27: B. | B27: STEEL ERECTION FOR MULTI STOREY BUILDING FRAME
B28: PREFAB SECTIONS, HIGHLY MECHANIZED OPERATION
C30: MANHOURS & EQUIPMENTHOUR PER TON ERECTED:
E32: MAN-HOURS | I32: EQUIPMENT-HOURS
E33: LOW | F33: AVERAGE | G33: HIGH | I33: LOW | J33: AVERAGE | K33: HIGH
B34: MEDIUM FRAME | E34: 36 | F34: 13.85 | G34: 10 | I34: 7 | J34: 2.69 | K34: 1.94
B35: HEAVY FRAME | E35: 32.73 | F35: 12.63 | G35: 9.11 | I35: 6.36 | J35: 2.46 | K35: 1.77
B36: STEEL JOIST | E36: 40 | F36: 15.37 | G36: 11.08 | I36: 7.78 | J36: 2.98 | K36: 2.15
B38: CREW: | H38: TOOLS:
B39: 1 | C39: LEAD MAN | E39: 8 | H39: 0.5 | I39: TOWER CRANE | L39: =H39*8 -> 4
B40: 4 | C40: RIGGERS | E40: =B40*8 -> 32 | H40: 2 | I40: WELDING TRANSFORMER | L40: =H40*8 -> 16
B41: 4 | C41: FITTERS | E41: =B41*8 -> 32 | H41: 1 | I41: LOT TOOLS | L41: =H41*8 -> 8
B42: 2 | C42: WELDERS | E42: =B42*8 -> 16 | H42: =SUM(H39:H41) -> 3.5 | L42: =SUM(L39:L41) -> 28 | M42: TOOL HOURS
B43: 1 | C43: CRANE OPERATOR | E43: =B43*8 -> 8
B44: 6 | C44: HELPERS | E44: =B44*8 -> 48
B45: =SUM(B39:B44) -> 18 | C45: MANDAYS | E45: =SUM(E39:E44) -> 144 | F45: MANHOURS
B47: MATERIALS : A36 WELDED CONNECTION
A51: C. | B51: STEEL ERECTION FOR COMMERCIAL AND MILL BUILDING FRAME
B52: PREFAB SECTIONS, HIGHLY MECHANIZED OPERATION
...
