Workbook
Name _100mm: Wall!$AK$11:$AK$14
Name _150mm: Wall!$AL$11:$AL$14
Name _200mm: Wall!$AM$11:$AM$14
Name A: Wall!$AK$11:$AM$11
Name B: Wall!$AK$12:$AM$12
Name C_: Wall!$AK$13:$AM$13
Name D: Wall!$AK$14:$AM$14

Sheet Home Page
A1: STRUCTURAL ESTIMATE
A12: FOOTING | B12: WALL FOOTING | C12: COLUMN | D12: BEAM | E12: SLAB | F12: WALL | G12: MATERIALS PRICE LIST

Sheet Footing
B1: FOOTING ESTIMATE
B6: FOOTING DETAILS
B7: FOOTING | C7: Quantity | D7: Concrete | G7: Concrete Mix Class | I7: Reinforcement (Rebar Length = Automatic)
G8: AA
D9: Length (m) | E9: Width (m) | F9: Thickness (m) | G9: Concrete Cover (mm) | H9: Depth (m) | I9: Along Length | N9: Along Width | AL9: Concrete Volume | AM9: Excavation | AN9: Backfill | AO9: AREA
I10: Bar Size | J10: Economical Bar Length (m) | K10: Cutting Length | L10: Top Bar (pcs) | M10: Bottom Bar (pcs) | N10: Bar Size | O10: Economical Bar Length (m) | P10: Cutting Length | Q10: Top Bar (pcs) | R10: Bottom Bar (pcs) | X10: Tie Wire | Y10: Tie Wire | AY10: Bar size | AZ10: Bar Length | BA10: Along Length | BB10: Quantity | BC10: Along Width | BD10: Quantity
B11: F-1 | C11: 4 | D11: 1.5 | E11: 2 | F11: 0.3 | G11: 70 | H11: 1.5 | I11: 16mm Ø | J11: =AI11 -> 12 | K11: =D11-0.002*G11+2*F11/2 -> 1.66 | L11: 10 | M11: 10 | N11: 12mm Ø | O11: =AX11 -> 9 | P11: =E11-0.002*G11+2*F11/2 -> 2.16 | Q11: 8 | R11: 8 | V11: 10mm Ø | W11: 0.61735018 | X11: =IF(C11>0,Z11*J11*VLOOKUP(I11,$V$11:$W$17,2,FALSE),"") -> 227.57997 | Y11: =IF(C11>0,O11*AA11*VLOOKUP(I11,$V$11:$W$17,2,FALSE),"") -> 227.57997 | Z11: =IF(C11>0,CEILING(C11*K11*(L11+M11)/J11,1),"") -> 12 | AA11: =IF(C11>0,CEILING(C11*P11*(Q11+R11)/O11,1),"") -> 16 | AB11: =K11 -> 1.66 | AC11: =IF(C11>0,AC$21-$AB11*FLOOR(AC$21/$AB11,1),"") -> 1.02 | AD11: =IF(D11>0,AD$21-$AB11*FLOOR(AD$21/$AB11,1),"") -> 0.86 | AE11: =IF(E11>0,AE$21-$AB11*FLOOR(AE$21/$AB11,1),"") -> 0.7 | AF11: =IF(F11>0,AF$21-$AB11*FLOOR(AF$21/$AB11,1),"") -> 0.54 | AG11: =IF(G11>0,AG$21-$AB11*FLOOR(AG$21/$AB11,1),"") -> 0.38 | AH11: =IF(AB11>0,SMALL(AC11:AG11,1),"") -> 0.38 | AI11: =IF(AB11>0,HLOOKUP(AH11,AC11:AG21,11,FALSE),"") -> 12 | AJ11: AA | AK11: 12 | AL11: =C11*D11*E11*F11 -> 3.6 | AM11: =C11*D11*E11*H11*1.05 -> 18.9 | AN11: =AM11-(AL11*1.05) -> 15.12 | AO11: =D11*E11*C11 -> 12 | AQ11: =P11 -> 2.16 | AR11: =IF(C11>0,AR$21-$AQ11*FLOOR(AR$21/$AQ11,1),"") -> 1.68 | AS11: =IF(D11>0,AS$21-$AQ11*FLOOR(AS$21/$AQ11,1),"") -> 1.02 | AT11: =IF(E11>0,AT$21-$AQ11*FLOOR(AT$21/$AQ11,1),"") -> 0.36 | AU11: =IF(F11>0,AU$21-$AQ11*FLOOR(AU$21/$AQ11,1),"") -> 1.86 | AV11: =IF(G11>0,AV$21-$AQ11*FLOOR(AV$21/$AQ11,1),"") -> 1.2 | AW11: =IF(AQ11>0,SMALL(AR11:AV11,1),"") -> 0.36 | AX11: =IF(AQ11>0,HLOOKUP(AW11,AR11:AV21,11,FALSE),"") -> 9
B12: F-2 | J12: =AI12 | K12: =D12-0.002*G12+2*F12/2 -> 0 | O12: =AX12 | P12: =E12-0.002*G12+2*F12/2 -> 0 | V12: 12mm Ø | W12: 0.88898426 | X12: =IF(C12>0,Z12*J12*VLOOKUP(I12,$V$11:$W$17,2,FALSE),"") | Y12: =IF(C12>0,O12*AA12*VLOOKUP(I12,$V$11:$W$17,2,FALSE),"") | Z12: =IF(C12>0,CEILING(C12*K12*(L12+M12)/J12,1),"") | AA12: =IF(C12>0,CEILING(C12*P12*(Q12+R12)/O12,1),"") | AB12: =K12 -> 0 | AC12: =IF(C12>0,AC$21-$AB12*FLOOR(AC$21/$AB12,1),"") | AD12: =IF(D12>0,AD$21-$AB12*FLOOR(AD$21/$AB12,1),"") | AE12: =IF(E12>0,AE$21-$AB12*FLOOR(AE$21/$AB12,1),"") | AF12: =IF(F12>0,AF$21-$AB12*FLOOR(AF$21/$AB12,1),"") | AG12: =IF(G12>0,AG$21-$AB12*FLOOR(AG$21/$AB12,1),"") | AH12: =IF(AB12>0,SMALL(AC12:AG12,1),"") | AI12: =IF(AB12>0,HLOOKUP(AH12,AC12:AG22,10,FALSE),"") | AJ12: A | AK12: 10 | AL12: =C12*D12*E12*F12 -> 0 | AM12: =C12*D12*E12*H12*1.05 -> 0 | AN12: =AM12-(AL12*1.15) -> 0 | AO12: =D12*E12*C12 -> 0 | AQ12: =P12 -> 0 | AR12: =IF(C12>0,AR$21-$AQ12*FLOOR(AR$21/$AQ12,1),"") | AS12: =IF(D12>0,AS$21-$AQ12*FLOOR(AS$21/$AQ12,1),"") | AT12: =IF(E12>0,AT$21-$AQ12*FLOOR(AT$21/$AQ12,1),"") | AU12: =IF(F12>0,AU$21-$AQ12*FLOOR(AU$21/$AQ12,1),"") | AV12: =IF(G12>0,AV$21-$AQ12*FLOOR(AV$21/$AQ12,1),"") | AW12: =IF(AQ12>0,SMALL(AR12:AV12,1),"") | AX12: =IF(AQ12>0,HLOOKUP(AW12,AR12:AV22,10,FALSE),"")
B13: F-3 | J13: =AI13 | K13: =D13-0.002*G13+2*F13/2 -> 0 | O13: =AX13 | P13: =E13-0.002*G13+2*F13/2 -> 0 | V13: 16mm Ø | W13: 1.5804165 | X13: =IF(C13>0,Z13*J13*VLOOKUP(I13,$V$11:$W$17,2,FALSE),"") | Y13: =IF(C13>0,O13*AA13*VLOOKUP(I13,$V$11:$W$17,2,FALSE),"") | Z13: =IF(C13>0,CEILING(C13*K13*(L13+M13)/J13,1),"") | AA13: =IF(C13>0,CEILING(C13*P13*(Q13+R13)/O13,1),"") | AB13: =K13 -> 0 | AC13: =IF(C13>0,AC$21-$AB13*FLOOR(AC$21/$AB13,1),"") | AD13: =IF(D13>0,AD$21-$AB13*FLOOR(AD$21/$AB13,1),"") | AE13: =IF(E13>0,AE$21-$AB13*FLOOR(AE$21/$AB13,1),"") | AF13: =IF(F13>0,AF$21-$AB13*FLOOR(AF$21/$AB13,1),"") | AG13: =IF(G13>0,AG$21-$AB13*FLOOR(AG$21/$AB13,1),"") | AH13: =IF(AB13>0,SMALL(AC13:AG13,1),"") | AI13: =IF(AB13>0,HLOOKUP(AH13,AC13:AG23,9,FALSE),"") | AJ13: B | AK13: 8 | AL13: =C13*D13*E13*F13 -> 0 | AM13: =C13*D13*E13*H13*1.05 -> 0 | AN13: =AM13-(AL13*1.15) -> 0 | AO13: =D13*E13*C13 -> 0 | AQ13: =P13 -> 0 | AR13: =IF(C13>0,AR$21-$AQ13*FLOOR(AR$21/$AQ13,1),"") | AS13: =IF(D13>0,AS$21-$AQ13*FLOOR(AS$21/$AQ13,1),"") | AT13: =IF(E13>0,AT$21-$AQ13*FLOOR(AT$21/$AQ13,1),"") | AU13: =IF(F13>0,AU$21-$AQ13*FLOOR(AU$21/$AQ13,1),"") | AV13: =IF(G13>0,AV$21-$AQ13*FLOOR(AV$21/$AQ13,1),"") | AW13: =IF(AQ13>0,SMALL(AR13:AV13,1),"") | AX13: =IF(AQ13>0,HLOOKUP(AW13,AR13:AV23,9,FALSE),"")
B14: F-4 | J14: =AI14 | K14: =D14-0.002*G14+2*F14/2 -> 0 | O14: =AX14 | P14: =E14-0.002*G14+2*F14/2 -> 0 | V14: 20mm Ø | W14: 2.4694007 | X14: =IF(C14>0,Z14*J14*VLOOKUP(I14,$V$11:$W$17,2,FALSE),"") | Y14: =IF(C14>0,O14*AA14*VLOOKUP(I14,$V$11:$W$17,2,FALSE),"") | Z14: =IF(C14>0,CEILING(C14*K14*(L14+M14)/J14,1),"") | AA14: =IF(C14>0,CEILING(C14*P14*(Q14+R14)/O14,1),"") | AB14: =K14 -> 0 | AC14: =IF(C14>0,AC$21-$AB14*FLOOR(AC$21/$AB14,1),"") | AD14: =IF(D14>0,AD$21-$AB14*FLOOR(AD$21/$AB14,1),"") | AE14: =IF(E14>0,AE$21-$AB14*FLOOR(AE$21/$AB14,1),"") | AF14: =IF(F14>0,AF$21-$AB14*FLOOR(AF$21/$AB14,1),"") | AG14: =IF(G14>0,AG$21-$AB14*FLOOR(AG$21/$AB14,1),"") | AH14: =IF(AB14>0,SMALL(AC14:AG14,1),"") | AI14: =IF(AB14>0,HLOOKUP(AH14,AC14:AG24,8,FALSE),"") | AJ14: C | AK14: 6.5 | AL14: =C14*D14*E14*F14 -> 0 | AM14: =C14*D14*E14*H14*1.05 -> 0 | AN14: =AM14-(AL14*1.15) -> 0 | AO14: =D14*E14*C14 -> 0 | AQ14: =P14 -> 0 | AR14: =IF(C14>0,AR$21-$AQ14*FLOOR(AR$21/$AQ14,1),"") | AS14: =IF(D14>0,AS$21-$AQ14*FLOOR(AS$21/$AQ14,1),"") | AT14: =IF(E14>0,AT$21-$AQ14*FLOOR(AT$21/$AQ14,1),"") | AU14: =IF(F14>0,AU$21-$AQ14*FLOOR(AU$21/$AQ14,1),"") | AV14: =IF(G14>0,AV$21-$AQ14*FLOOR(AV$21/$AQ14,1),"") | AW14: =IF(AQ14>0,SMALL(AR14:AV14,1),"") | AX14: =IF(AQ14>0,HLOOKUP(AW14,AR14:AV24,8,FALSE),"") | AY14: =IF(AQ14>0,SMALL(AR14:AV14,1),"") | AZ14: =IF(AQ14>0,HLOOKUP(AY14,AR14:AV24,8,FALSE),"")
B15: F-5 | J15: =AI15 | K15: =D15-0.002*G15+2*F15/2 -> 0 | O15: =AX15 | P15: =E15-0.002*G15+2*F15/2 -> 0 | V15: 25mm Ø | W15: 3.8584386 | X15: =IF(C15>0,Z15*J15*VLOOKUP(I15,$V$11:$W$17,2,FALSE),"") | Y15: =IF(C15>0,O15*AA15*VLOOKUP(I15,$V$11:$W$17,2,FALSE),"") | Z15: =IF(C15>0,CEILING(C15*K15*(L15+M15)/J15,1),"") | AA15: =IF(C15>0,CEILING(C15*P15*(Q15+R15)/O15,1),"") | AB15: =K15 -> 0 | AC15: =IF(C15>0,AC$21-$AB15*FLOOR(AC$21/$AB15,1),"") | AD15: =IF(D15>0,AD$21-$AB15*FLOOR(AD$21/$AB15,1),"") | AE15: =IF(E15>0,AE$21-$AB15*FLOOR(AE$21/$AB15,1),"") | AF15: =IF(F15>0,AF$21-$AB15*FLOOR(AF$21/$AB15,1),"") | AG15: =IF(G15>0,AG$21-$AB15*FLOOR(AG$21/$AB15,1),"") | AH15: =IF(AB15>0,SMALL(AC15:AG15,1),"") | AI15: =IF(AB15>0,HLOOKUP(AH15,AC15:AG29,7,FALSE),"") | AL15: =C15*D15*E15*F15 -> 0 | AM15: =C15*D15*E15*H15*1.05 -> 0 | AN15: =AM15-(AL15*1.15) -> 0 | AO15: =D15*E15*C15 -> 0 | AQ15: =P15 -> 0 | AR15: =IF(C15>0,AR$21-$AQ15*FLOOR(AR$21/$AQ15,1),"") | AS15: =IF(D15>0,AS$21-$AQ15*FLOOR(AS$21/$AQ15,1),"") | AT15: =IF(E15>0,AT$21-$AQ15*FLOOR(AT$21/$AQ15,1),"") | AU15: =IF(F15>0,AU$21-$AQ15*FLOOR(AU$21/$AQ15,1),"") | AV15: =IF(G15>0,AV$21-$AQ15*FLOOR(AV$21/$AQ15,1),"") | AW15: =IF(AQ15>0,SMALL(AR15:AV15,1),"") | AX15: =IF(AQ15>0,HLOOKUP(AW15,AR15:AV29,7,FALSE),"") | AY15: =IF(AQ15>0,SMALL(AR15:AV15,1),"") | AZ15: =IF(AQ15>0,HLOOKUP(AY15,AR15:AV29,7,FALSE),"")
B16: F-6 | J16: =AI16 | K16: =D16-0.002*G16+2*F16/2 -> 0 | O16: =AX16 | P16: =E16-0.002*G16+2*F16/2 -> 0 | V16: 28mm Ø | W16: 4.8400254 | X16: =IF(C16>0,Z16*J16*VLOOKUP(I16,$V$11:$W$17,2,FALSE),"") | Y16: =IF(C16>0,O16*AA16*VLOOKUP(I16,$V$11:$W$17,2,FALSE),"") | Z16: =IF(C16>0,CEILING(C16*K16*(L16+M16)/J16,1),"") | AA16: =IF(C16>0,CEILING(C16*P16*(Q16+R16)/O16,1),"") | AB16: =K16 -> 0 | AC16: =IF(C16>0,AC$21-$AB16*FLOOR(AC$21/$AB16,1),"") | AD16: =IF(D16>0,AD$21-$AB16*FLOOR(AD$21/$AB16,1),"") | AE16: =IF(E16>0,AE$21-$AB16*FLOOR(AE$21/$AB16,1),"") | AF16: =IF(F16>0,AF$21-$AB16*FLOOR(AF$21/$AB16,1),"") | AG16: =IF(G16>0,AG$21-$AB16*FLOOR(AG$21/$AB16,1),"") | AH16: =IF(AB16>0,SMALL(AC16:AG16,1),"") | AI16: =IF(AB16>0,HLOOKUP(AH16,AC16:AG31,6,FALSE),"") | AL16: =C16*D16*E16*F16 -> 0 | AM16: =C16*D16*E16*H16*1.05 -> 0 | AN16: =AM16-(AL16*1.15) -> 0 | AO16: =D16*E16*C16 -> 0 | AQ16: =P16 -> 0 | AR16: =IF(C16>0,AR$21-$AQ16*FLOOR(AR$21/$AQ16,1),"") | AS16: =IF(D16>0,AS$21-$AQ16*FLOOR(AS$21/$AQ16,1),"") | AT16: =IF(E16>0,AT$21-$AQ16*FLOOR(AT$21/$AQ16,1),"") | AU16: =IF(F16>0,AU$21-$AQ16*FLOOR(AU$21/$AQ16,1),"") | AV16: =IF(G16>0,AV$21-$AQ16*FLOOR(AV$21/$AQ16,1),"") | AW16: =IF(AQ16>0,SMALL(AR16:AV16,1),"") | AX16: =IF(AQ16>0,HLOOKUP(AW16,AR16:AV31,6,FALSE),"") | AY16: =IF(AQ16>0,SMALL(AR16:AV16,1),"") | AZ16: =IF(AQ16>0,HLOOKUP(AY16,AR16:AV31,6,FALSE),"")
B17: F-7 | J17: =AI17 | K17: =D17-0.002*G17+2*F17/2 -> 0 | O17: =AX17 | P17: =E17-0.002*G17+2*F17/2 -> 0 | V17: 32mm Ø | W17: 6.3216658 | X17: =IF(C17>0,Z17*J17*VLOOKUP(I17,$V$11:$W$17,2,FALSE),"") | Y17: =IF(C17>0,O17*AA17*VLOOKUP(I17,$V$11:$W$17,2,FALSE),"") | Z17: =IF(C17>0,CEILING(C17*K17*(L17+M17)/J17,1),"") | AA17: =IF(C17>0,CEILING(C17*P17*(Q17+R17)/O17,1),"") | AB17: =K17 -> 0 | AC17: =IF(C17>0,AC$21-$AB17*FLOOR(AC$21/$AB17,1),"") | AD17: =IF(D17>0,AD$21-$AB17*FLOOR(AD$21/$AB17,1),"") | AE17: =IF(E17>0,AE$21-$AB17*FLOOR(AE$21/$AB17,1),"") | AF17: =IF(F17>0,AF$21-$AB17*FLOOR(AF$21/$AB17,1),"") | AG17: =IF(G17>0,AG$21-$AB17*FLOOR(AG$21/$AB17,1),"") | AH17: =IF(AB17>0,SMALL(AC17:AG17,1),"") | AI17: =IF(AB17>0,HLOOKUP(AH17,AC17:AG33,5,FALSE),"") | AL17: =C17*D17*E17*F17 -> 0 | AM17: =C17*D17*E17*H17*1.05 -> 0 | AN17: =AM17-(AL17*1.15) -> 0 | AO17: =D17*E17*C17 -> 0 | AQ17: =P17 -> 0 | AR17: =IF(C17>0,AR$21-$AQ17*FLOOR(AR$21/$AQ17,1),"") | AS17: =IF(D17>0,AS$21-$AQ17*FLOOR(AS$21/$AQ17,1),"") | AT17: =IF(E17>0,AT$21-$AQ17*FLOOR(AT$21/$AQ17,1),"") | AU17: =IF(F17>0,AU$21-$AQ17*FLOOR(AU$21/$AQ17,1),"") | AV17: =IF(G17>0,AV$21-$AQ17*FLOOR(AV$21/$AQ17,1),"") | AW17: =IF(AQ17>0,SMALL(AR17:AV17,1),"") | AX17: =IF(AQ17>0,HLOOKUP(AW17,AR17:AV33,5,FALSE),"") | AY17: =IF(AQ17>0,SMALL(AR17:AV17,1),"") | AZ17: =IF(AQ17>0,HLOOKUP(AY17,AR17:AV33,5,FALSE),"")
B18: F-8 | J18: =AI18 | K18: =D18-0.002*G18+2*F18/2 -> 0 | O18: =AX18 | P18: =E18-0.002*G18+2*F18/2 -> 0 | X18: =IF(C18>0,Z18*J18*VLOOKUP(I18,$V$11:$W$17,2,FALSE),"") | Y18: =IF(C18>0,O18*AA18*VLOOKUP(I18,$V$11:$W$17,2,FALSE),"") | Z18: =IF(C18>0,CEILING(C18*K18*(L18+M18)/J18,1),"") | AA18: =IF(C18>0,CEILING(C18*P18*(Q18+R18)/O18,1),"") | AB18: =K18 -> 0 | AC18: =IF(C18>0,AC$21-$AB18*FLOOR(AC$21/$AB18,1),"") | AD18: =IF(D18>0,AD$21-$AB18*FLOOR(AD$21/$AB18,1),"") | AE18: =IF(E18>0,AE$21-$AB18*FLOOR(AE$21/$AB18,1),"") | AF18: =IF(F18>0,AF$21-$AB18*FLOOR(AF$21/$AB18,1),"") | AG18: =IF(G18>0,AG$21-$AB18*FLOOR(AG$21/$AB18,1),"") | AH18: =IF(AB18>0,SMALL(AC18:AG18,1),"") | AI18: =IF(AB18>0,HLOOKUP(AH18,AC18:AG35,4,FALSE),"") | AL18: =C18*D18*E18*F18 -> 0 | AM18: =C18*D18*E18*H18*1.05 -> 0 | AN18: =AM18-(AL18*1.15) -> 0 | AO18: =D18*E18*C18 -> 0 | AQ18: =P18 -> 0 | AR18: =IF(C18>0,AR$21-$AQ18*FLOOR(AR$21/$AQ18,1),"") | AS18: =IF(D18>0,AS$21-$AQ18*FLOOR(AS$21/$AQ18,1),"") | AT18: =IF(E18>0,AT$21-$AQ18*FLOOR(AT$21/$AQ18,1),"") | AU18: =IF(F18>0,AU$21-$AQ18*FLOOR(AU$21/$AQ18,1),"") | AV18: =IF(G18>0,AV$21-$AQ18*FLOOR(AV$21/$AQ18,1),"") | AW18: =IF(AQ18>0,SMALL(AR18:AV18,1),"") | AX18: =IF(AQ18>0,HLOOKUP(AW18,AR18:AV35,4,FALSE),"") | AY18: =IF(AQ18>0,SMALL(AR18:AV18,1),"") | AZ18: =IF(AQ18>0,HLOOKUP(AY18,AR18:AV35,4,FALSE),"")
B19: F-9 | J19: =AI19 | K19: =D19-0.002*G19+2*F19/2 -> 0 | O19: =AX19 | P19: =E19-0.002*G19+2*F19/2 -> 0 | X19: =IF(C19>0,Z19*J19*VLOOKUP(I19,$V$11:$W$17,2,FALSE),"") | Y19: =IF(C19>0,O19*AA19*VLOOKUP(I19,$V$11:$W$17,2,FALSE),"") | Z19: =IF(C19>0,CEILING(C19*K19*(L19+M19)/J19,1),"") | AA19: =IF(C19>0,CEILING(C19*P19*(Q19+R19)/O19,1),"") | AB19: =K19 -> 0 | AC19: =IF(C19>0,AC$21-$AB19*FLOOR(AC$21/$AB19,1),"") | AD19: =IF(D19>0,AD$21-$AB19*FLOOR(AD$21/$AB19,1),"") | AE19: =IF(E19>0,AE$21-$AB19*FLOOR(AE$21/$AB19,1),"") | AF19: =IF(F19>0,AF$21-$AB19*FLOOR(AF$21/$AB19,1),"") | AG19: =IF(G19>0,AG$21-$AB19*FLOOR(AG$21/$AB19,1),"") | AH19: =IF(AB19>0,SMALL(AC19:AG19,1),"") | AI19: =IF(AB19>0,HLOOKUP(AH19,AC19:AG37,3,FALSE),"") | AL19: =C19*D19*E19*F19 -> 0 | AM19: =C19*D19*E19*H19*1.05 -> 0 | AN19: =AM19-(AL19*1.15) -> 0 | AO19: =D19*E19*C19 -> 0 | AQ19: =P19 -> 0 | AR19: =IF(C19>0,AR$21-$AQ19*FLOOR(AR$21/$AQ19,1),"") | AS19: =IF(D19>0,AS$21-$AQ19*FLOOR(AS$21/$AQ19,1),"") | AT19: =IF(E19>0,AT$21-$AQ19*FLOOR(AT$21/$AQ19,1),"") | AU19: =IF(F19>0,AU$21-$AQ19*FLOOR(AU$21/$AQ19,1),"") | AV19: =IF(G19>0,AV$21-$AQ19*FLOOR(AV$21/$AQ19,1),"") | AW19: =IF(AQ19>0,SMALL(AR19:AV19,1),"") | AX19: =IF(AQ19>0,HLOOKUP(AW19,AR19:AV37,3,FALSE),"") | AY19: =IF(AQ19>0,SMALL(AR19:AV19,1),"") | AZ19: =IF(AQ19>0,HLOOKUP(AY19,AR19:AV37,3,FALSE),"")
B20: F-10 | J20: =AI20 | K20: =D20-0.002*G20+2*F20/2 -> 0 | O20: =AX20 | P20: =E20-0.002*G20+2*F20/2 -> 0 | X20: =IF(C20>0,Z20*J20*VLOOKUP(I20,$V$11:$W$17,2,FALSE),"") | Y20: =IF(C20>0,O20*AA20*VLOOKUP(I20,$V$11:$W$17,2,FALSE),"") | Z20: =IF(C20>0,CEILING(C20*K20*(L20+M20)/J20,1),"") | AA20: =IF(C20>0,CEILING(C20*P20*(Q20+R20)/O20,1),"") | AB20: =K20 -> 0 | AC20: =IF(C20>0,AC$21-$AB20*FLOOR(AC$21/$AB20,1),"") | AD20: =IF(D20>0,AD$21-$AB20*FLOOR(AD$21/$AB20,1),"") | AE20: =IF(E20>0,AE$21-$AB20*FLOOR(AE$21/$AB20,1),"") | AF20: =IF(F20>0,AF$21-$AB20*FLOOR(AF$21/$AB20,1),"") | AG20: =IF(G20>0,AG$21-$AB20*FLOOR(AG$21/$AB20,1),"") | AH20: =IF(AB20>0,SMALL(AC20:AG20,1),"") | AI20: =IF(AB20>0,HLOOKUP(AH20,AC20:AG39,2,FALSE),"") | AL20: =C20*D20*E20*F20 -> 0 | AM20: =C20*D20*E20*H20*1.05 -> 0 | AN20: =AM20-(AL20*1.15) -> 0 | AO20: =D20*E20*C20 -> 0 | AQ20: =P20 -> 0 | AR20: =IF(C20>0,AR$21-$AQ20*FLOOR(AR$21/$AQ20,1),"") | AS20: =IF(D20>0,AS$21-$AQ20*FLOOR(AS$21/$AQ20,1),"") | AT20: =IF(E20>0,AT$21-$AQ20*FLOOR(AT$21/$AQ20,1),"") | AU20: =IF(F20>0,AU$21-$AQ20*FLOOR(AU$21/$AQ20,1),"") | AV20: =IF(G20>0,AV$21-$AQ20*FLOOR(AV$21/$AQ20,1),"") | AW20: =IF(AQ20>0,SMALL(AR20:AV20,1),"") | AX20: =IF(AQ20>0,HLOOKUP(AW20,AR20:AV39,2,FALSE),"") | AY20: =IF(AQ20>0,SMALL(AR20:AV20,1),"") | AZ20: =IF(AQ20>0,HLOOKUP(AY20,AR20:AV39,2,FALSE),"")
X21: =SUM(X11:X17) -> 227.57997 | Y21: =SUM(Y11:Y17) -> 227.57997 | AC21: 6 | AD21: =AC21+1.5 -> 7.5 | AE21: =AD21+1.5 -> 9 | AF21: =AE21+1.5 -> 10.5 | AG21: =AF21+1.5 -> 12 | AL21: =SUM(AL11:AL20) -> 3.6 | AM21: =SUM(AM11:AM20) -> 18.9 | AN21: =SUM(AN11:AN20) -> 15.12 | AR21: 6 | AS21: =AR21+1.5 -> 7.5 | AT21: =AS21+1.5 -> 9 | AU21: =AT21+1.5 -> 10.5 | AV21: =AU21+1.5 -> 12
F22: MATERIALS | X22: =X21+Y21 -> 455.15994 | AL22: =VLOOKUP(G8,AJ11:AK14,2,FALSE) -> 12
X23: Tie Wire | Y23: =CEILING(0.013*X22,0.5) -> 6 | AK23: Cement | AL23: =CEILING(AL22*AL21,1) -> 44
F24: FOOTING | G24: ITEM | H24: QUANTITY | I24: UNIT | J24: PRICE | K24: TOTAL COST | AK24: Sand | AL24: =AL21/2 -> 1.8
G25: ='Materials Price List'!A8 -> Cement | H25: =AL23 -> 44 | I25: bags | J25: =IF(H25="","",VLOOKUP(G25,'Materials Price List'!$A$8:$B$46,2,FALSE)) -> 220 | K25: =IF(H25="","",H25*J25) -> 9680 | AK25: Gravel | AL25: =AL21 -> 3.6
G26: ='Materials Price List'!A9 -> Sand | H26: =AL24 -> 1.8 | I26: cu.m | J26: =IF(H26="","",VLOOKUP(G26,'Materials Price List'!$A$8:$B$46,2,FALSE)) -> 875 | K26: =IF(H26="","",H26*J26) -> 1575
G27: ='Materials Price List'!A10 -> Gravel | H27: =AL25 -> 3.6 | I27: cu.m | J27: =IF(H27="","",VLOOKUP(G27,'Materials Price List'!$A$8:$B$46,2,FALSE)) -> 1875 | K27: =IF(H27="","",H27*J27) -> 6750
G28: Tie Wire | H28: =Y23 -> 6 | I28: kg | J28: =IF(H28="","",VLOOKUP(G28,'Materials Price List'!$A$8:$B$46,2,FALSE)) -> 95 | K28: =IF(H28="","",H28*J28) -> 570
F29: =IF(C11>0,B11,"") -> F-1 | G29: =IF(C11>0,CONCATENATE(I11," X ",J11,"m"),"") -> 16mm Ø X 12m | H29: =Z11 -> 12 | I29: =IF(H29="","","pcs") -> pcs | J29: =IF(H29="","",VLOOKUP(G29,'Materials Price List'!$A$8:$B$46,2)) -> 471.76056 | K29: =IF(H29="","",H29*J29) -> 5661.1268
F30: =F29 -> F-1 | G30: =IF(C11>0,CONCATENATE(N11," X ",O11,"m"),"") -> 12mm Ø X 9m | H30: =AA11 -> 16 | I30: =IF(H30="","","pcs") -> pcs | J30: =IF(H30="","",VLOOKUP(G30,'Materials Price List'!$A$8:$B$46,2)) -> 354.40141 | K30: =IF(H30="","",H30*J30) -> 5670.4225
F31: =IF(C12>0,B12,"") | G31: =IF(C12>0,CONCATENATE(I12," X ",J12,"m"),"") | H31: =Z12 | I31: =IF(H31="","","pcs") | J31: =IF(H31="","",VLOOKUP(G31,'Materials Price List'!$A$8:$B$46,2)) | K31: =IF(H31="","",H31*J31)
F32: =F31 | G32: =IF(C12>0,CONCATENATE(N12," X ",O12,"m"),"") | H32: =AA12 | I32: =IF(H32="","","pcs") | J32: =IF(H32="","",VLOOKUP(G32,'Materials Price List'!$A$8:$B$46,2)) | K32: =IF(H32="","",H32*J32)
F33: =IF(C13>0,B13,"") | G33: =IF(C13>0,CONCATENATE(I13," X ",J13,"m"),"") | H33: =Z13 | I33: =IF(H33="","","pcs") | J33: =IF(H33="","",VLOOKUP(G33,'Materials Price List'!$A$8:$B$46,2)) | K33: =IF(H33="","",H33*J33)
F34: =F33 | G34: =IF(C13>0,CONCATENATE(N13," X ",O13,"m"),"") | H34: =AA13 | I34: =IF(H34="","","pcs") | J34: =IF(H34="","",VLOOKUP(G34,'Materials Price List'!$A$8:$B$46,2)) | K34: =IF(H34="","",H34*J34)
F35: =IF(C14>0,B14,"") | G35: =IF(C14>0,CONCATENATE(I14," X ",J14,"m"),"") | H35: =Z14 | I35: =IF(H35="","","pcs") | J35: =IF(H35="","",VLOOKUP(G35,'Materials Price List'!$A$8:$B$46,2)) | K35: =IF(H35="","",H35*J35)
F36: =F35 | G36: =IF(C14>0,CONCATENATE(N14," X ",O14,"m"),"") | H36: =AA14 | I36: =IF(H36="","","pcs") | J36: =IF(H36="","",VLOOKUP(G36,'Materials Price List'!$A$8:$B$46,2)) | K36: =IF(H36="","",H36*J36)
F37: =IF(C15>0,B15,"") | G37: =IF(C15>0,CONCATENATE(I15," X ",J15,"m"),"") | H37: =Z15 | I37: =IF(H37="","","pcs") | J37: =IF(H37="","",VLOOKUP(G37,'Materials Price List'!$A$8:$B$46,2)) | K37: =IF(H37="","",H37*J37)
F38: =F37 | G38: =IF(C15>0,CONCATENATE(N15," X ",O15,"m"),"") | H38: =AA15 | I38: =IF(H38="","","pcs") | J38: =IF(H38="","",VLOOKUP(G38,'Materials Price List'!$A$8:$B$46,2)) | K38: =IF(H38="","",H38*J38)
F39: =IF(C16>0,B16,"") | G39: =IF(C16>0,CONCATENATE(I16," X ",J16,"m"),"") | H39: =Z16 | I39: =IF(H39="","","pcs") | J39: =IF(H39="","",VLOOKUP(G39,'Materials Price List'!$A$8:$B$46,2)) | K39: =IF(H39="","",H39*J39)
F40: =F39 | G40: =IF(C16>0,CONCATENATE(N16," X ",O16,"m"),"") | H40: =AA16 | I40: =IF(H40="","","pcs") | J40: =IF(H40="","",VLOOKUP(G40,'Materials Price List'!$A$8:$B$46,2)) | K40: =IF(H40="","",H40*J40)
F41: =IF(C17>0,B17,"") | G41: =IF(C17>0,CONCATENATE(I17," X ",J17,"m"),"") | H41: =Z17 | I41: =IF(H41="","","pcs") | J41: =IF(H41="","",VLOOKUP(G41,'Materials Price List'!$A$8:$B$46,2)) | K41: =IF(H41="","",H41*J41)
F42: =F41 | G42: =IF(C17>0,CONCATENATE(N17," X ",O17,"m"),"") | H42: =AA17 | I42: =IF(H42="","","pcs") | J42: =IF(H42="","",VLOOKUP(G42,'Materials Price List'!$A$8:$B$46,2)) | K42: =IF(H42="","",H42*J42)
F43: =IF(C18>0,B18,"") | G43: =IF(C18>0,CONCATENATE(I18," X ",J18,"m"),"") | H43: =Z18 | I43: =IF(H43="","","pcs") | J43: =IF(H43="","",VLOOKUP(G43,'Materials Price List'!$A$8:$B$46,2)) | K43: =IF(H43="","",H43*J43)
F44: =F43 | G44: =IF(C18>0,CONCATENATE(N18," X ",O18,"m"),"") | H44: =AA18 | I44: =IF(H44="","","pcs") | J44: =IF(H44="","",VLOOKUP(G44,'Materials Price List'!$A$8:$B$46,2)) | K44: =IF(H44="","",H44*J44)
...

Sheet Wall Footing
B1: WALL FOOTING ESTIMATE
B6: WALL FOOTING DETAILS
B7: WALL FOOTING | C7: Quantity | D7: Concrete | G7: Concrete Mix Class | I7: Reinforcement (Rebar Length = Manual)
G8: B
D9: Length (m) | E9: Width (m) | F9: Thickness (m) | G9: Concrete Cover (mm) | H9: Depth (m) | I9: Along Length | N9: Along Width | AL9: Concrete Volume | AM9: Excavation | AN9: Backfill | AO9: AREA
I10: Bar Size | J10: Economical Bar Length (m) | K10: Steel Bars Length | L10: Main Bars (pcs) | M10: Temperature Bars (spacing) (mm) | N10: Bar Size | O10: Economical Bar Length (m) | P10: Cutting Length | Q10: Top Bar (pcs) | R10: Bottom Bar (pcs) | X10: Tie Wire | Y10: Tie Wire | AY10: Bar size | AZ10: Bar Length | BA10: Along Length | BB10: Quantity | BC10: Along Width | BD10: Quantity
B11: WF-1 | C11: 3 | D11: 10 | E11: 0.75 | F11: 0.25 | G11: 40 | H11: 1 | I11: 12mm Ø | J11: =K11 -> 6 | K11: 6 | L11: 4 | M11: 400 | N11: 10mm Ø | O11: =K11 -> 6 | P11: =E11-0.002*G11+2*F11/2 -> 0.92 | V11: 10mm Ø | W11: 0.61735018 | X11: =IF(C11>0,Z11*J11*VLOOKUP(I11,$V$11:$W$17,2,FALSE),"") -> 117.34592 | Y11: =IF(C11>0,O11*AA11*VLOOKUP(I11,$V$11:$W$17,2,FALSE),"") -> 53.339055 | Z11: =IF(C11>0,CEILING(C11*D11*(L11)/(J11-0.5),1),"") -> 22 | AA11: =IF(C11>0,CEILING(C11*(E11*D11*1000/M11/K11),1),"") -> 10 | AB11: =K11 -> 6 | AC11: =IF(C11>0,AC$21-$AB11*FLOOR(AC$21/$AB11,1),"") -> 0 | AD11: =IF(D11>0,AD$21-$AB11*FLOOR(AD$21/$AB11,1),"") -> 1.5 | AE11: =IF(E11>0,AE$21-$AB11*FLOOR(AE$21/$AB11,1),"") -> 3 | AF11: =IF(F11>0,AF$21-$AB11*FLOOR(AF$21/$AB11,1),"") -> 4.5 | AG11: =IF(G11>0,AG$21-$AB11*FLOOR(AG$21/$AB11,1),"") -> 0 | AH11: =IF(AB11>0,SMALL(AC11:AG11,1),"") -> 0 | AI11: =IF(AB11>0,HLOOKUP(AH11,AC11:AG21,11,FALSE),"") -> 6 | AJ11: AA | AK11: 12 | AL11: =C11*D11*E11*F11 -> 5.625 | AM11: =C11*D11*E11*H11*1.05 -> 23.625 | AN11: =AM11-(AL11*1.05) -> 17.71875 | AO11: =D11*E11*C11 -> 22.5 | AQ11: =P11 -> 0.92 | AR11: =IF(C11>0,AR$21-$AQ11*FLOOR(AR$21/$AQ11,1),"") -> 0.48 | AS11: =IF(D11>0,AS$21-$AQ11*FLOOR(AS$21/$AQ11,1),"") -> 0.14 | AT11: =IF(E11>0,AT$21-$AQ11*FLOOR(AT$21/$AQ11,1),"") -> 0.72 | AU11: =IF(F11>0,AU$21-$AQ11*FLOOR(AU$21/$AQ11,1),"") -> 0.38 | AV11: =IF(G11>0,AV$21-$AQ11*FLOOR(AV$21/$AQ11,1),"") -> 0.04 | AW11: =IF(AQ11>0,SMALL(AR11:AV11,1),"") -> 0.04 | AX11: =IF(AQ11>0,HLOOKUP(AW11,AR11:AV21,11,FALSE),"") -> 12
B12: WF-2 | J12: =K12 -> 0 | N12: 10mm Ø | O12: =K12 -> 0 | P12: =E12-0.002*G12+2*F12/2 -> 0 | V12: 12mm Ø | W12: 0.88898426 | X12: =IF(C12>0,Z12*J12*VLOOKUP(I12,$V$11:$W$17,2,FALSE),"") | Y12: =IF(C12>0,O12*AA12*VLOOKUP(I12,$V$11:$W$17,2,FALSE),"") | Z12: =IF(C12>0,CEILING(C12*D12*(L12)/(J12-0.5),1),"") | AA12: =IF(C12>0,CEILING(C12*(E12*D12*1000/M12/K12),1),"") | AB12: =K12 -> 0 | AC12: =IF(C12>0,AC$21-$AB12*FLOOR(AC$21/$AB12,1),"") | AD12: =IF(D12>0,AD$21-$AB12*FLOOR(AD$21/$AB12,1),"") | AE12: =IF(E12>0,AE$21-$AB12*FLOOR(AE$21/$AB12,1),"") | AF12: =IF(F12>0,AF$21-$AB12*FLOOR(AF$21/$AB12,1),"") | AG12: =IF(G12>0,AG$21-$AB12*FLOOR(AG$21/$AB12,1),"") | AH12: =IF(AB12>0,SMALL(AC12:AG12,1),"") | AI12: =IF(AB12>0,HLOOKUP(AH12,AC12:AG22,10,FALSE),"") | AJ12: A | AK12: 10 | AL12: =C12*D12*E12*F12 -> 0 | AM12: =C12*D12*E12*H12*1.05 -> 0 | AN12: =AM12-(AL12*1.15) -> 0 | AO12: =D12*E12*C12 -> 0 | AQ12: =P12 -> 0 | AR12: =IF(C12>0,AR$21-$AQ12*FLOOR(AR$21/$AQ12,1),"") | AS12: =IF(D12>0,AS$21-$AQ12*FLOOR(AS$21/$AQ12,1),"") | AT12: =IF(E12>0,AT$21-$AQ12*FLOOR(AT$21/$AQ12,1),"") | AU12: =IF(F12>0,AU$21-$AQ12*FLOOR(AU$21/$AQ12,1),"") | AV12: =IF(G12>0,AV$21-$AQ12*FLOOR(AV$21/$AQ12,1),"") | AW12: =IF(AQ12>0,SMALL(AR12:AV12,1),"") | AX12: =IF(AQ12>0,HLOOKUP(AW12,AR12:AV22,10,FALSE),"")
B13: WF-3 | J13: =K13 -> 0 | O13: =K13 -> 0 | P13: =E13-0.002*G13+2*F13/2 -> 0 | V13: 16mm Ø | W13: 1.5804165 | X13: =IF(C13>0,Z13*J13*VLOOKUP(I13,$V$11:$W$17,2,FALSE),"") | Y13: =IF(C13>0,O13*AA13*VLOOKUP(I13,$V$11:$W$17,2,FALSE),"") | Z13: =IF(C13>0,CEILING(C13*D13*(L13)/(J13-0.5),1),"") | AA13: =IF(C13>0,CEILING(C13*(E13*D13*1000/M13/K13),1),"") | AB13: =K13 -> 0 | AC13: =IF(C13>0,AC$21-$AB13*FLOOR(AC$21/$AB13,1),"") | AD13: =IF(D13>0,AD$21-$AB13*FLOOR(AD$21/$AB13,1),"") | AE13: =IF(E13>0,AE$21-$AB13*FLOOR(AE$21/$AB13,1),"") | AF13: =IF(F13>0,AF$21-$AB13*FLOOR(AF$21/$AB13,1),"") | AG13: =IF(G13>0,AG$21-$AB13*FLOOR(AG$21/$AB13,1),"") | AH13: =IF(AB13>0,SMALL(AC13:AG13,1),"") | AI13: =IF(AB13>0,HLOOKUP(AH13,AC13:AG23,9,FALSE),"") | AJ13: B | AK13: 8 | AL13: =C13*D13*E13*F13 -> 0 | AM13: =C13*D13*E13*H13*1.05 -> 0 | AN13: =AM13-(AL13*1.15) -> 0 | AO13: =D13*E13*C13 -> 0 | AQ13: =P13 -> 0 | AR13: =IF(C13>0,AR$21-$AQ13*FLOOR(AR$21/$AQ13,1),"") | AS13: =IF(D13>0,AS$21-$AQ13*FLOOR(AS$21/$AQ13,1),"") | AT13: =IF(E13>0,AT$21-$AQ13*FLOOR(AT$21/$AQ13,1),"") | AU13: =IF(F13>0,AU$21-$AQ13*FLOOR(AU$21/$AQ13,1),"") | AV13: =IF(G13>0,AV$21-$AQ13*FLOOR(AV$21/$AQ13,1),"") | AW13: =IF(AQ13>0,SMALL(AR13:AV13,1),"") | AX13: =IF(AQ13>0,HLOOKUP(AW13,AR13:AV23,9,FALSE),"")
B14: WF-4 | J14: =K14 -> 0 | O14: =K14 -> 0 | P14: =E14-0.002*G14+2*F14/2 -> 0 | V14: 20mm Ø | W14: 2.4694007 | X14: =IF(C14>0,Z14*J14*VLOOKUP(I14,$V$11:$W$17,2,FALSE),"") | Y14: =IF(C14>0,O14*AA14*VLOOKUP(I14,$V$11:$W$17,2,FALSE),"") | Z14: =IF(C14>0,CEILING(C14*D14*(L14)/(J14-0.5),1),"") | AA14: =IF(C14>0,CEILING(C14*(E14*D14*1000/M14/K14),1),"") | AB14: =K14 -> 0 | AC14: =IF(C14>0,AC$21-$AB14*FLOOR(AC$21/$AB14,1),"") | AD14: =IF(D14>0,AD$21-$AB14*FLOOR(AD$21/$AB14,1),"") | AE14: =IF(E14>0,AE$21-$AB14*FLOOR(AE$21/$AB14,1),"") | AF14: =IF(F14>0,AF$21-$AB14*FLOOR(AF$21/$AB14,1),"") | AG14: =IF(G14>0,AG$21-$AB14*FLOOR(AG$21/$AB14,1),"") | AH14: =IF(AB14>0,SMALL(AC14:AG14,1),"") | AI14: =IF(AB14>0,HLOOKUP(AH14,AC14:AG24,8,FALSE),"") | AJ14: C | AK14: 6.5 | AL14: =C14*D14*E14*F14 -> 0 | AM14: =C14*D14*E14*H14*1.05 -> 0 | AN14: =AM14-(AL14*1.15) -> 0 | AO14: =D14*E14*C14 -> 0 | AQ14: =P14 -> 0 | AR14: =IF(C14>0,AR$21-$AQ14*FLOOR(AR$21/$AQ14,1),"") | AS14: =IF(D14>0,AS$21-$AQ14*FLOOR(AS$21/$AQ14,1),"") | AT14: =IF(E14>0,AT$21-$AQ14*FLOOR(AT$21/$AQ14,1),"") | AU14: =IF(F14>0,AU$21-$AQ14*FLOOR(AU$21/$AQ14,1),"") | AV14: =IF(G14>0,AV$21-$AQ14*FLOOR(AV$21/$AQ14,1),"") | AW14: =IF(AQ14>0,SMALL(AR14:AV14,1),"") | AX14: =IF(AQ14>0,HLOOKUP(AW14,AR14:AV24,8,FALSE),"") | AY14: =IF(AQ14>0,SMALL(AR14:AV14,1),"") | AZ14: =IF(AQ14>0,HLOOKUP(AY14,AR14:AV24,8,FALSE),"")
B15: WF-5 | J15: =K15 -> 0 | O15: =K15 -> 0 | P15: =E15-0.002*G15+2*F15/2 -> 0 | V15: 25mm Ø | W15: 3.8584386 | X15: =IF(C15>0,Z15*J15*VLOOKUP(I15,$V$11:$W$17,2,FALSE),"") | Y15: =IF(C15>0,O15*AA15*VLOOKUP(I15,$V$11:$W$17,2,FALSE),"") | Z15: =IF(C15>0,CEILING(C15*D15*(L15)/(J15-0.5),1),"") | AA15: =IF(C15>0,CEILING(C15*(E15*D15*1000/M15/K15),1),"") | AB15: =K15 -> 0 | AC15: =IF(C15>0,AC$21-$AB15*FLOOR(AC$21/$AB15,1),"") | AD15: =IF(D15>0,AD$21-$AB15*FLOOR(AD$21/$AB15,1),"") | AE15: =IF(E15>0,AE$21-$AB15*FLOOR(AE$21/$AB15,1),"") | AF15: =IF(F15>0,AF$21-$AB15*FLOOR(AF$21/$AB15,1),"") | AG15: =IF(G15>0,AG$21-$AB15*FLOOR(AG$21/$AB15,1),"") | AH15: =IF(AB15>0,SMALL(AC15:AG15,1),"") | AI15: =IF(AB15>0,HLOOKUP(AH15,AC15:AG29,7,FALSE),"") | AL15: =C15*D15*E15*F15 -> 0 | AM15: =C15*D15*E15*H15*1.05 -> 0 | AN15: =AM15-(AL15*1.15) -> 0 | AO15: =D15*E15*C15 -> 0 | AQ15: =P15 -> 0 | AR15: =IF(C15>0,AR$21-$AQ15*FLOOR(AR$21/$AQ15,1),"") | AS15: =IF(D15>0,AS$21-$AQ15*FLOOR(AS$21/$AQ15,1),"") | AT15: =IF(E15>0,AT$21-$AQ15*FLOOR(AT$21/$AQ15,1),"") | AU15: =IF(F15>0,AU$21-$AQ15*FLOOR(AU$21/$AQ15,1),"") | AV15: =IF(G15>0,AV$21-$AQ15*FLOOR(AV$21/$AQ15,1),"") | AW15: =IF(AQ15>0,SMALL(AR15:AV15,1),"") | AX15: =IF(AQ15>0,HLOOKUP(AW15,AR15:AV29,7,FALSE),"") | AY15: =IF(AQ15>0,SMALL(AR15:AV15,1),"") | AZ15: =IF(AQ15>0,HLOOKUP(AY15,AR15:AV29,7,FALSE),"")
B16: WF-6 | J16: =K16 -> 0 | O16: =K16 -> 0 | P16: =E16-0.002*G16+2*F16/2 -> 0 | V16: 28mm Ø | W16: 4.8400254 | X16: =IF(C16>0,Z16*J16*VLOOKUP(I16,$V$11:$W$17,2,FALSE),"") | Y16: =IF(C16>0,O16*AA16*VLOOKUP(I16,$V$11:$W$17,2,FALSE),"") | Z16: =IF(C16>0,CEILING(C16*D16*(L16)/(J16-0.5),1),"") | AA16: =IF(C16>0,CEILING(C16*(E16*D16*1000/M16/K16),1),"") | AB16: =K16 -> 0 | AC16: =IF(C16>0,AC$21-$AB16*FLOOR(AC$21/$AB16,1),"") | AD16: =IF(D16>0,AD$21-$AB16*FLOOR(AD$21/$AB16,1),"") | AE16: =IF(E16>0,AE$21-$AB16*FLOOR(AE$21/$AB16,1),"") | AF16: =IF(F16>0,AF$21-$AB16*FLOOR(AF$21/$AB16,1),"") | AG16: =IF(G16>0,AG$21-$AB16*FLOOR(AG$21/$AB16,1),"") | AH16: =IF(AB16>0,SMALL(AC16:AG16,1),"") | AI16: =IF(AB16>0,HLOOKUP(AH16,AC16:AG31,6,FALSE),"") | AL16: =C16*D16*E16*F16 -> 0 | AM16: =C16*D16*E16*H16*1.05 -> 0 | AN16: =AM16-(AL16*1.15) -> 0 | AO16: =D16*E16*C16 -> 0 | AQ16: =P16 -> 0 | AR16: =IF(C16>0,AR$21-$AQ16*FLOOR(AR$21/$AQ16,1),"") | AS16: =IF(D16>0,AS$21-$AQ16*FLOOR(AS$21/$AQ16,1),"") | AT16: =IF(E16>0,AT$21-$AQ16*FLOOR(AT$21/$AQ16,1),"") | AU16: =IF(F16>0,AU$21-$AQ16*FLOOR(AU$21/$AQ16,1),"") | AV16: =IF(G16>0,AV$21-$AQ16*FLOOR(AV$21/$AQ16,1),"") | AW16: =IF(AQ16>0,SMALL(AR16:AV16,1),"") | AX16: =IF(AQ16>0,HLOOKUP(AW16,AR16:AV31,6,FALSE),"") | AY16: =IF(AQ16>0,SMALL(AR16:AV16,1),"") | AZ16: =IF(AQ16>0,HLOOKUP(AY16,AR16:AV31,6,FALSE),"")
B17: WF-7 | J17: =K17 -> 0 | O17: =K17 -> 0 | P17: =E17-0.002*G17+2*F17/2 -> 0 | V17: 32mm Ø | W17: 6.3216658 | X17: =IF(C17>0,Z17*J17*VLOOKUP(I17,$V$11:$W$17,2,FALSE),"") | Y17: =IF(C17>0,O17*AA17*VLOOKUP(I17,$V$11:$W$17,2,FALSE),"") | Z17: =IF(C17>0,CEILING(C17*D17*(L17)/(J17-0.5),1),"") | AA17: =IF(C17>0,CEILING(C17*(E17*D17*1000/M17/K17),1),"") | AB17: =K17 -> 0 | AC17: =IF(C17>0,AC$21-$AB17*FLOOR(AC$21/$AB17,1),"") | AD17: =IF(D17>0,AD$21-$AB17*FLOOR(AD$21/$AB17,1),"") | AE17: =IF(E17>0,AE$21-$AB17*FLOOR(AE$21/$AB17,1),"") | AF17: =IF(F17>0,AF$21-$AB17*FLOOR(AF$21/$AB17,1),"") | AG17: =IF(G17>0,AG$21-$AB17*FLOOR(AG$21/$AB17,1),"") | AH17: =IF(AB17>0,SMALL(AC17:AG17,1),"") | AI17: =IF(AB17>0,HLOOKUP(AH17,AC17:AG33,5,FALSE),"") | AL17: =C17*D17*E17*F17 -> 0 | AM17: =C17*D17*E17*H17*1.05 -> 0 | AN17: =AM17-(AL17*1.15) -> 0 | AO17: =D17*E17*C17 -> 0 | AQ17: =P17 -> 0 | AR17: =IF(C17>0,AR$21-$AQ17*FLOOR(AR$21/$AQ17,1),"") | AS17: =IF(D17>0,AS$21-$AQ17*FLOOR(AS$21/$AQ17,1),"") | AT17: =IF(E17>0,AT$21-$AQ17*FLOOR(AT$21/$AQ17,1),"") | AU17: =IF(F17>0,AU$21-$AQ17*FLOOR(AU$21/$AQ17,1),"") | AV17: =IF(G17>0,AV$21-$AQ17*FLOOR(AV$21/$AQ17,1),"") | AW17: =IF(AQ17>0,SMALL(AR17:AV17,1),"") | AX17: =IF(AQ17>0,HLOOKUP(AW17,AR17:AV33,5,FALSE),"") | AY17: =IF(AQ17>0,SMALL(AR17:AV17,1),"") | AZ17: =IF(AQ17>0,HLOOKUP(AY17,AR17:AV33,5,FALSE),"")
B18: WF-8 | J18: =K18 -> 0 | O18: =K18 -> 0 | P18: =E18-0.002*G18+2*F18/2 -> 0 | X18: =IF(C18>0,Z18*J18*VLOOKUP(I18,$V$11:$W$17,2,FALSE),"") | Y18: =IF(C18>0,O18*AA18*VLOOKUP(I18,$V$11:$W$17,2,FALSE),"") | Z18: =IF(C18>0,CEILING(C18*D18*(L18)/(J18-0.5),1),"") | AA18: =IF(C18>0,CEILING(C18*(E18*D18*1000/M18/K18),1),"") | AB18: =K18 -> 0 | AC18: =IF(C18>0,AC$21-$AB18*FLOOR(AC$21/$AB18,1),"") | AD18: =IF(D18>0,AD$21-$AB18*FLOOR(AD$21/$AB18,1),"") | AE18: =IF(E18>0,AE$21-$AB18*FLOOR(AE$21/$AB18,1),"") | AF18: =IF(F18>0,AF$21-$AB18*FLOOR(AF$21/$AB18,1),"") | AG18: =IF(G18>0,AG$21-$AB18*FLOOR(AG$21/$AB18,1),"") | AH18: =IF(AB18>0,SMALL(AC18:AG18,1),"") | AI18: =IF(AB18>0,HLOOKUP(AH18,AC18:AG35,4,FALSE),"") | AL18: =C18*D18*E18*F18 -> 0 | AM18: =C18*D18*E18*H18*1.05 -> 0 | AN18: =AM18-(AL18*1.15) -> 0 | AO18: =D18*E18*C18 -> 0 | AQ18: =P18 -> 0 | AR18: =IF(C18>0,AR$21-$AQ18*FLOOR(AR$21/$AQ18,1),"") | AS18: =IF(D18>0,AS$21-$AQ18*FLOOR(AS$21/$AQ18,1),"") | AT18: =IF(E18>0,AT$21-$AQ18*FLOOR(AT$21/$AQ18,1),"") | AU18: =IF(F18>0,AU$21-$AQ18*FLOOR(AU$21/$AQ18,1),"") | AV18: =IF(G18>0,AV$21-$AQ18*FLOOR(AV$21/$AQ18,1),"") | AW18: =IF(AQ18>0,SMALL(AR18:AV18,1),"") | AX18: =IF(AQ18>0,HLOOKUP(AW18,AR18:AV35,4,FALSE),"") | AY18: =IF(AQ18>0,SMALL(AR18:AV18,1),"") | AZ18: =IF(AQ18>0,HLOOKUP(AY18,AR18:AV35,4,FALSE),"")
B19: WF-9 | J19: =K19 -> 0 | O19: =K19 -> 0 | P19: =E19-0.002*G19+2*F19/2 -> 0 | X19: =IF(C19>0,Z19*J19*VLOOKUP(I19,$V$11:$W$17,2,FALSE),"") | Y19: =IF(C19>0,O19*AA19*VLOOKUP(I19,$V$11:$W$17,2,FALSE),"") | Z19: =IF(C19>0,CEILING(C19*D19*(L19)/(J19-0.5),1),"") | AA19: =IF(C19>0,CEILING(C19*(E19*D19*1000/M19/K19),1),"") | AB19: =K19 -> 0 | AC19: =IF(C19>0,AC$21-$AB19*FLOOR(AC$21/$AB19,1),"") | AD19: =IF(D19>0,AD$21-$AB19*FLOOR(AD$21/$AB19,1),"") | AE19: =IF(E19>0,AE$21-$AB19*FLOOR(AE$21/$AB19,1),"") | AF19: =IF(F19>0,AF$21-$AB19*FLOOR(AF$21/$AB19,1),"") | AG19: =IF(G19>0,AG$21-$AB19*FLOOR(AG$21/$AB19,1),"") | AH19: =IF(AB19>0,SMALL(AC19:AG19,1),"") | AI19: =IF(AB19>0,HLOOKUP(AH19,AC19:AG37,3,FALSE),"") | AL19: =C19*D19*E19*F19 -> 0 | AM19: =C19*D19*E19*H19*1.05 -> 0 | AN19: =AM19-(AL19*1.15) -> 0 | AO19: =D19*E19*C19 -> 0 | AQ19: =P19 -> 0 | AR19: =IF(C19>0,AR$21-$AQ19*FLOOR(AR$21/$AQ19,1),"") | AS19: =IF(D19>0,AS$21-$AQ19*FLOOR(AS$21/$AQ19,1),"") | AT19: =IF(E19>0,AT$21-$AQ19*FLOOR(AT$21/$AQ19,1),"") | AU19: =IF(F19>0,AU$21-$AQ19*FLOOR(AU$21/$AQ19,1),"") | AV19: =IF(G19>0,AV$21-$AQ19*FLOOR(AV$21/$AQ19,1),"") | AW19: =IF(AQ19>0,SMALL(AR19:AV19,1),"") | AX19: =IF(AQ19>0,HLOOKUP(AW19,AR19:AV37,3,FALSE),"") | AY19: =IF(AQ19>0,SMALL(AR19:AV19,1),"") | AZ19: =IF(AQ19>0,HLOOKUP(AY19,AR19:AV37,3,FALSE),"")
B20: WF-10 | J20: =K20 -> 0 | O20: =K20 -> 0 | P20: =E20-0.002*G20+2*F20/2 -> 0 | X20: =IF(C20>0,Z20*J20*VLOOKUP(I20,$V$11:$W$17,2,FALSE),"") | Y20: =IF(C20>0,O20*AA20*VLOOKUP(I20,$V$11:$W$17,2,FALSE),"") | Z20: =IF(C20>0,CEILING(C20*D20*(L20)/(J20-0.5),1),"") | AA20: =IF(C20>0,CEILING(C20*(E20*D20*1000/M20/K20),1),"") | AB20: =K20 -> 0 | AC20: =IF(C20>0,AC$21-$AB20*FLOOR(AC$21/$AB20,1),"") | AD20: =IF(D20>0,AD$21-$AB20*FLOOR(AD$21/$AB20,1),"") | AE20: =IF(E20>0,AE$21-$AB20*FLOOR(AE$21/$AB20,1),"") | AF20: =IF(F20>0,AF$21-$AB20*FLOOR(AF$21/$AB20,1),"") | AG20: =IF(G20>0,AG$21-$AB20*FLOOR(AG$21/$AB20,1),"") | AH20: =IF(AB20>0,SMALL(AC20:AG20,1),"") | AI20: =IF(AB20>0,HLOOKUP(AH20,AC20:AG39,2,FALSE),"") | AL20: =C20*D20*E20*F20 -> 0 | AM20: =C20*D20*E20*H20*1.05 -> 0 | AN20: =AM20-(AL20*1.15) -> 0 | AO20: =D20*E20*C20 -> 0 | AQ20: =P20 -> 0 | AR20: =IF(C20>0,AR$21-$AQ20*FLOOR(AR$21/$AQ20,1),"") | AS20: =IF(D20>0,AS$21-$AQ20*FLOOR(AS$21/$AQ20,1),"") | AT20: =IF(E20>0,AT$21-$AQ20*FLOOR(AT$21/$AQ20,1),"") | AU20: =IF(F20>0,AU$21-$AQ20*FLOOR(AU$21/$AQ20,1),"") | AV20: =IF(G20>0,AV$21-$AQ20*FLOOR(AV$21/$AQ20,1),"") | AW20: =IF(AQ20>0,SMALL(AR20:AV20,1),"") | AX20: =IF(AQ20>0,HLOOKUP(AW20,AR20:AV39,2,FALSE),"") | AY20: =IF(AQ20>0,SMALL(AR20:AV20,1),"") | AZ20: =IF(AQ20>0,HLOOKUP(AY20,AR20:AV39,2,FALSE),"")
X21: =SUM(X11:X17) -> 117.34592 | Y21: =SUM(Y11:Y17) -> 53.339055 | AC21: 6 | AD21: =AC21+1.5 -> 7.5 | AE21: =AD21+1.5 -> 9 | AF21: =AE21+1.5 -> 10.5 | AG21: =AF21+1.5 -> 12 | AL21: =SUM(AL11:AL20) -> 5.625 | AM21: =SUM(AM11:AM20) -> 23.625 | AN21: =SUM(AN11:AN20) -> 17.71875 | AR21: 6 | AS21: =AR21+1.5 -> 7.5 | AT21: =AS21+1.5 -> 9 | AU21: =AT21+1.5 -> 10.5 | AV21: =AU21+1.5 -> 12
F22: MATERIALS | X22: =X21+Y21 -> 170.68498 | AL22: =VLOOKUP(G8,AJ11:AK14,2,FALSE) -> 8
X23: Tie Wire | Y23: =CEILING(0.013*X22,0.5) -> 2.5 | AK23: Cement | AL23: =CEILING(AL22*AL21,1) -> 45
F24: FOOTING | G24: ITEM | H24: QUANTITY | I24: UNIT | J24: PRICE | K24: TOTAL COST | AK24: Sand | AL24: =AL21/2 -> 2.8125
G25: ='Materials Price List'!A8 -> Cement | H25: =AL23 -> 45 | I25: bags | J25: =IF(H25="","",VLOOKUP(G25,'Materials Price List'!$A$8:$B$46,2,FALSE)) -> 220 | K25: =IF(H25="","",H25*J25) -> 9900 | AK25: Gravel | AL25: =AL21 -> 5.625
G26: ='Materials Price List'!A9 -> Sand | H26: =AL24 -> 2.8125 | I26: cu.m | J26: =IF(H26="","",VLOOKUP(G26,'Materials Price List'!$A$8:$B$46,2,FALSE)) -> 875 | K26: =IF(H26="","",H26*J26) -> 2460.9375
G27: ='Materials Price List'!A10 -> Gravel | H27: =AL25 -> 5.625 | I27: cu.m | J27: =IF(H27="","",VLOOKUP(G27,'Materials Price List'!$A$8:$B$46,2,FALSE)) -> 1875 | K27: =IF(H27="","",H27*J27) -> 10546.875
G28: Tie Wire | H28: =Y23 -> 2.5 | I28: kg | J28: =IF(H28="","",VLOOKUP(G28,'Materials Price List'!$A$8:$B$46,2,FALSE)) -> 95 | K28: =IF(H28="","",H28*J28) -> 237.5
F29: =IF(C11>0,B11,"") -> WF-1 | G29: =IF(C11>0,CONCATENATE(I11," X ",J11,"m"),"") -> 12mm Ø X 6m | H29: =Z11 -> 22 | I29: =IF(H29="","","pcs") -> pcs | J29: =IF(H29="","",VLOOKUP(G29,'Materials Price List'!$A$8:$B$46,2)) -> 235.88028 | K29: =IF(H29="","",H29*J29) -> 5189.3662
F30: =F29 -> WF-1 | G30: =IF(C11>0,CONCATENATE(N11," X ",O11,"m"),"") -> 10mm Ø X 6m | H30: =AA11 -> 10 | I30: =IF(H30="","","pcs") -> pcs | J30: =IF(H30="","",VLOOKUP(G30,'Materials Price List'!$A$8:$B$46,2)) -> 165 | K30: =IF(H30="","",H30*J30) -> 1650
F31: =IF(C12>0,B12,"") | G31: =IF(C12>0,CONCATENATE(I12," X ",J12,"m"),"") | H31: =Z12 | I31: =IF(H31="","","pcs") | J31: =IF(H31="","",VLOOKUP(G31,'Materials Price List'!$A$8:$B$46,2)) | K31: =IF(H31="","",H31*J31)
F32: =F31 | G32: =IF(C12>0,CONCATENATE(N12," X ",O12,"m"),"") | H32: =AA12 | I32: =IF(H32="","","pcs") | J32: =IF(H32="","",VLOOKUP(G32,'Materials Price List'!$A$8:$B$46,2)) | K32: =IF(H32="","",H32*J32)
F33: =IF(C13>0,B13,"") | G33: =IF(C13>0,CONCATENATE(I13," X ",J13,"m"),"") | H33: =Z13 | I33: =IF(H33="","","pcs") | J33: =IF(H33="","",VLOOKUP(G33,'Materials Price List'!$A$8:$B$46,2)) | K33: =IF(H33="","",H33*J33)
F34: =F33 | G34: =IF(C13>0,CONCATENATE(N13," X ",O13,"m"),"") | H34: =AA13 | I34: =IF(H34="","","pcs") | J34: =IF(H34="","",VLOOKUP(G34,'Materials Price List'!$A$8:$B$46,2)) | K34: =IF(H34="","",H34*J34)
F35: =IF(C14>0,B14,"") | G35: =IF(C14>0,CONCATENATE(I14," X ",J14,"m"),"") | H35: =Z14 | I35: =IF(H35="","","pcs") | J35: =IF(H35="","",VLOOKUP(G35,'Materials Price List'!$A$8:$B$46,2)) | K35: =IF(H35="","",H35*J35)
F36: =F35 | G36: =IF(C14>0,CONCATENATE(N14," X ",O14,"m"),"") | H36: =AA14 | I36: =IF(H36="","","pcs") | J36: =IF(H36="","",VLOOKUP(G36,'Materials Price List'!$A$8:$B$46,2)) | K36: =IF(H36="","",H36*J36)
F37: =IF(C15>0,B15,"") | G37: =IF(C15>0,CONCATENATE(I15," X ",J15,"m"),"") | H37: =Z15 | I37: =IF(H37="","","pcs") | J37: =IF(H37="","",VLOOKUP(G37,'Materials Price List'!$A$8:$B$46,2)) | K37: =IF(H37="","",H37*J37)
F38: =F37 | G38: =IF(C15>0,CONCATENATE(N15," X ",O15,"m"),"") | H38: =AA15 | I38: =IF(H38="","","pcs") | J38: =IF(H38="","",VLOOKUP(G38,'Materials Price List'!$A$8:$B$46,2)) | K38: =IF(H38="","",H38*J38)
F39: =IF(C16>0,B16,"") | G39: =IF(C16>0,CONCATENATE(I16," X ",J16,"m"),"") | H39: =Z16 | I39: =IF(H39="","","pcs") | J39: =IF(H39="","",VLOOKUP(G39,'Materials Price List'!$A$8:$B$46,2)) | K39: =IF(H39="","",H39*J39)
F40: =F39 | G40: =IF(C16>0,CONCATENATE(N16," X ",O16,"m"),"") | H40: =AA16 | I40: =IF(H40="","","pcs") | J40: =IF(H40="","",VLOOKUP(G40,'Materials Price List'!$A$8:$B$46,2)) | K40: =IF(H40="","",H40*J40)
F41: =IF(C17>0,B17,"") | G41: =IF(C17>0,CONCATENATE(I17," X ",J17,"m"),"") | H41: =Z17 | I41: =IF(H41="","","pcs") | J41: =IF(H41="","",VLOOKUP(G41,'Materials Price List'!$A$8:$B$46,2)) | K41: =IF(H41="","",H41*J41)
F42: =F41 | G42: =IF(C17>0,CONCATENATE(N17," X ",O17,"m"),"") | H42: =AA17 | I42: =IF(H42="","","pcs") | J42: =IF(H42="","",VLOOKUP(G42,'Materials Price List'!$A$8:$B$46,2)) | K42: =IF(H42="","",H42*J42)
F43: =IF(C18>0,B18,"") | G43: =IF(C18>0,CONCATENATE(I18," X ",J18,"m"),"") | H43: =Z18 | I43: =IF(H43="","","pcs") | J43: =IF(H43="","",VLOOKUP(G43,'Materials Price List'!$A$8:$B$46,2)) | K43: =IF(H43="","",H43*J43)
F44: =F43 | G44: =IF(C18>0,CONCATENATE(N18," X ",O18,"m"),"") | H44: =AA18 | I44: =IF(H44="","","pcs") | J44: =IF(H44="","",VLOOKUP(G44,'Materials Price List'!$A$8:$B$46,2)) | K44: =IF(H44="","",H44*J44)
...

Sheet Column
B1: COLUMN ESTIMATE
B6: COLUMN DETAILS
B7: COLUMN | C7: Quantity | D7: Concrete | G7: Concrete Mix Class | I7: Reinforcement (Rebar Length = Automatic)
G8: AA
D9: B1 (m) | E9: B2 (m) | F9: Height (m) | G9: Concrete Cover (mm) | H9: Footing Depth if Ground Column | I9: MAIN REINFORCEMENT | N9: LATERAL TIES | AL9: Concrete Volume | AM9: Excavation | AN9: Backfill | AO9: AREA | BE9: FORMWORKS
I10: Bar Size | J10: Economical Bar Length (m) | K10: Steel Bars Length | L10: Top Bar (pcs) | M10: Bottom Bar (pcs) | N10: Bar Size | O10: Economical Bar Length (m) | P10: Cutting Length | Q10: MAIN TIES SPACING (mm) | R10: Bottom Bar (pcs) | X10: Tie Wire | Y10: Tie Wire | AY10: Bar size | AZ10: Bar Length | BA10: Along Length | BB10: Quantity | BC10: Along Width | BD10: Quantity | BE10: AREA | BF10: PLYWOOD | BG10: 2X2X8 | BH10: 2X3X8 | BI10: CWN 2" | BJ10: CWN 3"
B11: C-1 | C11: 4 | D11: 0.4 | E11: 0.4 | F11: 4 | G11: 40 | H11: 1.5 | I11: 16mm Ø | J11: =AI11 -> 6 | K11: =F11+H11-G11/1000+IF(C11>0,0.5,0) -> 5.96 | L11: 3 | M11: 3 | N11: 10mm Ø | O11: =AX11 -> 12 | P11: =IF(C11>0,0.05*2+2*(D11+E11)-4*(G11/1000),0) -> 1.54 | Q11: 200 | R11: 0 | T11: =4*0.05+10*0.1 -> 1.2 | U11: =F11-T11 -> 2.8 | V11: 10mm Ø | W11: 0.61735018 | X11: =IF(C11>0,Z11*J11*VLOOKUP(I11,$V$11:$W$17,2,FALSE),"") -> 227.57997 | Y11: =IF(C11>0,O11*AA11*VLOOKUP(I11,$V$11:$W$17,2,FALSE),"") -> 284.47496 | Z11: =IF(C11>0,CEILING(C11*K11*(L11+M11)/J11,1),"") -> 24 | AA11: =IF(C11>0,CEILING(C11*P11*(14+U11*1000/Q11+R11+1)/O11,1),"") -> 15 | AB11: =K11 -> 5.96 | AC11: =IF(C11>0,AC$21-$AB11*FLOOR(AC$21/$AB11,1),"") -> 0.04 | AD11: =IF(D11>0,AD$21-$AB11*FLOOR(AD$21/$AB11,1),"") -> 1.54 | AE11: =IF(E11>0,AE$21-$AB11*FLOOR(AE$21/$AB11,1),"") -> 3.04 | AF11: =IF(F11>0,AF$21-$AB11*FLOOR(AF$21/$AB11,1),"") -> 4.54 | AG11: =IF(G11>0,AG$21-$AB11*FLOOR(AG$21/$AB11,1),"") -> 0.08 | AH11: =IF(AB11>0,SMALL(AC11:AG11,1),"") -> 0.04 | AI11: =IF(AB11>0,HLOOKUP(AH11,AC11:AG21,11,FALSE),"") -> 6 | AJ11: AA | AK11: 12 | AL11: =C11*D11*E11*F11 -> 2.56 | AM11: =C11*D11*E11*H11*1.3 -> 1.248 | AN11: =AM11-(AL11*1.15) -> -1.696 | AO11: =D11*E11*C11 -> 0.64 | AQ11: =P11 -> 1.54 | AR11: =IF(C11>0,AR$21-$AQ11*FLOOR(AR$21/$AQ11,1),"") -> 1.38 | AS11: =IF(D11>0,AS$21-$AQ11*FLOOR(AS$21/$AQ11,1),"") -> 1.34 | AT11: =IF(E11>0,AT$21-$AQ11*FLOOR(AT$21/$AQ11,1),"") -> 1.3 | AU11: =IF(F11>0,AU$21-$AQ11*FLOOR(AU$21/$AQ11,1),"") -> 1.26 | AV11: =IF(G11>0,AV$21-$AQ11*FLOOR(AV$21/$AQ11,1),"") -> 1.22 | AW11: =IF(AQ11>0,SMALL(AR11:AV11,1),"") -> 1.22 | AX11: =IF(AQ11>0,HLOOKUP(AW11,AR11:AV21,11,FALSE),"") -> 12 | BE11: =C11*2*(D11+E11)*F11 -> 25.6 | BF11: =BE11/(1.2*2.4) -> 8.8888889 | BG11: =BF11*20.33/(2*2*8/12)/1.5 -> 45.177778 | BH11: =BF11*30.5/(2*3*8/12)/1.5 -> 45.185185 | BI11: =0.02*4*8*BF11 -> 5.6888889 | BJ11: =0.02*4*8*BF11 -> 5.6888889
B12: C-2 | J12: =AI12 | K12: =F12+H12-G12/1000+IF(C12>0,0.5,0) -> 0 | O12: =AX12 | P12: =IF(C12>0,0.05*2+2*(D12+E12)-4*(G12/1000),0) -> 0 | R12: 0 | T12: =4*0.05+10*0.1 -> 1.2 | U12: =F12-T12 -> -1.2 | V12: 12mm Ø | W12: 0.88898426 | X12: =IF(C12>0,Z12*J12*VLOOKUP(I12,$V$11:$W$17,2,FALSE),"") | Y12: =IF(C12>0,O12*AA12*VLOOKUP(I12,$V$11:$W$17,2,FALSE),"") | Z12: =IF(C12>0,CEILING(C12*K12*(L12+M12)/J12,1),"") | AA12: =IF(C12>0,CEILING(C12*P12*(14+U12*1000/Q12+R12+1)/O12,1),"") | AB12: =K12 -> 0 | AC12: =IF(C12>0,AC$21-$AB12*FLOOR(AC$21/$AB12,1),"") | AD12: =IF(D12>0,AD$21-$AB12*FLOOR(AD$21/$AB12,1),"") | AE12: =IF(E12>0,AE$21-$AB12*FLOOR(AE$21/$AB12,1),"") | AF12: =IF(F12>0,AF$21-$AB12*FLOOR(AF$21/$AB12,1),"") | AG12: =IF(G12>0,AG$21-$AB12*FLOOR(AG$21/$AB12,1),"") | AH12: =IF(AB12>0,SMALL(AC12:AG12,1),"") | AI12: =IF(AB12>0,HLOOKUP(AH12,AC12:AG22,10,FALSE),"") | AJ12: A | AK12: 10 | AL12: =C12*D12*E12*F12 -> 0 | AM12: =C12*D12*E12*H12*1.3 -> 0 | AN12: =AM12-(AL12*1.15) -> 0 | AO12: =D12*E12*C12 -> 0 | AQ12: =P12 -> 0 | AR12: =IF(C12>0,AR$21-$AQ12*FLOOR(AR$21/$AQ12,1),"") | AS12: =IF(D12>0,AS$21-$AQ12*FLOOR(AS$21/$AQ12,1),"") | AT12: =IF(E12>0,AT$21-$AQ12*FLOOR(AT$21/$AQ12,1),"") | AU12: =IF(F12>0,AU$21-$AQ12*FLOOR(AU$21/$AQ12,1),"") | AV12: =IF(G12>0,AV$21-$AQ12*FLOOR(AV$21/$AQ12,1),"") | AW12: =IF(AQ12>0,SMALL(AR12:AV12,1),"") | AX12: =IF(AQ12>0,HLOOKUP(AW12,AR12:AV22,10,FALSE),"") | BE12: =C12*2*(D12+E12)*F12 -> 0 | BF12: =BE12/(1.2*2.4) -> 0 | BG12: =BF12*20.33/(2*2*8/12)/1.5 -> 0 | BH12: =BF12*30.5/(2*3*8/12)/1.5 -> 0 | BI12: =0.02*4*8*BF12 -> 0 | BJ12: =0.02*4*8*BF12 -> 0
B13: C-3 | J13: =AI13 | K13: =F13+H13-G13/1000+IF(C13>0,0.5,0) -> 0 | O13: =AX13 | P13: =IF(C13>0,0.05*2+2*(D13+E13)-4*(G13/1000),0) -> 0 | R13: 0 | T13: =4*0.05+10*0.1 -> 1.2 | U13: =F13-T13 -> -1.2 | V13: 16mm Ø | W13: 1.5804165 | X13: =IF(C13>0,Z13*J13*VLOOKUP(I13,$V$11:$W$17,2,FALSE),"") | Y13: =IF(C13>0,O13*AA13*VLOOKUP(I13,$V$11:$W$17,2,FALSE),"") | Z13: =IF(C13>0,CEILING(C13*K13*(L13+M13)/J13,1),"") | AA13: =IF(C13>0,CEILING(C13*P13*(14+U13*1000/Q13+R13+1)/O13,1),"") | AB13: =K13 -> 0 | AC13: =IF(C13>0,AC$21-$AB13*FLOOR(AC$21/$AB13,1),"") | AD13: =IF(D13>0,AD$21-$AB13*FLOOR(AD$21/$AB13,1),"") | AE13: =IF(E13>0,AE$21-$AB13*FLOOR(AE$21/$AB13,1),"") | AF13: =IF(F13>0,AF$21-$AB13*FLOOR(AF$21/$AB13,1),"") | AG13: =IF(G13>0,AG$21-$AB13*FLOOR(AG$21/$AB13,1),"") | AH13: =IF(AB13>0,SMALL(AC13:AG13,1),"") | AI13: =IF(AB13>0,HLOOKUP(AH13,AC13:AG23,9,FALSE),"") | AJ13: B | AK13: 8 | AL13: =C13*D13*E13*F13 -> 0 | AM13: =C13*D13*E13*H13*1.3 -> 0 | AN13: =AM13-(AL13*1.15) -> 0 | AO13: =D13*E13*C13 -> 0 | AQ13: =P13 -> 0 | AR13: =IF(C13>0,AR$21-$AQ13*FLOOR(AR$21/$AQ13,1),"") | AS13: =IF(D13>0,AS$21-$AQ13*FLOOR(AS$21/$AQ13,1),"") | AT13: =IF(E13>0,AT$21-$AQ13*FLOOR(AT$21/$AQ13,1),"") | AU13: =IF(F13>0,AU$21-$AQ13*FLOOR(AU$21/$AQ13,1),"") | AV13: =IF(G13>0,AV$21-$AQ13*FLOOR(AV$21/$AQ13,1),"") | AW13: =IF(AQ13>0,SMALL(AR13:AV13,1),"") | AX13: =IF(AQ13>0,HLOOKUP(AW13,AR13:AV23,9,FALSE),"") | BE13: =C13*2*(D13+E13)*F13 -> 0 | BF13: =BE13/(1.2*2.4) -> 0 | BG13: =BF13*20.33/(2*2*8/12)/1.5 -> 0 | BH13: =BF13*30.5/(2*3*8/12)/1.5 -> 0 | BI13: =0.02*4*8*BF13 -> 0 | BJ13: =0.02*4*8*BF13 -> 0
B14: C-4 | J14: =AI14 | K14: =F14+H14-G14/1000+IF(C14>0,0.5,0) -> 0 | O14: =AX14 | P14: =IF(C14>0,0.05*2+2*(D14+E14)-4*(G14/1000),0) -> 0 | R14: 0 | T14: =4*0.05+10*0.1 -> 1.2 | U14: =F14-T14 -> -1.2 | V14: 20mm Ø | W14: 2.4694007 | X14: =IF(C14>0,Z14*J14*VLOOKUP(I14,$V$11:$W$17,2,FALSE),"") | Y14: =IF(C14>0,O14*AA14*VLOOKUP(I14,$V$11:$W$17,2,FALSE),"") | Z14: =IF(C14>0,CEILING(C14*K14*(L14+M14)/J14,1),"") | AA14: =IF(C14>0,CEILING(C14*P14*(14+U14*1000/Q14+R14+1)/O14,1),"") | AB14: =K14 -> 0 | AC14: =IF(C14>0,AC$21-$AB14*FLOOR(AC$21/$AB14,1),"") | AD14: =IF(D14>0,AD$21-$AB14*FLOOR(AD$21/$AB14,1),"") | AE14: =IF(E14>0,AE$21-$AB14*FLOOR(AE$21/$AB14,1),"") | AF14: =IF(F14>0,AF$21-$AB14*FLOOR(AF$21/$AB14,1),"") | AG14: =IF(G14>0,AG$21-$AB14*FLOOR(AG$21/$AB14,1),"") | AH14: =IF(AB14>0,SMALL(AC14:AG14,1),"") | AI14: =IF(AB14>0,HLOOKUP(AH14,AC14:AG24,8,FALSE),"") | AJ14: C | AK14: 6.5 | AL14: =C14*D14*E14*F14 -> 0 | AM14: =C14*D14*E14*H14*1.3 -> 0 | AN14: =AM14-(AL14*1.15) -> 0 | AO14: =D14*E14*C14 -> 0 | AQ14: =P14 -> 0 | AR14: =IF(C14>0,AR$21-$AQ14*FLOOR(AR$21/$AQ14,1),"") | AS14: =IF(D14>0,AS$21-$AQ14*FLOOR(AS$21/$AQ14,1),"") | AT14: =IF(E14>0,AT$21-$AQ14*FLOOR(AT$21/$AQ14,1),"") | AU14: =IF(F14>0,AU$21-$AQ14*FLOOR(AU$21/$AQ14,1),"") | AV14: =IF(G14>0,AV$21-$AQ14*FLOOR(AV$21/$AQ14,1),"") | AW14: =IF(AQ14>0,SMALL(AR14:AV14,1),"") | AX14: =IF(AQ14>0,HLOOKUP(AW14,AR14:AV24,8,FALSE),"") | AY14: =IF(AQ14>0,SMALL(AR14:AV14,1),"") | AZ14: =IF(AQ14>0,HLOOKUP(AY14,AR14:AV24,8,FALSE),"") | BE14: =C14*2*(D14+E14)*F14 -> 0 | BF14: =BE14/(1.2*2.4) -> 0 | BG14: =BF14*20.33/(2*2*8/12)/1.5 -> 0 | BH14: =BF14*30.5/(2*3*8/12)/1.5 -> 0 | BI14: =0.02*4*8*BF14 -> 0 | BJ14: =0.02*4*8*BF14 -> 0
B15: C-5 | J15: =AI15 | K15: =F15+H15-G15/1000+IF(C15>0,0.5,0) -> 0 | O15: =AX15 | P15: =IF(C15>0,0.05*2+2*(D15+E15)-4*(G15/1000),0) -> 0 | R15: 0 | T15: =4*0.05+10*0.1 -> 1.2 | U15: =F15-T15 -> -1.2 | V15: 25mm Ø | W15: 3.8584386 | X15: =IF(C15>0,Z15*J15*VLOOKUP(I15,$V$11:$W$17,2,FALSE),"") | Y15: =IF(C15>0,O15*AA15*VLOOKUP(I15,$V$11:$W$17,2,FALSE),"") | Z15: =IF(C15>0,CEILING(C15*K15*(L15+M15)/J15,1),"") | AA15: =IF(C15>0,CEILING(C15*P15*(14+U15*1000/Q15+R15+1)/O15,1),"") | AB15: =K15 -> 0 | AC15: =IF(C15>0,AC$21-$AB15*FLOOR(AC$21/$AB15,1),"") | AD15: =IF(D15>0,AD$21-$AB15*FLOOR(AD$21/$AB15,1),"") | AE15: =IF(E15>0,AE$21-$AB15*FLOOR(AE$21/$AB15,1),"") | AF15: =IF(F15>0,AF$21-$AB15*FLOOR(AF$21/$AB15,1),"") | AG15: =IF(G15>0,AG$21-$AB15*FLOOR(AG$21/$AB15,1),"") | AH15: =IF(AB15>0,SMALL(AC15:AG15,1),"") | AI15: =IF(AB15>0,HLOOKUP(AH15,AC15:AG34,7,FALSE),"") | AL15: =C15*D15*E15*F15 -> 0 | AM15: =C15*D15*E15*H15*1.3 -> 0 | AN15: =AM15-(AL15*1.15) -> 0 | AO15: =D15*E15*C15 -> 0 | AQ15: =P15 -> 0 | AR15: =IF(C15>0,AR$21-$AQ15*FLOOR(AR$21/$AQ15,1),"") | AS15: =IF(D15>0,AS$21-$AQ15*FLOOR(AS$21/$AQ15,1),"") | AT15: =IF(E15>0,AT$21-$AQ15*FLOOR(AT$21/$AQ15,1),"") | AU15: =IF(F15>0,AU$21-$AQ15*FLOOR(AU$21/$AQ15,1),"") | AV15: =IF(G15>0,AV$21-$AQ15*FLOOR(AV$21/$AQ15,1),"") | AW15: =IF(AQ15>0,SMALL(AR15:AV15,1),"") | AX15: =IF(AQ15>0,HLOOKUP(AW15,AR15:AV34,7,FALSE),"") | AY15: =IF(AQ15>0,SMALL(AR15:AV15,1),"") | AZ15: =IF(AQ15>0,HLOOKUP(AY15,AR15:AV34,7,FALSE),"") | BE15: =C15*2*(D15+E15)*F15 -> 0 | BF15: =BE15/(1.2*2.4) -> 0 | BG15: =BF15*20.33/(2*2*8/12)/1.5 -> 0 | BH15: =BF15*30.5/(2*3*8/12)/1.5 -> 0 | BI15: =0.02*4*8*BF15 -> 0 | BJ15: =0.02*4*8*BF15 -> 0
B16: C-6 | J16: =AI16 | K16: =F16+H16-G16/1000+IF(C16>0,0.5,0) -> 0 | O16: =AX16 | P16: =IF(C16>0,0.05*2+2*(D16+E16)-4*(G16/1000),0) -> 0 | R16: 0 | T16: =4*0.05+10*0.1 -> 1.2 | U16: =F16-T16 -> -1.2 | V16: 28mm Ø | W16: 4.8400254 | X16: =IF(C16>0,Z16*J16*VLOOKUP(I16,$V$11:$W$17,2,FALSE),"") | Y16: =IF(C16>0,O16*AA16*VLOOKUP(I16,$V$11:$W$17,2,FALSE),"") | Z16: =IF(C16>0,CEILING(C16*K16*(L16+M16)/J16,1),"") | AA16: =IF(C16>0,CEILING(C16*P16*(14+U16*1000/Q16+R16+1)/O16,1),"") | AB16: =K16 -> 0 | AC16: =IF(C16>0,AC$21-$AB16*FLOOR(AC$21/$AB16,1),"") | AD16: =IF(D16>0,AD$21-$AB16*FLOOR(AD$21/$AB16,1),"") | AE16: =IF(E16>0,AE$21-$AB16*FLOOR(AE$21/$AB16,1),"") | AF16: =IF(F16>0,AF$21-$AB16*FLOOR(AF$21/$AB16,1),"") | AG16: =IF(G16>0,AG$21-$AB16*FLOOR(AG$21/$AB16,1),"") | AH16: =IF(AB16>0,SMALL(AC16:AG16,1),"") | AI16: =IF(AB16>0,HLOOKUP(AH16,AC16:AG36,6,FALSE),"") | AL16: =C16*D16*E16*F16 -> 0 | AM16: =C16*D16*E16*H16*1.3 -> 0 | AN16: =AM16-(AL16*1.15) -> 0 | AO16: =D16*E16*C16 -> 0 | AQ16: =P16 -> 0 | AR16: =IF(C16>0,AR$21-$AQ16*FLOOR(AR$21/$AQ16,1),"") | AS16: =IF(D16>0,AS$21-$AQ16*FLOOR(AS$21/$AQ16,1),"") | AT16: =IF(E16>0,AT$21-$AQ16*FLOOR(AT$21/$AQ16,1),"") | AU16: =IF(F16>0,AU$21-$AQ16*FLOOR(AU$21/$AQ16,1),"") | AV16: =IF(G16>0,AV$21-$AQ16*FLOOR(AV$21/$AQ16,1),"") | AW16: =IF(AQ16>0,SMALL(AR16:AV16,1),"") | AX16: =IF(AQ16>0,HLOOKUP(AW16,AR16:AV36,6,FALSE),"") | AY16: =IF(AQ16>0,SMALL(AR16:AV16,1),"") | AZ16: =IF(AQ16>0,HLOOKUP(AY16,AR16:AV36,6,FALSE),"") | BE16: =C16*2*(D16+E16)*F16 -> 0 | BF16: =BE16/(1.2*2.4) -> 0 | BG16: =BF16*20.33/(2*2*8/12)/1.5 -> 0 | BH16: =BF16*30.5/(2*3*8/12)/1.5 -> 0 | BI16: =0.02*4*8*BF16 -> 0 | BJ16: =0.02*4*8*BF16 -> 0
B17: C-7 | J17: =AI17 | K17: =F17+H17-G17/1000+IF(C17>0,0.5,0) -> 0 | O17: =AX17 | P17: =IF(C17>0,0.05*2+2*(D17+E17)-4*(G17/1000),0) -> 0 | R17: 0 | T17: =4*0.05+10*0.1 -> 1.2 | U17: =F17-T17 -> -1.2 | V17: 32mm Ø | W17: 6.3216658 | X17: =IF(C17>0,Z17*J17*VLOOKUP(I17,$V$11:$W$17,2,FALSE),"") | Y17: =IF(C17>0,O17*AA17*VLOOKUP(I17,$V$11:$W$17,2,FALSE),"") | Z17: =IF(C17>0,CEILING(C17*K17*(L17+M17)/J17,1),"") | AA17: =IF(C17>0,CEILING(C17*P17*(14+U17*1000/Q17+R17+1)/O17,1),"") | AB17: =K17 -> 0 | AC17: =IF(C17>0,AC$21-$AB17*FLOOR(AC$21/$AB17,1),"") | AD17: =IF(D17>0,AD$21-$AB17*FLOOR(AD$21/$AB17,1),"") | AE17: =IF(E17>0,AE$21-$AB17*FLOOR(AE$21/$AB17,1),"") | AF17: =IF(F17>0,AF$21-$AB17*FLOOR(AF$21/$AB17,1),"") | AG17: =IF(G17>0,AG$21-$AB17*FLOOR(AG$21/$AB17,1),"") | AH17: =IF(AB17>0,SMALL(AC17:AG17,1),"") | AI17: =IF(AB17>0,HLOOKUP(AH17,AC17:AG38,5,FALSE),"") | AL17: =C17*D17*E17*F17 -> 0 | AM17: =C17*D17*E17*H17*1.3 -> 0 | AN17: =AM17-(AL17*1.15) -> 0 | AO17: =D17*E17*C17 -> 0 | AQ17: =P17 -> 0 | AR17: =IF(C17>0,AR$21-$AQ17*FLOOR(AR$21/$AQ17,1),"") | AS17: =IF(D17>0,AS$21-$AQ17*FLOOR(AS$21/$AQ17,1),"") | AT17: =IF(E17>0,AT$21-$AQ17*FLOOR(AT$21/$AQ17,1),"") | AU17: =IF(F17>0,AU$21-$AQ17*FLOOR(AU$21/$AQ17,1),"") | AV17: =IF(G17>0,AV$21-$AQ17*FLOOR(AV$21/$AQ17,1),"") | AW17: =IF(AQ17>0,SMALL(AR17:AV17,1),"") | AX17: =IF(AQ17>0,HLOOKUP(AW17,AR17:AV38,5,FALSE),"") | AY17: =IF(AQ17>0,SMALL(AR17:AV17,1),"") | AZ17: =IF(AQ17>0,HLOOKUP(AY17,AR17:AV38,5,FALSE),"") | BE17: =C17*2*(D17+E17)*F17 -> 0 | BF17: =BE17/(1.2*2.4) -> 0 | BG17: =BF17*20.33/(2*2*8/12)/1.5 -> 0 | BH17: =BF17*30.5/(2*3*8/12)/1.5 -> 0 | BI17: =0.02*4*8*BF17 -> 0 | BJ17: =0.02*4*8*BF17 -> 0
B18: C-8 | J18: =AI18 | K18: =F18+H18-G18/1000+IF(C18>0,0.5,0) -> 0 | O18: =AX18 | P18: =IF(C18>0,0.05*2+2*(D18+E18)-4*(G18/1000),0) -> 0 | R18: 0 | T18: =4*0.05+10*0.1 -> 1.2 | U18: =F18-T18 -> -1.2 | X18: =IF(C18>0,Z18*J18*VLOOKUP(I18,$V$11:$W$17,2,FALSE),"") | Y18: =IF(C18>0,O18*AA18*VLOOKUP(I18,$V$11:$W$17,2,FALSE),"") | Z18: =IF(C18>0,CEILING(C18*K18*(L18+M18)/J18,1),"") | AA18: =IF(C18>0,CEILING(C18*P18*(14+U18*1000/Q18+R18+1)/O18,1),"") | AB18: =K18 -> 0 | AC18: =IF(C18>0,AC$21-$AB18*FLOOR(AC$21/$AB18,1),"") | AD18: =IF(D18>0,AD$21-$AB18*FLOOR(AD$21/$AB18,1),"") | AE18: =IF(E18>0,AE$21-$AB18*FLOOR(AE$21/$AB18,1),"") | AF18: =IF(F18>0,AF$21-$AB18*FLOOR(AF$21/$AB18,1),"") | AG18: =IF(G18>0,AG$21-$AB18*FLOOR(AG$21/$AB18,1),"") | AH18: =IF(AB18>0,SMALL(AC18:AG18,1),"") | AI18: =IF(AB18>0,HLOOKUP(AH18,AC18:AG40,4,FALSE),"") | AL18: =C18*D18*E18*F18 -> 0 | AM18: =C18*D18*E18*H18*1.3 -> 0 | AN18: =AM18-(AL18*1.15) -> 0 | AO18: =D18*E18*C18 -> 0 | AQ18: =P18 -> 0 | AR18: =IF(C18>0,AR$21-$AQ18*FLOOR(AR$21/$AQ18,1),"") | AS18: =IF(D18>0,AS$21-$AQ18*FLOOR(AS$21/$AQ18,1),"") | AT18: =IF(E18>0,AT$21-$AQ18*FLOOR(AT$21/$AQ18,1),"") | AU18: =IF(F18>0,AU$21-$AQ18*FLOOR(AU$21/$AQ18,1),"") | AV18: =IF(G18>0,AV$21-$AQ18*FLOOR(AV$21/$AQ18,1),"") | AW18: =IF(AQ18>0,SMALL(AR18:AV18,1),"") | AX18: =IF(AQ18>0,HLOOKUP(AW18,AR18:AV40,4,FALSE),"") | AY18: =IF(AQ18>0,SMALL(AR18:AV18,1),"") | AZ18: =IF(AQ18>0,HLOOKUP(AY18,AR18:AV40,4,FALSE),"") | BE18: =C18*2*(D18+E18)*F18 -> 0 | BF18: =BE18/(1.2*2.4) -> 0 | BG18: =BF18*20.33/(2*2*8/12)/1.5 -> 0 | BH18: =BF18*30.5/(2*3*8/12)/1.5 -> 0 | BI18: =0.02*4*8*BF18 -> 0 | BJ18: =0.02*4*8*BF18 -> 0
B19: C-9 | J19: =AI19 | K19: =F19+H19-G19/1000+IF(C19>0,0.5,0) -> 0 | O19: =AX19 | P19: =IF(C19>0,0.05*2+2*(D19+E19)-4*(G19/1000),0) -> 0 | R19: 0 | T19: =4*0.05+10*0.1 -> 1.2 | U19: =F19-T19 -> -1.2 | X19: =IF(C19>0,Z19*J19*VLOOKUP(I19,$V$11:$W$17,2,FALSE),"") | Y19: =IF(C19>0,O19*AA19*VLOOKUP(I19,$V$11:$W$17,2,FALSE),"") | Z19: =IF(C19>0,CEILING(C19*K19*(L19+M19)/J19,1),"") | AA19: =IF(C19>0,CEILING(C19*P19*(14+U19*1000/Q19+R19+1)/O19,1),"") | AB19: =K19 -> 0 | AC19: =IF(C19>0,AC$21-$AB19*FLOOR(AC$21/$AB19,1),"") | AD19: =IF(D19>0,AD$21-$AB19*FLOOR(AD$21/$AB19,1),"") | AE19: =IF(E19>0,AE$21-$AB19*FLOOR(AE$21/$AB19,1),"") | AF19: =IF(F19>0,AF$21-$AB19*FLOOR(AF$21/$AB19,1),"") | AG19: =IF(G19>0,AG$21-$AB19*FLOOR(AG$21/$AB19,1),"") | AH19: =IF(AB19>0,SMALL(AC19:AG19,1),"") | AI19: =IF(AB19>0,HLOOKUP(AH19,AC19:AG42,3,FALSE),"") | AL19: =C19*D19*E19*F19 -> 0 | AM19: =C19*D19*E19*H19*1.3 -> 0 | AN19: =AM19-(AL19*1.15) -> 0 | AO19: =D19*E19*C19 -> 0 | AQ19: =P19 -> 0 | AR19: =IF(C19>0,AR$21-$AQ19*FLOOR(AR$21/$AQ19,1),"") | AS19: =IF(D19>0,AS$21-$AQ19*FLOOR(AS$21/$AQ19,1),"") | AT19: =IF(E19>0,AT$21-$AQ19*FLOOR(AT$21/$AQ19,1),"") | AU19: =IF(F19>0,AU$21-$AQ19*FLOOR(AU$21/$AQ19,1),"") | AV19: =IF(G19>0,AV$21-$AQ19*FLOOR(AV$21/$AQ19,1),"") | AW19: =IF(AQ19>0,SMALL(AR19:AV19,1),"") | AX19: =IF(AQ19>0,HLOOKUP(AW19,AR19:AV42,3,FALSE),"") | AY19: =IF(AQ19>0,SMALL(AR19:AV19,1),"") | AZ19: =IF(AQ19>0,HLOOKUP(AY19,AR19:AV42,3,FALSE),"") | BE19: =C19*2*(D19+E19)*F19 -> 0 | BF19: =BE19/(1.2*2.4) -> 0 | BG19: =BF19*20.33/(2*2*8/12)/1.5 -> 0 | BH19: =BF19*30.5/(2*3*8/12)/1.5 -> 0 | BI19: =0.02*4*8*BF19 -> 0 | BJ19: =0.02*4*8*BF19 -> 0
B20: C-10 | J20: =AI20 | K20: =F20+H20-G20/1000+IF(C20>0,0.5,0) -> 0 | O20: =AX20 | P20: =IF(C20>0,0.05*2+2*(D20+E20)-4*(G20/1000),0) -> 0 | R20: 0 | T20: =4*0.05+10*0.1 -> 1.2 | U20: =F20-T20 -> -1.2 | X20: =IF(C20>0,Z20*J20*VLOOKUP(I20,$V$11:$W$17,2,FALSE),"") | Y20: =IF(C20>0,O20*AA20*VLOOKUP(I20,$V$11:$W$17,2,FALSE),"") | Z20: =IF(C20>0,CEILING(C20*K20*(L20+M20)/J20,1),"") | AA20: =IF(C20>0,CEILING(C20*P20*(14+U20*1000/Q20+R20+1)/O20,1),"") | AB20: =K20 -> 0 | AC20: =IF(C20>0,AC$21-$AB20*FLOOR(AC$21/$AB20,1),"") | AD20: =IF(D20>0,AD$21-$AB20*FLOOR(AD$21/$AB20,1),"") | AE20: =IF(E20>0,AE$21-$AB20*FLOOR(AE$21/$AB20,1),"") | AF20: =IF(F20>0,AF$21-$AB20*FLOOR(AF$21/$AB20,1),"") | AG20: =IF(G20>0,AG$21-$AB20*FLOOR(AG$21/$AB20,1),"") | AH20: =IF(AB20>0,SMALL(AC20:AG20,1),"") | AI20: =IF(AB20>0,HLOOKUP(AH20,AC20:AG44,2,FALSE),"") | AL20: =C20*D20*E20*F20 -> 0 | AM20: =C20*D20*E20*H20*1.3 -> 0 | AN20: =AM20-(AL20*1.15) -> 0 | AO20: =D20*E20*C20 -> 0 | AQ20: =P20 -> 0 | AR20: =IF(C20>0,AR$21-$AQ20*FLOOR(AR$21/$AQ20,1),"") | AS20: =IF(D20>0,AS$21-$AQ20*FLOOR(AS$21/$AQ20,1),"") | AT20: =IF(E20>0,AT$21-$AQ20*FLOOR(AT$21/$AQ20,1),"") | AU20: =IF(F20>0,AU$21-$AQ20*FLOOR(AU$21/$AQ20,1),"") | AV20: =IF(G20>0,AV$21-$AQ20*FLOOR(AV$21/$AQ20,1),"") | AW20: =IF(AQ20>0,SMALL(AR20:AV20,1),"") | AX20: =IF(AQ20>0,HLOOKUP(AW20,AR20:AV44,2,FALSE),"") | AY20: =IF(AQ20>0,SMALL(AR20:AV20,1),"") | AZ20: =IF(AQ20>0,HLOOKUP(AY20,AR20:AV44,2,FALSE),"") | BE20: =C20*2*(D20+E20)*F20 -> 0 | BF20: =BE20/(1.2*2.4) -> 0 | BG20: =BF20*20.33/(2*2*8/12)/1.5 -> 0 | BH20: =BF20*30.5/(2*3*8/12)/1.5 -> 0 | BI20: =0.02*4*8*BF20 -> 0 | BJ20: =0.02*4*8*BF20 -> 0
X21: =SUM(X11:X17) -> 227.57997 | Y21: =SUM(Y11:Y17) -> 284.47496 | AC21: 6 | AD21: =AC21+1.5 -> 7.5 | AE21: =AD21+1.5 -> 9 | AF21: =AE21+1.5 -> 10.5 | AG21: =AF21+1.5 -> 12 | AL21: =SUM(AL11:AL20) -> 2.56 | AM21: =SUM(AM11:AM20) -> 1.248 | AN21: =SUM(AN11:AN20) -> -1.696 | AR21: 6 | AS21: =AR21+1.5 -> 7.5 | AT21: =AS21+1.5 -> 9 | AU21: =AT21+1.5 -> 10.5 | AV21: =AU21+1.5 -> 12 | BF21: =CEILING(SUM(BF11:BF20),1) -> 9 | BG21: =CEILING(SUM(BG11:BG20),1) -> 46 | BH21: =CEILING(SUM(BH11:BH20),1) -> 46 | BI21: =CEILING(SUM(BI11:BI20),1) -> 6 | BJ21: =CEILING(SUM(BJ11:BJ20),1) -> 6
F22: MATERIALS | X22: =X21+Y21 -> 512.05493 | AL22: =VLOOKUP(G8,AJ11:AK14,2,FALSE) -> 12
X23: Tie Wire | Y23: =CEILING(0.013*X22,0.5) -> 7 | AK23: Cement | AL23: =CEILING(AL22*AL21,1) -> 31
F24: COLUMN | G24: ITEM | H24: QUANTITY | I24: UNIT | J24: PRICE | K24: TOTAL COST | AK24: Sand | AL24: =AL21/2 -> 1.28
G25: ='Materials Price List'!A8 -> Cement | H25: =AL23 -> 31 | I25: bags | J25: =IF(H25="","",VLOOKUP(G25,'Materials Price List'!$A$8:$B$100,2,FALSE)) -> 220 | K25: =IF(H25="","",H25*J25) -> 6820 | AK25: Gravel | AL25: =AL21 -> 2.56
G26: ='Materials Price List'!A9 -> Sand | H26: =AL24 -> 1.28 | I26: cu.m | J26: =IF(H26="","",VLOOKUP(G26,'Materials Price List'!$A$8:$B$100,2,FALSE)) -> 875 | K26: =IF(H26="","",H26*J26) -> 1120
G27: ='Materials Price List'!A10 -> Gravel | H27: =AL25 -> 2.56 | I27: cu.m | J27: =IF(H27="","",VLOOKUP(G27,'Materials Price List'!$A$8:$B$100,2,FALSE)) -> 1875 | K27: =IF(H27="","",H27*J27) -> 4800
G28: ='Materials Price List'!A11 -> Tie Wire | H28: =Y23 -> 7 | I28: kg | J28: =IF(H28="","",VLOOKUP(G28,'Materials Price List'!$A$8:$B$100,2,FALSE)) -> 95 | K28: =IF(H28="","",H28*J28) -> 665
G29: ='Materials Price List'!A51 -> 2x3x8 Good Lumber | H29: =BH21 -> 46 | I29: pcs | J29: =IF(H29="","",VLOOKUP(G29,'Materials Price List'!$A$8:$B$100,2,FALSE)) -> 275 | K29: =IF(H29="","",H29*J29) -> 12650
G30: ='Materials Price List'!A52 -> 2x2x8 Good Lumber | H30: =BG21 -> 46 | I30: pcs | J30: =IF(H30="","",VLOOKUP(G30,'Materials Price List'!$A$8:$B$100,2,FALSE)) -> 210 | K30: =IF(H30="","",H30*J30) -> 9660
G31: ='Materials Price List'!A54 -> 3/4" Phenolic Board | H31: =BF21 -> 9 | I31: pcs | J31: =IF(H31="","",VLOOKUP(G31,'Materials Price List'!$A$8:$B$100,2,FALSE)) -> 1200 | K31: =IF(H31="","",H31*J31) -> 10800
G32: ='Materials Price List'!A55 -> Common Nail 2" | H32: =BI21 -> 6 | I32: kg | J32: =IF(H32="","",VLOOKUP(G32,'Materials Price List'!$A$8:$B$100,2,FALSE)) -> 90 | K32: =IF(H32="","",H32*J32) -> 540
G33: ='Materials Price List'!A56 -> Common Nail 3" | H33: =BJ21 -> 6 | I33: kg | J33: =IF(H33="","",VLOOKUP(G33,'Materials Price List'!$A$8:$B$100,2,FALSE)) -> 90 | K33: =IF(H33="","",H33*J33) -> 540
F34: =IF(C11>0,B11,"") -> C-1 | G34: =IF(C11>0,CONCATENATE(I11," X ",J11,"m"),"") -> 16mm Ø X 6m | H34: =Z11 -> 24 | I34: =IF(H34="","","pcs") -> pcs | J34: =IF(H34="","",VLOOKUP(G34,'Materials Price List'!$A$8:$B$100,2,FALSE)) -> 419.47183 | K34: =IF(H34="","",H34*J34) -> 10067.324
