Workbook

Sheet Estimate
A1: Project Title: | C1: PROPOSED CONSTRUCTION OF TWO STOREY RESIDENTIAL/APARTMENT BUILDING.
A2: Location: | C2: Maganay, Buug, Zamboanga Sibugay | K2: Budget | L2: 1200000 | O2: No window grilles
A3: Date: | K3: Matls Markup | L3: 0 | M3: =E430 -> 857193.83 | O3: No boulders
A4: DETAILED ESTIMATE | K4: Hauling Rate | L4: 0.01 | M4: =H430 -> 7840.205 | O4: Septic Tank at 1.50m x 3.00m
A5: ITEM NO. | B5: ITEM DESCRIPTION | F5: QTY | G5: UNIT | H5: UNIT PRICE | I5: AMOUNT | K5: Labor Rate | L5: 0.3 | M5: =F430 -> 246942.15
K6: EDC | L6: =ABC!G33 -> 1220214.3
A7: I. | B7: LAYOUT AND EXCAVATION | F7: =F10+F11+F12 -> 58.68 | G7: cu.m of excavation | K7: OCM | L7: =5%+0.5%+0.5% -> 0.06
B8: Scope of Work: | K8: Contr Profit | L8: 0.1
C9: 1. Includes clearing, layout, and excavation works for: | K9: Indirect Cost | L9: =ABC!N33 -> 266006.71
C10: a. Wall and Zoccalo Footings | F10: 10.68 | K10: TOTAL | L10: =ABC!O33 -> 1486221
C11: b. Column Footings | F11: 21
C12: c. Septic Tank | F12: 27
B13: Labor:
C14: Excavation works | F14: =F7 -> 58.68 | G14: cu.m | H14: 200 | I14: =H14*F14 -> 11736
B15: Materials:
C16: Assorted Form Lumber | F16: =2*2*10/12*50 -> 166.66667 | G16: bd.ft | H16: 23 | I16: =H16*F16 -> 3833.3333
C17: Assorted CW Nails | F17: 3 | G17: kgs | H17: 80 | I17: =H17*F17 -> 240
C18: Nylon Chord | F18: 3 | G18: rolls | H18: 50 | I18: =H18*F18 -> 150
H20: Material Cost | I20: =SUM(I16:I18) -> 4223.3333
H21: Labor Cost | I21: =I14 -> 11736
H22: Total Cost | I22: =I20+I21 -> 15959.333
A23: II. | B23: EMBANKMENT WORKS | F23: 14 | G23: cu.m
B24: Scope of Work:
C25: 1. Embankment for buildable areas
C26: 2. Backfilling Works
B28: Materials:
C29: Filling Materials - to elevate the buildable area by 0.20m | F29: =F23 -> 14 | G29: cu.m | H29: 250 | I29: =H29*F29 -> 3500
H31: Material Cost | I31: =SUM(I29:I30) -> 3500
H32: ="Hauling/Handling Cost "&TEXT(L$4,"#%")&" of MC" -> Hauling/Handling Cost 1% of MC | I32: =L$4*I31 -> 35
H33: ="Labor Cost "&TEXT(L$5,"#%")&" of MC" -> Labor Cost 30% of MC | I33: =L$5*I31 -> 1050
H34: Total Cost | I34: =I31+I32+I33 -> 4585
A35: III. | B35: REINFORCED CONCRETE WORKS | G35: cu.m concrete
B36: Scope of Work:
B37: 1. Construction of reinforced concrete works system with deformed bars layout arranged according to structural plans
B38: and specification, includes the following:
B39: a. | C39: Column Footings
B40: b. | C40: Columns
B41: c. | C41: Floor Slabs on Grade - all areas includ. Porch, Back Exit Landing, Ramp
C42: Slab thickness shall be 0.10m with temperature bars spaced 0.60m bothways on top of gravel bed throughout.
B43: NOTE: | C43: Finishing of Ramp with horizontal grooves every 10 cm along entire length
...

Sheet Sheet2

Sheet ABC
A1: Republic of the Philippines
A2: DEPARTMENT OF HEALTH | R2: 2 copies Detailed Estimate (File, COA)
A3: REGIONAL OFFICE IX | R3: 1 copy BOQ
A4: Upper Calarian, Zamboanga City 7000 | R4: 3 copies ABC (File, BAC, COA)
A5: Phone : (062) 983-0314, (062) 983-0416, Fax : (062) 991-3380 | R5: 3 copies PERT-CPM (File, BAC, COA)
A6: Email : dohchdzp@yahoo.com, Web : www.doh.gov.ph | R6: 3 copies Scope of Work (File, BAC, COA)
A8: APPROVED BUDGET FOR THE CONTRACT
A10: =Estimate!C1 -> PROPOSED CONSTRUCTION OF TWO STOREY RESIDENTIAL/APARTMENT BUILDING.
A11: =Estimate!C2 -> Maganay, Buug, Zamboanga Sibugay
A12: Type of Facility : Barangay Health Station (BHS)
A13: Floor Area : 54.40 sq.m | O13: Contract Duration: | P13: 150 C.D.
A14: ITEM NO. | B14: DESCRIPTION | E14: QUANTITY | F14: UNIT | G14: ESTIMATED DIRECT COST | H14: MARKUPS IN PERCENT | J14: TOTAL MARKUP | L14: VAT | N14: TOTAL INDIRECT COST | O14: TOTAL COST | P14: UNIT COST
H15: OCM | I15: PROFIT | J15: % | K15: VALUE
A16: (1) | B16: (2) | E16: (3) | F16: (4) | G16: (5) | H16: (6) | I16: (7) | J16: (8) | K16: (9) | L16: (10) | N16: (11) | O16: (12) | P16: (13)
H17: =Estimate!L7 -> 0.06 | I17: =Estimate!L8 -> 0.1 | J17: (6) + (7) | K17: (5) x (8) | L17: 0.05 | M17: [(5)+(9)] | N17: (9) + (10) | O17: (5) + (11) | P17: (12) / (3)
A18: I | B18: LAYOUT AND EXCAVATION | E18: =20.002+10.53 -> 30.532 | F18: cu.m | G18: =Estimate!I22 -> 15959.333 | H18: =H$17 -> 0.06 | I18: =I$17 -> 0.1 | J18: =SUM(H18:I18) -> 0.16 | K18: =G18*J18 -> 2553.4933 | L18: =(G18+K18)*0.05 -> 925.64133 | N18: =SUM(K18+L18) -> 3479.1347 | O18: =G18+N18 -> 19438.468 | P18: =O18/E18 -> 636.65885
A19: II | B19: EMBANKMENT WORKS | E19: =ROUNDUP(8*6.8*(0.4),0) -> 22 | F19: cu.m | G19: =Estimate!I34 -> 4585 | H19: =H$17 -> 0.06 | I19: =I$17 -> 0.1 | J19: =SUM(H19:I19) -> 0.16 | K19: =G19*J19 -> 733.6 | L19: =(G19+K19)*0.05 -> 265.93 | N19: =SUM(K19+L19) -> 999.53 | O19: =G19+N19 -> 5584.53 | P19: =O19/E19 -> 253.84227
A20: III | B20: REINFORCED CONCRETE WORKS | E20: 11.43 | F20: cu.m | G20: =Estimate!I63 -> 148509.46 | H20: =H$17 -> 0.06 | I20: =I$17 -> 0.1 | J20: =SUM(H20:I20) -> 0.16 | K20: =G20*J20 -> 23761.514 | L20: =(G20+K20)*0.05 -> 8613.5487 | N20: =SUM(K20+L20) -> 32375.062 | O20: =G20+N20 -> 180884.52 | P20: =O20/E20 -> 15825.418
A21: IV | B21: MASONRY WORKS | E21: 135.54 | F21: sq.m | G21: =Estimate!I88 -> 160345.96 | H21: =H$17 -> 0.06 | I21: =I$17 -> 0.1 | J21: =SUM(H21:I21) -> 0.16 | K21: =G21*J21 -> 25655.354 | L21: =(G21+K21)*0.05 -> 9300.066 | N21: =SUM(K21+L21) -> 34955.42 | O21: =G21+N21 -> 195301.39 | P21: =O21/E21 -> 1440.9133
A22: V | B22: CARPENTRY WORKS | E22: 96.8 | F22: sq.m | G22: =Estimate!I123 -> 82234.595 | H22: =H$17 -> 0.06 | I22: =I$17 -> 0.1 | J22: =SUM(H22:I22) -> 0.16 | K22: =G22*J22 -> 13157.535 | L22: =(G22+K22)*0.05 -> 4769.6065 | N22: =SUM(K22+L22) -> 17927.142 | O22: =G22+N22 -> 100161.74 | P22: =O22/E22 -> 1034.7287
A23: VI | B23: DOORS AND WINDOWS | E23: 14 | F23: job orders | G23: =Estimate!I144 -> 68950 | H23: =H$17 -> 0.06 | I23: =I$17 -> 0.1 | J23: =SUM(H23:I23) -> 0.16 | K23: =G23*J23 -> 11032 | L23: =(G23+K23)*0.05 -> 3999.1 | N23: =SUM(K23+L23) -> 15031.1 | O23: =G23+N23 -> 83981.1 | P23: =O23/E23 -> 5998.65
A24: VII | B24: STEEL WORKS AND SIGNAGE | E24: 1 | F24: lot | G24: =Estimate!I178 -> 83208.58 | H24: =H$17 -> 0.06 | I24: =I$17 -> 0.1 | J24: =SUM(H24:I24) -> 0.16 | K24: =G24*J24 -> 13313.373 | L24: =(G24+K24)*0.05 -> 4826.0976 | N24: =SUM(K24+L24) -> 18139.47 | O24: =G24+N24 -> 101348.05 | P24: =O24/E24 -> 101348.05
A25: VIII | B25: ROOFING WORKS | E25: 98.56 | F25: lin.m | G25: =Estimate!I197 -> 102247.46 | H25: =H$17 -> 0.06 | I25: =I$17 -> 0.1 | J25: =SUM(H25:I25) -> 0.16 | K25: =G25*J25 -> 16359.594 | L25: =(G25+K25)*0.05 -> 5930.353 | N25: =SUM(K25+L25) -> 22289.947 | O25: =G25+N25 -> 124537.41 | P25: =O25/E25 -> 1263.5695
A26: IX | B26: TILE WORKS | E26: 77.34 | F26: sq.m | G26: =Estimate!I226 -> 242972.25 | H26: =H$17 -> 0.06 | I26: =I$17 -> 0.1 | J26: =SUM(H26:I26) -> 0.16 | K26: =G26*J26 -> 38875.56 | L26: =(G26+K26)*0.05 -> 14092.391 | N26: =SUM(K26+L26) -> 52967.95 | O26: =G26+N26 -> 295940.2 | P26: =O26/E26 -> 3826.4831
A27: X | B27: SEPTIC TANK | E27: =1.5*3*1.8+1.2*1.2*1.5 -> 10.26 | F27: cu.m | G27: =Estimate!I251 -> 30023.89 | H27: =H$17 -> 0.06 | I27: =I$17 -> 0.1 | J27: =SUM(H27:I27) -> 0.16 | K27: =G27*J27 -> 4803.8224 | L27: =(G27+K27)*0.05 -> 1741.3856 | N27: =SUM(K27+L27) -> 6545.208 | O27: =G27+N27 -> 36569.098 | P27: =O27/E27 -> 3564.2396
A28: XI | B28: ELECTRICAL WORKS | E28: 3 | F28: circuits | G28: =Estimate!I301 -> 96068.85 | H28: =H$17 -> 0.06 | I28: =I$17 -> 0.1 | J28: =SUM(H28:I28) -> 0.16 | K28: =G28*J28 -> 15371.016 | L28: =(G28+K28)*0.05 -> 5571.9933 | N28: =SUM(K28+L28) -> 20943.009 | O28: =G28+N28 -> 117011.86 | P28: =O28/E28 -> 39003.953
A29: XII | B29: PLUMBING WORKS | E29: 1 | F29: unit | G29: =Estimate!I347 -> 35592.7 | H29: =H$17 -> 0.06 | I29: =I$17 -> 0.1 | J29: =SUM(H29:I29) -> 0.16 | K29: =G29*J29 -> 5694.832 | L29: =(G29+K29)*0.05 -> 2064.3766 | N29: =SUM(K29+L29) -> 7759.2086 | O29: =G29+N29 -> 43351.909 | P29: =O29/E29 -> 43351.909
A30: XIII | B30: PAINTING WORKS | E30: =354.12 -> 354.12 | F30: sq.m | G30: =Estimate!I377 -> 41278.1 | H30: =H$17 -> 0.06 | I30: =I$17 -> 0.1 | J30: =SUM(H30:I30) -> 0.16 | K30: =G30*J30 -> 6604.496 | L30: =(G30+K30)*0.05 -> 2394.1298 | N30: =SUM(K30+L30) -> 8998.6258 | O30: =G30+N30 -> 50276.726 | P30: =O30/E30 -> 141.97652
A31: =Estimate!A378 -> XIV. | B31: =Estimate!B378 -> WATER TOWER | E31: =Estimate!F378 -> 1 | F31: =Estimate!G378 -> unit | G31: =Estimate!I411 -> 108238.1 | H31: =H$17 -> 0.06 | I31: =I$17 -> 0.1 | J31: =SUM(H31:I31) -> 0.16 | K31: =G31*J31 -> 17318.095 | L31: =(G31+K31)*0.05 -> 6277.8095 | N31: =SUM(K31+L31) -> 23595.905 | O31: =G31+N31 -> 131834 | P31: =O31/E31 -> 131834
A33: TOTAL | G33: =SUM(G18:G32) -> 1220214.3 | K33: =SUM(K18:K32) -> 195234.29 | L33: =SUM(L18:L32) -> 70772.428 | N33: =SUM(N18:N32) -> 266006.71 | O33: =SUM(O18:O32) -> 1486221
A36: Prepared by: | D36: Verified and Certified by: | H36: Recommending Approval by: | N36: Approved by:
A37: CAMILO Y. NEE, CE | D37: BARJUNAID T. AMILASAN, CE | H37: only as to documents presented
H38: ATTY. TIMOTHY E. GALVEZ, RN, MPA | N38: JOSHUA G. BRILLANTES, MD, MPH
A41: HFEP Engineer II | D41: Engineer III / HFEP Infra In-Charge | H41: R.L.E.D. Chief / HFEP Coordinator | N41: BAC Chairman

Sheet BOQ
A1: Standard Form Number: SF-INFR-55
A2: Revised on: August 11, 2004
A3: BILL OF QUANTITIES
A5: Project Title: | C5: =Estimate!C1 -> PROPOSED CONSTRUCTION OF TWO STOREY RESIDENTIAL/APARTMENT BUILDING.
A6: Location: | C6: =Estimate!C2 -> Maganay, Buug, Zamboanga Sibugay
A8: ITEM# | B8: ITEM DESCRIPTION | F8: QTY | G8: UNIT | H8: UNIT PRICE | I8: AMOUNT
A10: I. | B10: LAYOUT AND EXCAVATION | F10: =Estimate!F7 -> 58.68 | G10: cu.m of excavation
B11: Scope of Work:
C12: 1. Includes clearing, layout, and excavation works for:
C13: a. Wall and Zoccalo Footings
C14: b. Column Footings
C15: c. Septic Tank
B16: Labor:
C17: Excavation works | G17: cu.m
B18: Materials:
C19: Assorted Form Lumber | G19: bd.ft
C20: Assorted CW Nails | G20: kgs
C21: Nylon Chord | G21: rolls
B24: (Pesos) _________________________ Amount in Words ____________________________________________________________________
C25: _____________________________________________________________________________________________________________
A27: II. | B27: EMBANKMENT WORKS | F27: =ROUNDUP(8*6.8*(0.4),0) -> 22 | G27: cu.m
B28: Scope of Work:
C29: 1. Embankment for buildable areas
C30: 2. Backfilling Works
B31: NOTE: | C31: If actual terrain and level of surface ground of the project site is hilly or too low such that rainwater may certainly flow into the building,
C32: proposal shall be made as extra work to raise the building further by such level higher than the road that is safe from flooding.
C33: Initial provision shall be included in this scope of work for the buildable area.
B35: Materials:
C36: Filling Materials - to elevate the buildable area by 0.40m | G36: cu.m
B39: (Pesos) _________________________ Amount in Words ____________________________________________________________________
C40: _____________________________________________________________________________________________________________
A42: III. | B42: REINFORCED CONCRETE WORKS | F42: =Estimate!F35 -> 0 | G42: cu.m concrete
B43: Scope of Work:
B44: 1. Construction of reinforced concrete works system with deformed bars layout arranged according to structural plans
B45: and specification, includes the following:
B46: a. | C46: Column Footings
B47: b. | C47: Columns
B48: c. | C48: Floor Slabs on Grade - all areas includ. Porch, Back Exit Landing, Ramp
C49: Slab thickness shall be 0.10m with temperature bars spaced 0.60m bothways on top of gravel bed throughout.
B50: NOTE: | C50: Finishing of Ramp with horizontal grooves every 10 cm along entire length
...

Sheet BOQ w quantity
A1: Standard Form Number: SF-INFR-55
A2: Revised on: August 11, 2004
A3: BILL OF QUANTITIES
A5: Project Title: | C5: =Estimate!C1 -> PROPOSED CONSTRUCTION OF TWO STOREY RESIDENTIAL/APARTMENT BUILDING.
A6: Location: | C6: =Estimate!C2 -> Maganay, Buug, Zamboanga Sibugay
A8: ITEM# | B8: ITEM DESCRIPTION | F8: QTY | G8: UNIT | H8: UNIT PRICE | I8: AMOUNT
A10: I. | B10: LAYOUT AND EXCAVATION | F10: 25.191 | G10: cu.m of excavation
B11: Scope of Work:
C12: 1. Includes clearing, layout, and excavation works for:
C13: a. Wall and Zoccalo Footings
C14: b. Column Footings
C15: c. Septic Tank and Placenta Pit
B16: Labor: | F16: 1 | G16: lumpsum | I16: =H16*F16 -> 0
B17: Materials:
C18: Assorted Form Lumber | F18: 166.66667 | G18: bd.ft | I18: =H18*F18 -> 0
C19: Assorted CW Nails | F19: 3 | G19: kgs | I19: =H19*F19 -> 0
C20: Nylon Chord | F20: 3 | G20: rolls | I20: =H20*F20 -> 0
B22: (Pesos) _________________________ Amount in Words ____________________________________________________________________
C23: _____________________________________________________________________________________________________________
A25: II. | B25: EMBANKMENT WORKS | F25: 22 | G25: cu.m
B26: Scope of Work:
C27: 1. Embankment for buildable areas
C28: 2. Backfilling Works
B29: NOTE: | C29: If actual terrain and level of surface ground of the project site is hilly or too low such that rainwater may certainly flow into the building,
C30: proposal shall be made as extra work to raise the building further by such level higher than the road that is safe from flooding.
C31: Initial provision shall be included in this scope of work for the buildable area.
B33: Materials:
C34: Filling Materials - to elevate the buildable area by 0.40m | F34: 22 | G34: cu.m | I34: =H34*F34 -> 0
B37: (Pesos) _________________________ Amount in Words ____________________________________________________________________
C38: _____________________________________________________________________________________________________________
A40: III. | B40: REINFORCED CONCRETE WORKS | F40: 10.852 | G40: cu.m concrete
B41: Scope of Work:
B42: 1. Construction of reinforced concrete works system with deformed bars layout arranged according to structural plans
B43: and specification, includes the following:
B44: a. | C44: Column Footings - 3 of 1.0m x 1.0m x 0.20m + 6 of 0.80m x 0.80m x 0.20m | F44: 1.368 | G44: cu.m
B45: b. | C45: Columns - 9 of 0.20m x 0.20m x 4.10m | F45: 1.476 | G45: cu.m
B46: c. | C46: Floor Slabs on Grade - all areas includ. Porch, Back Exit Landing, Ramp - 67.2 sq.m | F46: 6.718 | G46: cu.m
C47: Slab thickness shall be 0.10m with temperature bars spaced 0.60m bothways on top of gravel bed throughout.
B48: NOTE: | C48: Finishing of Ramp with horizontal grooves every 10 cm along entire length
B49: d. | C49: Roof Beams - 0.15m x 0.20m x 36.40 lin.m | F49: 1.092 | G49: cu.m
...

Sheet Sheet1
A1: CIRCUIT No. | B1: LOAD DESCRIPTION | C1: LIGHT | E1: SWITCH | H1: POWER OUTLET | I1: VOLT-AMPERE | J1: VOLTAGE | K1: AMPERE | L1: WIRE SIZE | M1: CONDUIT | N1: CIRCUIT BREAKER
C2: FL (20w) | D2: PL 18w | E2: S1 | F2: S2 | G2: S3
A3: 1 | B3: Lighting Load | C3: 5 | D3: 6 | E3: 4 | G3: 2 | I3: =5*20+6*18 -> 208 | J3: 220 | K3: =IF(ISBLANK(J3),"",I3/J3) -> 0.94545455 | L3: 2 - 3.5mm2 TW (#12) | M3: uPVC Pipe 1/2”Ø | N3: 15 amp. 2P | P3: TW Cu. Wire 2.0 mm2 (#14) [150 mtrs/box] (for lights)
A4: 2 | B4: Lighting Load | D4: 7 | G4: 1 | I4: =7*18 -> 126 | J4: 220 | K4: =IF(ISBLANK(J4),"",I4/J4) -> 0.57272727 | L4: 2 - 3.5mm2 TW (#12) | M4: uPVC Pipe 1/2”Ø | N4: 15 amp. 2P | P4: TW Cu. Wire 3.5 mm2 (#12) [150 mtrs/box] (for lights & outlets)
A5: 3 | B5: Power Outlets (Left Side) | H5: 6 | I5: =H5*360 -> 2160 | J5: 220 | K5: =IF(ISBLANK(J5),"",I5/J5) -> 9.8181818 | L5: 2 - 3.5mm2 TW (#12) | M5: uPVC Pipe 1/2”Ø | N5: 15 amp. 2P | P5: TW Cu. Wire Stranded 5.5 mm2 (#10) (for aircon provision)
A6: 4 | B6: Power Outlets (Right Side) | H6: 7 | I6: =H6*360 -> 2520 | J6: 220 | K6: =IF(ISBLANK(J6),"",I6/J6) -> 11.454545 | L6: 2 - 3.5mm2 TW (#12) | M6: uPVC Pipe 1/2”Ø | N6: 15 amp. 2P | P6: TW Cu. Wire Stranded 8 mm2 (#8) (for aircon provision)
A7: 5 | B7: Power Outlets | H7: 4 | I7: =H7*360 -> 1440 | J7: 220 | K7: =IF(ISBLANK(J7),"",I7/J7) -> 6.5454545 | L7: 2 - 3.5mm2 TW (#12) | M7: uPVC Pipe 1/2”Ø | N7: 15 amp. 2P | P7: TW Cu. Wire Stranded 14 mm2 (#6) (for aircon provision)
A8: 6 | B8: Spare | K8: =IF(ISBLANK(J8),"",I8/J8) | N8: 15 amp. 2P | P8: TW Cu. Wire Stranded 22 mm2 (#4) (for main entrance)
A9: TOTAL | C9: =SUM(C3:C8) -> 5 | D9: =SUM(D3:D8) -> 13 | E9: =SUM(E3:E8) -> 4 | F9: =SUM(F3:F8) -> 0 | G9: =SUM(G3:G8) -> 3 | H9: =SUM(H3:H8) -> 17 | I9: =SUM(I3:I8) -> 6454 | J9: =SUM(J3:J8) -> 1100 | K9: =SUM(K3:K8) -> 29.336364
B11: DIRECT COST
B12: A.1 Cost of Materials to be used in doing the work item called for, which shall include, the following:
B13: A.1.1 Cost at source, including processing, crushing, stockpiling, loading, royalties, local taxes, construction and/or maintenance of haul roads, etc.
B14: A.1.2 Expenses for Hauling to project site
B15: A.1.3 Handling expenses
B16: A.1.4 Storage expenses
B17: A.1.5 Allowance for waste and/or losses, not to exceed 5% of materials requirement
B18: A.2 Cost of Labor
B19: A.2.1 Salaries and wages, as authorized by the Department of Labor and Employment
B20: A.2.2 Fringe benefits, such as vacation and sick leaves, benefits under the Workmen's Compensation Act, GSIS and/or SSS contributions, allowances, 13th month pay, bonuses, etc
B21: A.3 Equipment Expenses
B22: A.3.1 Rental of equipment which shall be based on the prevailing "Associated Construction Equipment Lessors, Inc" (ACEL) rental rates approved for use by the DPWH (Presently it is the 2009 ACEL Rates). Rental rates of equipment not indicated in the ACEL booklet shall be taken from the rental rates prepared by the Bureau of Equipment. For simplicity in computation, the operated rental rates are preferred over the bare rental rates as the former includes operator's wages, fringe benefits, fuel, oil, lubricants and equipment maintenance. The make, model and capacity of the equipment should be indicated in the detailed unit cost analysis.
... B38: B.5 VAT Component – shall be 12% of the sum of the EDC, OCM and Profit

Sheet ARDYL
A1: Project Title: | C1: PROPOSED CONSTRUCTION OF TWO STOREY RESIDENTIAL/APARTMENT BUILDING.
A2: Location: | K2: Budget | L2: 1200000 | O2: No window grilles
A3: Date: | K3: Matls Markup | L3: 0 | M3: =E357 -> 1276735 | O3: No boulders
A4: DETAILED ESTIMATE | K4: Hauling Rate | L4: 0.01 | M4: =H357 -> 0 | O4: Septic Tank at 1.50m x 3.00m
A5: ITEM NO. | B5: ITEM DESCRIPTION | F5: QTY | G5: UNIT | H5: UNIT PRICE | I5: AMOUNT | K5: Labor Rate | L5: 0.3 | M5: =F357 -> 0
K6: EDC | L6: =ABC!G33 -> 1220214.3
A7: I. | B7: LAYOUT AND EXCAVATION | F7: =F10+F11+F12 -> 58.68 | G7: cu.m of excavation | K7: OCM | L7: =5%+0.5%+0.5% -> 0.06
B8: Scope of Work: | K8: Contr Profit | L8: 0.1
C9: 1. Includes clearing, layout, and excavation works for: | K9: Indirect Cost | L9: =ABC!N33 -> 266006.71
C10: a. Wall and Zoccalo Footings | F10: 10.68 | K10: TOTAL | L10: =ABC!O33 -> 1486221
C11: b. Column Footings | F11: 21
C12: c. Septic Tank | F12: 27
B13: Labor:
C14: Excavation works | F14: =F7 -> 58.68 | G14: cu.m | H14: 200 | I14: =H14*F14 -> 11736
B15: Materials:
C16: Assorted Form Lumber | F16: =2*2*10/12*50 -> 166.66667 | G16: bd.ft | H16: 21 | I16: =H16*F16 -> 3500
C17: Assorted CW Nails | F17: 3 | G17: kgs | H17: 80 | I17: =H17*F17 -> 240
C18: Nylon Chord | F18: 3 | G18: rolls | H18: 50 | I18: =H18*F18 -> 150
H20: Material Cost | I20: =SUM(I16:I18) -> 3890
H21: Labor Cost | I21: =I14 -> 11736
H22: Total Cost | I22: =I20+I21 -> 15626
A23: II. | B23: EMBANKMENT WORKS | F23: 14 | G23: cu.m
B24: Scope of Work:
C25: 1. Embankment for buildable areas
C26: 2. Backfilling Works
B28: Materials:
C29: Filling Materials - to elevate the buildable area by 0.20m | F29: =F23 -> 14 | G29: cu.m | H29: 250 | I29: =H29*F29 -> 3500
H31: Material Cost | I31: =SUM(I29:I30) -> 3500
H32: ="Labor Cost "&TEXT(L$5,"#%")&" of MC" -> Labor Cost 30% of MC | I32: =L$5*I31 -> 1050
H33: Total Cost | I33: =I31+I32 -> 4550
A34: III. | B34: REINFORCED CONCRETE WORKS | F34: 64.93 | G34: cu.m concrete
B35: Scope of Work:
B36: 1. Construction of reinforced concrete works system with deformed bars layout arranged according to structural plans
B37: and specification, includes the following:
B38: a. | C38: Column Footings
B39: b. | C39: Columns
B40: c. | C40: Floor Slabs on Grade - all areas includ. Porch,
C41: Slab thickness shall be 0.10m with temperature bars spaced 0.60m bothways on top of gravel bed throughout.
B42: d. | C42: Roof Beams
B43: e. | C43: Lavatory Counters
...

Sheet Masonry Works.
A1: TOTAL AREA = | C1: 539.91 | D1: sq.m
A3: Front
A4: total Area | C4: sq.m
A6: Rare
A7: total Area | C7: sq.m
A9: Right Side's
A10: Total area | C10: sq.m
A12: Left Side's
A13: Total area | C13: sq.m
A15: Interior wall
A16: area | C16: sq.m
A19: Deductive
A20: Door's
A21: width | B21: 1
A22: height | B22: 2.1
A23: area | B23: =B22*B21 -> 2.1 | C23: sq.m
A26: Window's
A27: width | B27: 1.9 | K27: 28 | L27: 3 | M27: =K27*L27 -> 84
A28: height | B28: 1.2
A29: area | B29: =B28*B27 -> 2.28 | C29: sq.m
A31: 100m thinck CHB = | D31: =C1*12.5 -> 6748.875 | E31: pcs | J31: =D31*0.128 -> 863.856 | K31: =J31/6 -> 143.976 | L31: =K31+K32 -> 337.44375
D32: Mortar | E32: Plaster | F32: Total | J32: =D31*0.172 -> 1160.8065 | K32: =J32/6 -> 193.46775
A33: Portland Cement (40kg/bag) = | D33: =(D31/100)*4.176 -> 281.83302 | E33: =C1*0.192 -> 103.66272 | F33: =ROUNDUP(D33+E33,0) -> 386 | G33: bags
A34: Washed Sand = | D34: =(D31/100)*0.348 -> 23.486085 | E34: =C1*0.016 -> 8.63856 | F34: =ROUNDUP(D34+E34,0) -> 33 | G34: cu.m
D36: Horizontal | E36: Vertical
A37: 10mmØ x 6.0m Def. Bar = | D37: =ROUNDUP(((D31*0.128)/6),0) -> 144 | E37: =ROUNDUP(((D31*0.172)/6),0) -> 194 | F37: =D37+E37 -> 338 | G37: pcs
A41: Summary
A42: 1 | B42: CHB= | E42: =D31 -> 6748.875 | F42: Pcs
A43: 2 | B43: Cement= | E43: =F33 -> 386 | F43: Bags
A44: 3 | B44: Fine Aggregates= | E44: =F34 -> 33 | F44: Cu.m
A45: 4 | B45: 10mm Def. Bars= | E45: =F37 -> 338 | F45: Pcs
