Workbook
Name A: #REF!
Name A: #REF!
Name A: #REF!
Name A: #REF!
Name A: #REF!
Name A: #REF!
Name A: #REF!
Name A: #REF!
Name A: #REF!
Name A: #REF!
Name A: #REF!
Name A: #REF!
Name A: #REF!
Name A: #REF!
Name A: #REF!
Name A: #REF!
Name A: #REF!
Name A: #REF!
Name A: #REF!
Name A: #REF!
Name A: #REF!
Name A: #REF!
Name A: #REF!
Name A: #REF!
Name A: #REF!
Name A: #REF!
Name A: #REF!
Name A: #REF!
Name A: #REF!
Name A: #REF!
Name A: #REF!
Name A: #REF!
Name A: #REF!
Name A: #REF!
Name A: #REF!
Name A: #REF!
Name A: #REF!
Name A: #REF!
Name A: #REF!
Name A: #REF!
Name A: #REF!
Name A: #REF!
Name A: #REF!
Name A: #REF!
Name A: #REF!
Name A: #REF!
Name A: #REF!
Name A: #REF!
Name A: #REF!
Name add: #REF!
Name add: #REF!
Name add: #REF!
Name add: #REF!
Name add: #REF!
Name add: #REF!
Name add: #REF!
Name add: #REF!
Name add: #REF!
Name add: #REF!
Name add: #REF!

Sheet INPUT DATA
A2: INPUT ONLY ON GRAY CELLS
B4: PROJECT TITLE: | C4: PROPOSED ONE STOREY TWO BED ROOM RESIDENTIAL BUILDING
B5: PROJECT LOCATION: | C5: ANGELES, PAMPANGA
A7: Item Number | B7: Item of Works | C7: Qty | D7: Units | E7: Remarks | F7: DIRECT COST | I7: INDIRECT COST
F8: Manpower /Labor | G8: Equipment/ Tools | H8: Materials | I8: OCM | J8: Profit | K8: VAT | L8: Total Cost | M8: Unit Cost
A9: ARCHITECTURAL / CIVIL WORKS
A10: ='800(1) Clearing & Grab'!E5 -> 800(1) | B10: ='800(1) Clearing & Grab'!G5 -> CLEARING AND GRUBBING | C10: 200 | D10: ='800(1) Clearing & Grab'!G8 -> SQ.M. | E10: Area of the project for clearing | F10: ='800(1) Clearing & Grab'!T20 -> 600 | G10: ='800(1) Clearing & Grab'!T29 -> 21555.2 | H10: ='800(1) Clearing & Grab'!T46 -> 0 | I10: ='800(1) Clearing & Grab'!T48 -> 1107.76 | J10: ='800(1) Clearing & Grab'!T49 -> 2215.52 | K10: ='800(1) Clearing & Grab'!T50 -> 0 | L10: =SUM(F10:K10) -> 25478.48 | M10: =L10/C10 -> 127.3924
A11: ='800(3)a Ind Remov of Trees'!E5 -> 800(3)a | B11: ='800(3)a Ind Remov of Trees'!G5 -> INDIVIDUAL REMOVAL OF TREES (UPTO 300MM DIAMETER) | C11: 2 | D11: ='800(3)a Ind Remov of Trees'!E6 -> EACH | E11: Number of trees to be removed from project site | F11: ='800(3)a Ind Remov of Trees'!T20 -> 550 | G11: ='800(3)a Ind Remov of Trees'!T30 -> 3908.94 | H11: ='800(3)a Ind Remov of Trees'!T47 -> 0 | I11: ='800(3)a Ind Remov of Trees'!T49 -> 222.947 | J11: ='800(3)a Ind Remov of Trees'!T50 -> 445.894 | K11: ='800(3)a Ind Remov of Trees'!T51 -> 0 | L11: =SUM(F11:K11) -> 5127.781 | M11: =L11/C11 -> 2563.8905
A12: ='803(1)a-Struc Exca Common Soil'!E5 -> 803(1)a | B12: ='803(1)a-Struc Exca Common Soil'!G5 -> STRUCTURE EXCAVATION (COMMON SOIL) | C12: 23 | D12: ='803(1)a-Struc Exca Common Soil'!G8 -> CU.M. | E12: Volume to be excavated by Backhoe | F12: ='803(1)a-Struc Exca Common Soil'!T19 -> 287.5 | G12: ='803(1)a-Struc Exca Common Soil'!T29 -> 4905.9 | H12: ='803(1)a-Struc Exca Common Soil'!T42 -> 0 | I12: ='803(1)a-Struc Exca Common Soil'!T44 -> 259.67 | J12: ='803(1)a-Struc Exca Common Soil'!T45 -> 519.34 | K12: ='803(1)a-Struc Exca Common Soil'!T46 -> 0 | L12: =SUM(F12:K12) -> 5972.41 | M12: =L12/C12 -> 259.67
A13: ='803(1)a-Struc Exca Soft Rock'!E5 -> 803(1)a | B13: ='803(1)a-Struc Exca Soft Rock'!G5 -> STRUCTURE EXCAVATION (SOFT ROCK) | C13: 0 | D13: ='803(1)a-Struc Exca Soft Rock'!E6 -> CU.M. | E13: Volume to be excavated by Backhoe | F13: ='803(1)a-Struc Exca Soft Rock'!T19 -> 0 | G13: ='803(1)a-Struc Exca Soft Rock'!T30 -> 0 | H13: ='803(1)a-Struc Exca Soft Rock'!T43 -> 0 | I13: ='803(1)a-Struc Exca Soft Rock'!T45 -> 0 | J13: ='803(1)a-Struc Exca Soft Rock'!T46 -> 0 | K13: ='803(1)a-Struc Exca Soft Rock'!T47 -> 0 | L13: =SUM(F13:K13) -> 0 | M13: =L13/C13 -> #DIV/0!
A14: ='804(4) Gravel Bedding'!E5 -> 804(4) | B14: ='804(4) Gravel Bedding'!G5 -> GRAVEL BEDDING | C14: 3 | D14: ='804(4) Gravel Bedding'!G8 -> CU.M. | E14: Putting gravel as bedding in foundation | F14: ='804(4) Gravel Bedding'!T19 -> 625 | G14: ='804(4) Gravel Bedding'!T28 -> 677.5 | H14: ='804(4) Gravel Bedding'!T41 -> 4200 | I14: ='804(4) Gravel Bedding'!T43 -> 275.125 | J14: ='804(4) Gravel Bedding'!T44 -> 550.25 | K14: ='804(4) Gravel Bedding'!T45 -> 0 | L14: =SUM(F14:K14) -> 6327.875 | M14: =L14/C14 -> 2109.2917
A15: ='902(1)-Reinforced S for 1Storey'!E5 -> 902(1) | B15: ='902(1)-Reinforced S for 1Storey'!G5 -> REINFORCING STEEL OF REINFORCED CONCRETE STRUCTURES FOR ONE-STOREY, GRADE 40/60 | C15: 1200 | D15: ='902(1)-Reinforced S for 1Storey'!E6 -> KGS. | E15: After estimating the number of steel bars by direct counting on plan, get its total weight in kgs. | F15: ='902(1)-Reinforced S for 1Storey'!T17 -> 7738.54 | G15: ='902(1)-Reinforced S for 1Storey'!T26 -> 3772.43 | H15: ='902(1)-Reinforced S for 1Storey'!T38 -> 96201 | I15: ='902(1)-Reinforced S for 1Storey'!T40 -> 5385.5985 | J15: ='902(1)-Reinforced S for 1Storey'!T41 -> 10771.197 | K15: ='902(1)-Reinforced S for 1Storey'!T42 -> 0 | L15: =SUM(F15:K15) -> 123868.77 | M15: =L15/C15 -> 103.22397
A16: ='902(1)-Rein St for 2-5storey'!E5 -> 902(1) | B16: ='902(1)-Rein St for 2-5storey'!G5 -> REINFORCING STEEL OF REINFORCED CONCRETE STRUCTURES FOR TWO UPTO FIVE STOREY | C16: 50 | D16: ='902(1)-Rein St for 2-5storey'!E6 -> KGS. | E16: This is for two to 5 storey only. After estimating the number of steel bars by direct counting on plan, get its total weight in kgs. | F16: ='902(1)-Rein St for 2-5storey'!T17 -> 358.27 | G16: ='902(1)-Rein St for 2-5storey'!T26 -> 146.45 | H16: ='902(1)-Rein St for 2-5storey'!T38 -> 4008.38 | I16: ='902(1)-Rein St for 2-5storey'!T40 -> 225.655 | J16: ='902(1)-Rein St for 2-5storey'!T41 -> 451.31 | K16: ='902(1)-Rein St for 2-5storey'!T42 -> 0 | L16: =SUM(F16:K16) -> 5190.065 | M16: =L16/C16 -> 103.8013
A17: ='900(1)c2 Struc Con for footing'!E5 -> 900(1)c2 | B17: ='900(1)c2 Struc Con for footing'!G5 -> STRUCTURAL CONCRETE FOR FOOTING AND SLAB ON FILL (CLASS A, 28 DAYS) | C17: 12.4 | D17: ='900(1)c2 Struc Con for footing'!G8 -> CU.M. | E17: Total concrete volume of Footing & Slab on grade | F17: ='900(1)c2 Struc Con for footing'!T21 -> 13025.21 | G17: ='900(1)c2 Struc Con for footing'!T30 -> 7276.75 | H17: ='900(1)c2 Struc Con for footing'!T46 -> 55942.6 | I17: ='900(1)c2 Struc Con for footing'!T48 -> 3812.228 | J17: ='900(1)c2 Struc Con for footing'!T49 -> 7624.456 | K17: ='900(1)c2 Struc Con for footing'!T50 -> 0 | L17: =SUM(F17:K17) -> 87681.244 | M17: =L17/C17 -> 7071.0681
A18: ='900(1)Struc Con for beam col su'!E5 -> 900(1) | B18: ='900(1)Struc Con for beam col su'!G5 -> STRUCTURAL CONCRETE FOR FOOTING TIE BEAM, COLUMN, SUSPENDED SLAB, GIRDER/BEAM (CLASS A, 28 DAYS) | C18: 23.6 | D18: ='900(1)Struc Con for beam col su'!G8 -> CU.M. | E18: Total volume of concrete for beam, column tie beam, suspended slab & girder | F18: ='900(1)Struc Con for beam col su'!T21 -> 32777.78 | G18: ='900(1)Struc Con for beam col su'!T30 -> 18311.85 | H18: ='900(1)Struc Con for beam col su'!T46 -> 99391.4 | I18: ='900(1)Struc Con for beam col su'!T48 -> 7524.0515 | J18: ='900(1)Struc Con for beam col su'!T49 -> 15048.103 | K18: ='900(1)Struc Con for beam col su'!T50 -> 0 | L18: =SUM(F18:K18) -> 173053.18 | M18: =L18/C18 -> 7332.7621
A19: ='903(2) Formworks for 1-storey'!E5 -> 903(2) | B19: ='903(2) Formworks for 1-storey'!G5 -> FORMWORKS AND FALSEWORKS (FOR ONE-STOREY BUILDING) | C19: 49 | D19: ='903(2) Formworks for 1-storey'!G8 -> SQ.M. | E19: Area of the surface to be covered. E.i. compute the areas of columns, beams and other structural members that need form for concreting | F19: ='903(2) Formworks for 1-storey'!T22 -> 9285.8 | G19: ='903(2) Formworks for 1-storey'!T31 -> 928.58 | H19: ='903(2) Formworks for 1-storey'!T47 -> 29647.03 | I19: ='903(2) Formworks for 1-storey'!T49 -> 1993.0705 | J19: ='903(2) Formworks for 1-storey'!T50 -> 3986.141 | K19: ='903(2) Formworks for 1-storey'!T51 -> 0 | L19: =SUM(F19:K19) -> 45840.621 | M19: =L19/C19 -> 935.52289
A20: ='1046 4"CHB'!E5 -> 1046 | B20: ='1046 4"CHB'!G5 -> 100MM CHB NON LOAD BEARING/LOAD BEARING (INCLUDING REINFORCING STEEL) | C20: 189 | D20: ='1046 4"CHB'!E6 -> SQ.M. | E20: Total area of wall using 4" CHB | F20: ='1046 4"CHB'!T21 -> 19764.71 | G20: ='1046 4"CHB'!T30 -> 10475.29 | H20: ='1046 4"CHB'!T46 -> 120511.13 | I20: ='1046 4"CHB'!T48 -> 7537.5565 | J20: ='1046 4"CHB'!T49 -> 15075.113 | K20: ='1046 4"CHB'!T50 -> 0 | L20: =SUM(F20:K20) -> 173363.8 | M20: =L20/C20 -> 917.26878
A21: ='1046 6" CHB'!E5 -> 1046 | B21: ='1046 6" CHB'!G5 -> 150mm. CHB NON LOAD BEARING (including Reinforcing Steel) | C21: 36 | D21: ='1046 6" CHB'!E6 -> SQ.M. | E21: Total area of wall using 6" CHB | F21: ='1046 6" CHB'!T21 -> 4528.3 | G21: ='1046 6" CHB'!T30 -> 2400 | H21: ='1046 6" CHB'!T46 -> 33660 | I21: ='1046 6" CHB'!T48 -> 2029.415 | J21: ='1046 6" CHB'!T49 -> 4058.83 | K21: ='1046 6" CHB'!T50 -> 0 | L21: =SUM(F21:K21) -> 46676.545 | M21: =L21/C21 -> 1296.5707
A22: ='1027-Plaster'!E5 -> 1027(1) | B22: ='1027-Plaster'!G5 -> CEMENT PLASTER FINISH WITH 19MM THICK & 1:3 MORTAR MIXTURE | C22: 420 | D22: ='1027-Plaster'!G8 -> SQ.M. | E22: Total area of concrete surface to be plastered | F22: ='1027-Plaster'!T20 -> 26526.32 | G22: ='1027-Plaster'!T29 -> 2652.63 | H22: ='1027-Plaster'!T45 -> 57141 | I22: ='1027-Plaster'!T47 -> 4315.9975 | J22: ='1027-Plaster'!T48 -> 8631.995 | K22: ='1027-Plaster'!T49 -> 0 | L22: =SUM(F22:K22) -> 99267.942 | M22: =L22/C22 -> 236.35224
A23: ='1047(2)b Struc Steel Truss'!E5 -> 1047(2)b | B23: ='1047(2)b Struc Steel Truss'!G5 -> STRUCTURAL STEEL ROOF TRUSS | C23: 0 | D23: ='1047(2)b Struc Steel Truss'!G8 -> KGS. | E23: Determine the steel materials by direct counting on plan, then convert it to weight in kilograms | F23: ='1047(2)b Struc Steel Truss'!T27 -> 0 | G23: ='1047(2)b Struc Steel Truss'!T36 -> 0 | H23: ='1047(2)b Struc Steel Truss'!T52 -> 0 | I23: ='1047(2)b Struc Steel Truss'!T54 -> 0 | J23: ='1047(2)b Struc Steel Truss'!T55 -> 0 | K23: ='1047(2)b Struc Steel Truss'!T56 -> 0 | L23: =SUM(F23:K23) -> 0 | M23: =L23/C23 -> #DIV/0!
A24: ='1047(2)C Struc Steel Purlins'!E5 -> 1047(2)c | B24: ='1047(2)C Struc Steel Purlins'!G5 -> STRUCTURAL STEEL PURLINS | C24: 200 | D24: ='1047(2)C Struc Steel Purlins'!G8 -> KGS. | E24: Determine the number of C-Purlins by direct counting on plan, then convert it to weight in kilograms | F24: ='1047(2)C Struc Steel Purlins'!T21 -> 995.02 | G24: ='1047(2)C Struc Steel Purlins'!T30 -> 895.52 | H24: ='1047(2)C Struc Steel Purlins'!T44 -> 16107 | I24: ='1047(2)C Struc Steel Purlins'!T46 -> 899.877 | J24: ='1047(2)C Struc Steel Purlins'!T47 -> 1799.754 | K24: ='1047(2)C Struc Steel Purlins'!T48 -> 0 | L24: =SUM(F24:K24) -> 20697.171 | M24: =L24/C24 -> 103.48586
A25: ='1013(1) Corr Metal Roofing'!E5 -> 1013(1) | B25: ='1013(1) Corr Metal Roofing'!G5 -> CORRUGATED METAL ROOFING | C25: 0 | D25: ='1013(1) Corr Metal Roofing'!E6 -> SQ.M. | E25: Determine the roof area to be covered by corrugated roof sheet | F25: ='1013(1) Corr Metal Roofing'!T22 -> 0 | G25: ='1013(1) Corr Metal Roofing'!T31 -> 0 | H25: ='1013(1) Corr Metal Roofing'!T47 -> 0 | I25: ='1013(1) Corr Metal Roofing'!T47 -> 0 | J25: ='1013(1) Corr Metal Roofing'!T50 -> 0 | K25: ='1013(1) Corr Metal Roofing'!T51 -> 0 | L25: =SUM(F25:K25) -> 0 | M25: =L25/C25 -> #DIV/0!
A26: ='1013(2) Roof ridge flash valley'!E5 -> 1013(2) | B26: ='1013(2) Roof ridge flash valley'!G5 -> FABRICATED METAL ROOFING ACCESSORY (RIDGE/HIP ROLLS/FLASHING/COUNTER FLASHING/ VALLEY ROLL) | C26: 38 | D26: ='1013(2) Roof ridge flash valley'!E6 -> M. | E26: Determine the total length of Flashing, Ridge Roll and Valley Roll | F26: ='1013(2) Roof ridge flash valley'!T22 -> 855 | G26: ='1013(2) Roof ridge flash valley'!T31 -> 85.5 | H26: ='1013(2) Roof ridge flash valley'!T47 -> 8167.21 | I26: ='1013(2) Roof ridge flash valley'!T49 -> 455.3855 | J26: ='1013(2) Roof ridge flash valley'!T50 -> 910.771 | K26: ='1013(2) Roof ridge flash valley'!T51 -> 0 | L26: =SUM(F26:K26) -> 10473.867 | M26: =L26/C26 -> 275.62807
A27: ='1013(2) Metal Roof Acc (Gutter'!E5 -> 1013(2) | B27: ='1013(2) Metal Roof Acc (Gutter'!G5 -> FABRICATED METAL ROOFING ACCESSORY (GUTTER) | C27: 13 | D27: ='1013(2) Metal Roof Acc (Gutter'!G8 -> M. | E27: Determine the total length of Gutter | F27: ='1013(2) Metal Roof Acc (Gutter'!T22 -> 247.88 | G27: ='1013(2) Metal Roof Acc (Gutter'!T31 -> 24.79 | H27: ='1013(2) Metal Roof Acc (Gutter'!T48 -> 2941.34 | I27: ='1013(2) Metal Roof Acc (Gutter'!T50 -> 160.7005 | J27: ='1013(2) Metal Roof Acc (Gutter'!T51 -> 321.401 | K27: ='1013(2) Metal Roof Acc (Gutter'!T52 -> 0 | L27: =SUM(F27:K27) -> 3696.1115 | M27: =L27/C27 -> 284.31627
A28: ='1014 Prepainted Met Sheets-Roof'!E5 -> 1014 | B28: ='1014 Prepainted Met Sheets-Roof'!G5 -> PREPAINTED METAL SHEETS (CORRUGATE, SHORT SPAN/LONG SPAN) | C28: 0 | D28: ='1014 Prepainted Met Sheets-Roof'!E6 -> SQ.M. | E28: Determine the roof area to be covered by prepainted corrugated roof sheet | F28: ='1014 Prepainted Met Sheets-Roof'!T22 -> 0 | G28: ='1014 Prepainted Met Sheets-Roof'!T31 -> 0 | H28: ='1014 Prepainted Met Sheets-Roof'!T47 -> 0 | I28: ='1014 Prepainted Met Sheets-Roof'!T49 -> 0 | J28: ='1014 Prepainted Met Sheets-Roof'!T50 -> 0 | K28: ='1014 Prepainted Met Sheets-Roof'!T51 -> 0 | L28: =SUM(F28:K28) -> 0 | M28: =L28/C28 -> #DIV/0!
A29: ='1014 Prepainted Met Sheets RIB'!E5 -> 1014 | B29: ='1014 Prepainted Met Sheets RIB'!G5 -> PREPAINTED METAL SHEETS (RIB TYPE 0.4-0.5MM THICK) | C29: 140 | D29: ='1014 Prepainted Met Sheets RIB'!E6 -> SQ.M. | E29: Determine the roof area to be covered by prepainted rib-type roof sheet | F29: ='1014 Prepainted Met Sheets RIB'!T22 -> 13903.94 | G29: ='1014 Prepainted Met Sheets RIB'!T31 -> 1390.39 | H29: ='1014 Prepainted Met Sheets RIB'!T47 -> 53354 | I29: ='1014 Prepainted Met Sheets RIB'!T49 -> 3432.4165 | J29: ='1014 Prepainted Met Sheets RIB'!T50 -> 6864.833 | K29: ='1014 Prepainted Met Sheets RIB'!T51 -> 0 | L29: =SUM(F29:K29) -> 78945.58 | M29: =L29/C29 -> 563.897
A30: ='1016-Waterproof Cement'!E5 -> 1016(1)a | B30: ='1016-Waterproof Cement'!G5 -> WATERPROOFING CEMENT BASE | C30: 66 | D30: ='1016-Waterproof Cement'!E6 -> SQ.M. | E30: Determine the area for waterproofing | F30: ='1016-Waterproof Cement'!T20 -> 7920 | G30: ='1016-Waterproof Cement'!T29 -> 792 | H30: ='1016-Waterproof Cement'!T46 -> 3499.47 | I30: ='1016-Waterproof Cement'!T48 -> 610.5735 | J30: ='1016-Waterproof Cement'!T49 -> 1221.147 | K30: ='1016-Waterproof Cement'!T50 -> 0 | L30: =SUM(F30:K30) -> 14043.191 | M30: =L30/C30 -> 212.77561
A31: ='1018- Tiles'!E5 -> 1018 | B31: ='1018- Tiles'!G5 -> UNGLAZED TILES/ GRANITE TILES/ SYNTHETIC GRANITE TILES | C31: 80 | D31: ='1018- Tiles'!G8 -> SQ.M. | E31: Determine the area for tiles | F31: ='1018- Tiles'!T20 -> 29743.59 | G31: ='1018- Tiles'!T29 -> 2974.359 | H31: ='1018- Tiles'!T46 -> 70502 | I31: ='1018- Tiles'!T48 -> 5160.9974 | J31: ='1018- Tiles'!T49 -> 10321.995 | K31: ='1018- Tiles'!T50 -> 0 | L31: =SUM(F31:K31) -> 118702.94 | M31: =L31/C31 -> 1483.7868
A32: ='1003(1) Ceiling'!E5 -> 1003(1) | B32: ='1003(1) Ceiling'!G5 -> FIBER CEMENT BOARD/MARINE PLYWOOD/ORDINARY PLYWOOD ON METAL FRAME CEILING | C32: 130 | D32: ='1003(1) Ceiling'!G8 -> SQ.M. | E32: Determine the area for Ceiling | F32: ='1003(1) Ceiling'!T20 -> 28761.06 | G32: ='1003(1) Ceiling'!T29 -> 2876.106 | H32: ='1003(1) Ceiling'!T46 -> 125787.57 | I32: ='1003(1) Ceiling'!T48 -> 7871.2368 | J32: ='1003(1) Ceiling'!T49 -> 15742.474 | K32: ='1003(1) Ceiling'!T50 -> 0 | L32: =SUM(F32:K32) -> 181038.45 | M32: =L32/C32 -> 1392.6034
A33: ='1010(2) Hollow Flush Door'!E5 -> 1010(2)a | B33: ='1010(2) Hollow Flush Door'!G5 -> HOLLOW CORE FLUSH DOOR | C33: 5.04 | D33: ='1010(2) Hollow Flush Door'!G8 -> SQ.M. | E33: Determine and input the total area of flush type door | F33: ='1010(2) Hollow Flush Door'!T20 -> 3543.75 | G33: ='1010(2) Hollow Flush Door'!T29 -> 354.38 | H33: ='1010(2) Hollow Flush Door'!T46 -> 11550 | I33: ='1010(2) Hollow Flush Door'!T48 -> 772.4065 | J33: ='1010(2) Hollow Flush Door'!T49 -> 1544.813 | K33: ='1010(2) Hollow Flush Door'!T50 -> 0 | L33: =SUM(F33:K33) -> 17765.35 | M33: =L33/C33 -> 3524.8709
A34: ='1010(2) Panel Door'!E5 -> 1010(2) | B34: ='1010(2) Panel Door'!G5 -> WOODEN PANEL DOOR WITH HEAVY DUTY DOOR KNOB | C34: 2.1 | D34: ='1010(2) Panel Door'!G8 -> SQ.M. | E34: Determine the total area of Wooden Panel Door | F34: ='1010(2) Panel Door'!T20 -> 1604.17 | G34: ='1010(2) Panel Door'!T29 -> 160.42 | H34: ='1010(2) Panel Door'!T46 -> 6600 | I34: ='1010(2) Panel Door'!T48 -> 418.2295 | J34: ='1010(2) Panel Door'!T49 -> 836.459 | K34: ='1010(2) Panel Door'!T50 -> 0 | L34: =SUM(F34:K34) -> 9619.2785 | M34: =L34/C34 -> 4580.6088
A35: ='1043(1) PVC Door'!E5 -> 1043(1) | B35: ='1043(1) PVC Door'!G5 -> PVC DOORS AND FRAMES W/ HEAVY DUTY DOOR KNOB | C35: 1.26 | D35: ='1043(1) PVC Door'!G8 -> SQ.M. | E35: Determine the total area of PVC Door | F35: ='1043(1) PVC Door'!T20 -> 900 | G35: ='1043(1) PVC Door'!T29 -> 90 | H35: ='1043(1) PVC Door'!T45 -> 2625 | I35: ='1043(1) PVC Door'!T47 -> 180.75 | J35: ='1043(1) PVC Door'!T48 -> 361.5 | K35: ='1043(1) PVC Door'!T49 -> 0 | L35: =SUM(F35:K35) -> 4157.25 | M35: =L35/C35 -> 3299.4048
A36: ='1032-Paint Concrete'!E5 -> 1032(1)a | B36: ='1032-Paint Concrete'!G5 -> PAINTING WORKS (MASONRY PAINTING) | C36: 540 | D36: ='1032-Paint Concrete'!G8 -> SQ.M. | E36: Determine the area of concrete surface for painting | F36: ='1032-Paint Concrete'!T20 -> 77142.86 | G36: ='1032-Paint Concrete'!T29 -> 0 | H36: ='1032-Paint Concrete'!T46 -> 78160.1 | I36: ='1032-Paint Concrete'!T48 -> 7765.148 | J36: ='1032-Paint Concrete'!T49 -> 15530.296 | K36: ='1032-Paint Concrete'!T50 -> 0 | L36: =SUM(F36:K36) -> 178598.4 | M36: =L36/C36 -> 330.73779
A37: ='1032-Paint Metal'!E5 -> 1032(1)c | B37: ='1032-Paint Metal'!G5 -> PAINTING WORKS (METAL PAINTING) | C37: 45 | D37: ='1032-Paint Metal'!G8 -> SQ.M. | E37: Determine the area of metal surface for painting | F37: ='1032-Paint Metal'!T20 -> 6750 | G37: ='1032-Paint Metal'!T29 -> 0 | H37: ='1032-Paint Metal'!T46 -> 22411.13 | I37: ='1032-Paint Metal'!T48 -> 1458.0565 | J37: ='1032-Paint Metal'!T49 -> 2916.113 | K37: ='1032-Paint Metal'!T50 -> 0 | L37: =SUM(F37:K37) -> 33535.3 | M37: =L37/C37 -> 745.22888
A38: ='Sliding Glass'!E5 -> SPL - ? | B38: ='Sliding Glass'!G5 -> SUPPLY AND INSTALLATION OF ANALOK TYPE SLIDING WINDOW | C38: 11.34 | D38: ='Sliding Glass'!G8 -> SQ.M. | E38: Determine the total area of sliding window | F38: ='Sliding Glass'!T20 -> 0 | G38: ='Sliding Glass'!T29 -> 0 | H38: ='Sliding Glass'!T45 -> 45360 | I38: ='Sliding Glass'!T47 -> 2268 | J38: ='Sliding Glass'!T48 -> 4536 | K38: ='Sliding Glass'!T49 -> 0 | L38: =SUM(F38:K38) -> 52164 | M38: =L38/C38 -> 4600
A39: ='Other item-Civil Works'!E5 -> SPL - ? | B39: ='Other item-Civil Works'!G5 -> (INPUT ITEM DESCRIPTION) | C39: 1 | D39: ='Other item-Civil Works'!E6 -> L.S. | E39: If you need additional item that is not found in this spreadsheet, you may use this and go to "Other Item" Tab to create item of work | F39: ='Other item-Civil Works'!T20 -> 0 | G39: ='Other item-Civil Works'!T29 -> 0 | H39: ='Other item-Civil Works'!T45 -> 0 | I39: ='Other item-Civil Works'!T47 -> 0 | J39: ='Other item-Civil Works'!T48 -> 0 | K39: ='Other item-Civil Works'!T49 -> 0 | L39: =SUM(F39:K39) -> 0 | M39: =L39/C39 -> 0
A40: PLUMBING WORKS
A41: ='1001(1)a 2" -4" San PVC Pipe'!E5 -> 1001(1)a | B41: ='1001(1)a 2" -4" San PVC Pipe'!G5 -> 50MM DIA - 100MM DIA SANITARY PVC PIPE, SERIES 600/1000 | C41: 12 | D41: ='1001(1)a 2" -4" San PVC Pipe'!E6 -> M. | E41: Determine the number and length of Sanitary Pipes by Sizes and indicate in in the estimate DUPA tab | F41: ='1001(1)a 2" -4" San PVC Pipe'!T20 -> 1100 | G41: ='1001(1)a 2" -4" San PVC Pipe'!T29 -> 110 | H41: ='1001(1)a 2" -4" San PVC Pipe'!T45 -> 1980 | I41: ='1001(1)a 2" -4" San PVC Pipe'!T47 -> 159.5 | J41: ='1001(1)a 2" -4" San PVC Pipe'!T48 -> 319 | K41: ='1001(1)a 2" -4" San PVC Pipe'!T49 -> 0 | L41: =SUM(F41:K41) -> 3668.5 | M41: =L41/C41 -> 305.70833
A42: ='1002(6) Waterline Pipes fitting'!E5 -> 1002(6) | B42: ='1002(6) Waterline Pipes fitting'!G5 -> WATERLINE PIPES & FITTINGS | C42: 1 | D42: ='1002(6) Waterline Pipes fitting'!G8 -> L.S. | E42: It is suggested that the unit for this item is always 1.00 Lump Sum. The estimator shall go to its DUPA tab and indicate the necessary materials, tools and manpower | F42: ='1002(6) Waterline Pipes fitting'!T20 -> 2200 | G42: ='1002(6) Waterline Pipes fitting'!T29 -> 220 | H42: ='1002(6) Waterline Pipes fitting'!T45 -> 2780 | I42: ='1002(6) Waterline Pipes fitting'!T47 -> 260 | J42: ='1002(6) Waterline Pipes fitting'!T48 -> 520 | K42: ='1002(6) Waterline Pipes fitting'!T49 -> 0 | L42: =SUM(F42:K42) -> 5980 | M42: =L42/C42 -> 5980
A43: ='1002(5) W Closet w acc'!E5 -> 1002(5) | B43: ='1002(5) W Closet w acc'!G5 -> WATER CLOSET/ URINAL W/ COMPLETE ACCESSORIES | C43: 1 | D43: ='1002(5) W Closet w acc'!G8 -> SET | E43: Input the total quantity of the water closet plus urinal. Also, go to the DUPA and input in the necessary materials. | F43: ='1002(5) W Closet w acc'!T20 -> 450 | G43: ='1002(5) W Closet w acc'!T29 -> 45 | H43: ='1002(5) W Closet w acc'!T45 -> 6600 | I43: ='1002(5) W Closet w acc'!T47 -> 354.75 | J43: ='1002(5) W Closet w acc'!T48 -> 709.5 | K43: ='1002(5) W Closet w acc'!T49 -> 0 | L43: =SUM(F43:K43) -> 8159.25 | M43: =L43/C43 -> 8159.25
...

Sheet BOE
B6: PROJECT TITLE: | F6: ='INPUT DATA'!C4 -> PROPOSED ONE STOREY TWO BED ROOM RESIDENTIAL BUILDING
B7: Project Location: | F7: ='INPUT DATA'!C5 -> ANGELES, PAMPANGA
B9: BREAKDOWN OF EXPENDITURES | N9: % OF TOTAL | Q9: AMOUNT | U9: PERCENTAGE
C10: DIRECT COST:
D11: Materials | N11: =Q11/$Q$20 -> 0.61608141 | Q11: ='INPUT DATA'!H59 -> 1013330.9 | U11: =Q11/$Q$14 -> 0.70849362 | V11: MATERIALS
D12: Labor/Manpower | N12: =Q12/$Q$20 -> 0.19864838 | Q12: ='INPUT DATA'!F59 -> 326736.9 | U12: =Q12/$Q$14 -> 0.22844563 | V12: LABOR
D13: Equipment/Tools Expenses | N13: =Q13/$Q$20 -> 0.054835431 | Q13: ='INPUT DATA'!G59 -> 90193.33 | U13: =Q13/$Q$14 -> 0.063060745 | V13: EQUIPMENT
B14: S U B - T O T A L (DIRECT COST) | N14: =SUM(N11:P13) -> 0.86956522 | Q14: =SUM(Q11:S13) -> 1430261.1 | AG14: =AI14 -> 34376992 | AH14: xxx p-1 | AI14: 34376992
C15: INDIRECT COST:
D16: Overhead, Contingency & Misc. | N16: =Q16/$Q$20 -> 0.043478261 | Q16: ='INPUT DATA'!I59 -> 71513.054
D17: Contractor's Profit | N17: =Q17/$Q$20 -> 0.086956522 | Q17: ='INPUT DATA'!J59 -> 143026.11
D18: Value Added Tax | N18: =Q18/$Q$20 -> 0 | Q18: ='INPUT DATA'!K59 -> 0
B19: S U B - T O T A L (INDIRECT COST)
B20: TOTAL PROJECT COST | N20: =SUM(N16:P18)+N14 -> 1 | Q20: =SUM(Q16:S18)+Q14 -> 1644800.3 | AG20: 27089626
C23: Prepared by:
E26: Licensed Engineer/Registered Master Plumber/Master Electrician
C38: NOTE:
C40: 1. FOR QUERIES REGARDING THIS, YOU MAY COMMUNICATE WITH THE AUTHOR AT em.bautistajr@yahoo.com OR ON HIS YOUTUBE CHANNEL
C41: 2. THIS ESTIMATE FORMAT IN DETAILED UNIT PRICE ANALYSIS IS A PERSONAL PROPERTY OF ENGR. EDITO M. BAUTISTA, JR. CE, EnP, RMP, RME
C42: 3. IF YOU USE THIS IN A STUDY OR RESEARCH, PLEASE ACKNOWLEDGE THE AUTHOR.
C43: 4. DISCLAIMER: THE AUTHOR OF THIS SPREADSHEET IS DENYING ANY AND ALL LIABILITY FOR ANY DAMAGES ARISING OUT FROM USING THIS SPREADSHEET.
C44: 5. THE BASIS FOR THE DERIVATION OF THIS SPREADSHEET IS THE DPWH DEPARTMENT ORDER NO. 137 SERIES OF 2017, COST ESTIMATION MANUAL FOR LOW RISE BUILDING (UPTO 5 STOREY BUILDING)
C45: 6. THE USER MAY CHANGE THE MANPOWER RATES, EQUIPMENT RATES, MATERIALS PRICES AND THE MARK-UPS (OCM, PROFIT & TAX)

Sheet ABC
A2: =BOE!B2 -> 0
B6: =BOE!B6 -> PROJECT TITLE: | D6: ='INPUT DATA'!C4 -> PROPOSED ONE STOREY TWO BED ROOM RESIDENTIAL BUILDING
B7: =BOE!B7 -> Project Location: | D7: ='INPUT DATA'!C5 -> ANGELES, PAMPANGA
B10: DESCRIPTION | D10: QUANTITY | E10: UNIT | G10: MARK-UPS | I10: TOTAL MARK-UP | K10: VAT | M10: TOTAL COST
A11: ITEM | F11: ESTIMATED | G11: IN PERCENT | L11: TOTAL | O11: UNIT
A12: NO. | F12: DIRECT COST | G12: OCM | H12: PROFIT | I12: % | J12: VALUE | L12: INDIRECT COST | O12: COST
A14: -1 | B14: -2 | D14: -3 | E14: -4 | F14: -5 | G14: -6 | H14: -7 | I14: -8 | J14: -9 | K14: -10 | L14: -11 | M14: -12 | O14: -13
J15: (5)X(8) | K15: (5)+(9)) | L15: (9)+(10) | M15: (5)+(11) | O15: (12)/(3)
A16: ='INPUT DATA'!A9 -> ARCHITECTURAL / CIVIL WORKS
A17: ='INPUT DATA'!A10 -> 800(1) | B17: ='INPUT DATA'!B10 -> CLEARING AND GRUBBING | D17: ='INPUT DATA'!C10 -> 200 | E17: ='INPUT DATA'!D10 -> SQ.M. | F17: ='INPUT DATA'!F10+'INPUT DATA'!G10+'INPUT DATA'!H10 -> 22155.2 | G17: ='INPUT DATA'!$C$62 -> 0.05 | H17: ='INPUT DATA'!$C$63 -> 0.1 | I17: =H17+G17 -> 0.15 | J17: =I17*F17 -> 3323.28 | K17: ='INPUT DATA'!$C$64*(ABC!J17+ABC!F17) -> 0 | L17: =J17+K17 -> 3323.28 | M17: =L17+F17 -> 25478.48 | O17: =M17/D17 -> 127.3924 | P17: =M17-'INPUT DATA'!L10 -> 0
A18: ='INPUT DATA'!A11 -> 800(3)a | B18: ='INPUT DATA'!B11 -> INDIVIDUAL REMOVAL OF TREES (UPTO 300MM DIAMETER) | D18: ='INPUT DATA'!C11 -> 2 | E18: ='INPUT DATA'!D11 -> EACH | F18: ='INPUT DATA'!F11+'INPUT DATA'!G11+'INPUT DATA'!H11 -> 4458.94 | G18: ='INPUT DATA'!$C$62 -> 0.05 | H18: ='INPUT DATA'!$C$63 -> 0.1 | I18: =H18+G18 -> 0.15 | J18: =I18*F18 -> 668.841 | K18: ='INPUT DATA'!$C$64*(ABC!J18+ABC!F18) -> 0 | L18: =J18+K18 -> 668.841 | M18: =L18+F18 -> 5127.781 | O18: =M18/D18 -> 2563.8905 | P18: =M18-'INPUT DATA'!L11 -> 0
A19: ='INPUT DATA'!A12 -> 803(1)a | B19: ='INPUT DATA'!B12 -> STRUCTURE EXCAVATION (COMMON SOIL) | D19: ='INPUT DATA'!C12 -> 23 | E19: ='INPUT DATA'!D12 -> CU.M. | F19: ='INPUT DATA'!F12+'INPUT DATA'!G12+'INPUT DATA'!H12 -> 5193.4 | G19: ='INPUT DATA'!$C$62 -> 0.05 | H19: ='INPUT DATA'!$C$63 -> 0.1 | I19: =H19+G19 -> 0.15 | J19: =I19*F19 -> 779.01 | K19: ='INPUT DATA'!$C$64*(ABC!J19+ABC!F19) -> 0 | L19: =J19+K19 -> 779.01 | M19: =L19+F19 -> 5972.41 | O19: =M19/D19 -> 259.67 | P19: =M19-'INPUT DATA'!L12 -> 0
A20: ='INPUT DATA'!A13 -> 803(1)a | B20: ='INPUT DATA'!B13 -> STRUCTURE EXCAVATION (SOFT ROCK) | D20: ='INPUT DATA'!C13 -> 0 | E20: ='INPUT DATA'!D13 -> CU.M. | F20: ='INPUT DATA'!F13+'INPUT DATA'!G13+'INPUT DATA'!H13 -> 0 | G20: ='INPUT DATA'!$C$62 -> 0.05 | H20: ='INPUT DATA'!$C$63 -> 0.1 | I20: =H20+G20 -> 0.15 | J20: =I20*F20 -> 0 | K20: ='INPUT DATA'!$C$64*(ABC!J20+ABC!F20) -> 0 | L20: =J20+K20 -> 0 | M20: =L20+F20 -> 0 | O20: =M20/D20 -> #DIV/0! | P20: =M20-'INPUT DATA'!L13 -> 0
A21: ='INPUT DATA'!A14 -> 804(4) | B21: ='INPUT DATA'!B14 -> GRAVEL BEDDING | D21: ='INPUT DATA'!C14 -> 3 | E21: ='INPUT DATA'!D14 -> CU.M. | F21: ='INPUT DATA'!F14+'INPUT DATA'!G14+'INPUT DATA'!H14 -> 5502.5 | G21: ='INPUT DATA'!$C$62 -> 0.05 | H21: ='INPUT DATA'!$C$63 -> 0.1 | I21: =H21+G21 -> 0.15 | J21: =I21*F21 -> 825.375 | K21: ='INPUT DATA'!$C$64*(ABC!J21+ABC!F21) -> 0 | L21: =J21+K21 -> 825.375 | M21: =L21+F21 -> 6327.875 | O21: =M21/D21 -> 2109.2917 | P21: =M21-'INPUT DATA'!L14 -> 0
A22: ='INPUT DATA'!A15 -> 902(1) | B22: ='INPUT DATA'!B15 -> REINFORCING STEEL OF REINFORCED CONCRETE STRUCTURES FOR ONE-STOREY, GRADE 40/60 | D22: ='INPUT DATA'!C15 -> 1200 | E22: ='INPUT DATA'!D15 -> KGS. | F22: ='INPUT DATA'!F15+'INPUT DATA'!G15+'INPUT DATA'!H15 -> 107711.97 | G22: ='INPUT DATA'!$C$62 -> 0.05 | H22: ='INPUT DATA'!$C$63 -> 0.1 | I22: =H22+G22 -> 0.15 | J22: =I22*F22 -> 16156.796 | K22: ='INPUT DATA'!$C$64*(ABC!J22+ABC!F22) -> 0 | L22: =J22+K22 -> 16156.796 | M22: =L22+F22 -> 123868.77 | O22: =M22/D22 -> 103.22397 | P22: =M22-'INPUT DATA'!L15 -> 0
A23: ='INPUT DATA'!A16 -> 902(1) | B23: ='INPUT DATA'!B16 -> REINFORCING STEEL OF REINFORCED CONCRETE STRUCTURES FOR TWO UPTO FIVE STOREY | D23: ='INPUT DATA'!C16 -> 50 | E23: ='INPUT DATA'!D16 -> KGS. | F23: ='INPUT DATA'!F16+'INPUT DATA'!G16+'INPUT DATA'!H16 -> 4513.1 | G23: ='INPUT DATA'!$C$62 -> 0.05 | H23: ='INPUT DATA'!$C$63 -> 0.1 | I23: =H23+G23 -> 0.15 | J23: =I23*F23 -> 676.965 | K23: ='INPUT DATA'!$C$64*(ABC!J23+ABC!F23) -> 0 | L23: =J23+K23 -> 676.965 | M23: =L23+F23 -> 5190.065 | O23: =M23/D23 -> 103.8013 | P23: =M23-'INPUT DATA'!L16 -> 0
A24: ='INPUT DATA'!A17 -> 900(1)c2 | B24: ='INPUT DATA'!B17 -> STRUCTURAL CONCRETE FOR FOOTING AND SLAB ON FILL (CLASS A, 28 DAYS) | D24: ='INPUT DATA'!C17 -> 12.4 | E24: ='INPUT DATA'!D17 -> CU.M. | F24: ='INPUT DATA'!F17+'INPUT DATA'!G17+'INPUT DATA'!H17 -> 76244.56 | G24: ='INPUT DATA'!$C$62 -> 0.05 | H24: ='INPUT DATA'!$C$63 -> 0.1 | I24: =H24+G24 -> 0.15 | J24: =I24*F24 -> 11436.684 | K24: ='INPUT DATA'!$C$64*(ABC!J24+ABC!F24) -> 0 | L24: =J24+K24 -> 11436.684 | M24: =L24+F24 -> 87681.244 | O24: =M24/D24 -> 7071.0681 | P24: =M24-'INPUT DATA'!L17 -> 0
A25: ='INPUT DATA'!A18 -> 900(1) | B25: ='INPUT DATA'!B18 -> STRUCTURAL CONCRETE FOR FOOTING TIE BEAM, COLUMN, SUSPENDED SLAB, GIRDER/BEAM (CLASS A, 28 DAYS) | D25: ='INPUT DATA'!C18 -> 23.6 | E25: ='INPUT DATA'!D18 -> CU.M. | F25: ='INPUT DATA'!F18+'INPUT DATA'!G18+'INPUT DATA'!H18 -> 150481.03 | G25: ='INPUT DATA'!$C$62 -> 0.05 | H25: ='INPUT DATA'!$C$63 -> 0.1 | I25: =H25+G25 -> 0.15 | J25: =I25*F25 -> 22572.155 | K25: ='INPUT DATA'!$C$64*(ABC!J25+ABC!F25) -> 0 | L25: =J25+K25 -> 22572.155 | M25: =L25+F25 -> 173053.18 | O25: =M25/D25 -> 7332.7621 | P25: =M25-'INPUT DATA'!L18 -> 0
A26: ='INPUT DATA'!A19 -> 903(2) | B26: ='INPUT DATA'!B19 -> FORMWORKS AND FALSEWORKS (FOR ONE-STOREY BUILDING) | D26: ='INPUT DATA'!C19 -> 49 | E26: ='INPUT DATA'!D19 -> SQ.M. | F26: ='INPUT DATA'!F19+'INPUT DATA'!G19+'INPUT DATA'!H19 -> 39861.41 | G26: ='INPUT DATA'!$C$62 -> 0.05 | H26: ='INPUT DATA'!$C$63 -> 0.1 | I26: =H26+G26 -> 0.15 | J26: =I26*F26 -> 5979.2115 | K26: ='INPUT DATA'!$C$64*(ABC!J26+ABC!F26) -> 0 | L26: =J26+K26 -> 5979.2115 | M26: =L26+F26 -> 45840.621 | O26: =M26/D26 -> 935.52289 | P26: =M26-'INPUT DATA'!L19 -> 0
A27: ='INPUT DATA'!A20 -> 1046 | B27: ='INPUT DATA'!B20 -> 100MM CHB NON LOAD BEARING/LOAD BEARING (INCLUDING REINFORCING STEEL) | D27: ='INPUT DATA'!C20 -> 189 | E27: ='INPUT DATA'!D20 -> SQ.M. | F27: ='INPUT DATA'!F20+'INPUT DATA'!G20+'INPUT DATA'!H20 -> 150751.13 | G27: ='INPUT DATA'!$C$62 -> 0.05 | H27: ='INPUT DATA'!$C$63 -> 0.1 | I27: =H27+G27 -> 0.15 | J27: =I27*F27 -> 22612.67 | K27: ='INPUT DATA'!$C$64*(ABC!J27+ABC!F27) -> 0 | L27: =J27+K27 -> 22612.67 | M27: =L27+F27 -> 173363.8 | O27: =M27/D27 -> 917.26878 | P27: =M27-'INPUT DATA'!L20 -> 0
A28: ='INPUT DATA'!A21 -> 1046 | B28: ='INPUT DATA'!B21 -> 150mm. CHB NON LOAD BEARING (including Reinforcing Steel) | D28: ='INPUT DATA'!C21 -> 36 | E28: ='INPUT DATA'!D21 -> SQ.M. | F28: ='INPUT DATA'!F21+'INPUT DATA'!G21+'INPUT DATA'!H21 -> 40588.3 | G28: ='INPUT DATA'!$C$62 -> 0.05 | H28: ='INPUT DATA'!$C$63 -> 0.1 | I28: =H28+G28 -> 0.15 | J28: =I28*F28 -> 6088.245 | K28: ='INPUT DATA'!$C$64*(ABC!J28+ABC!F28) -> 0 | L28: =J28+K28 -> 6088.245 | M28: =L28+F28 -> 46676.545 | O28: =M28/D28 -> 1296.5707 | P28: =M28-'INPUT DATA'!L21 -> 0
... A46: ='INPUT DATA'!A39 -> SPL - ? | B46: ='INPUT DATA'!B39 -> (INPUT ITEM DESCRIPTION) | D46: ='INPUT DATA'!C39 -> 1 | E46: ='INPUT DATA'!D39 -> L.S. | F46: ='INPUT DATA'!F39+'INPUT DATA'!G39+'INPUT DATA'!H39 -> 0 | G46: ='INPUT DATA'!$C$62 -> 0.05 | H46: ='INPUT DATA'!$C$63 -> 0.1 | I46: =H46+G46 -> 0.15 | J46: =I46*F46 -> 0 | K46: ='INPUT DATA'!$C$64*(ABC!J46+ABC!F46) -> 0 | L46: =J46+K46 -> 0 | M46: =L46+F46 -> 0 | O46: =M46/D46 -> 0 | P46: =M46-'INPUT DATA'!L39 -> 0
A47: ='INPUT DATA'!A40 -> PLUMBING WORKS | P47: =M47-'INPUT DATA'!L40 -> 0
A48: ='INPUT DATA'!A41 -> 1001(1)a | B48: ='INPUT DATA'!B41 -> 50MM DIA - 100MM DIA SANITARY PVC PIPE, SERIES 600/1000 | D48: ='INPUT DATA'!C41 -> 12 | E48: ='INPUT DATA'!D41 -> M. | F48: ='INPUT DATA'!F41+'INPUT DATA'!G41+'INPUT DATA'!H41 -> 3190 | G48: ='INPUT DATA'!$C$62 -> 0.05 | H48: ='INPUT DATA'!$C$63 -> 0.1 | I48: =H48+G48 -> 0.15 | J48: =I48*F48 -> 478.5 | K48: ='INPUT DATA'!$C$64*(ABC!J48+ABC!F48) -> 0 | L48: =J48+K48 -> 478.5 | M48: =L48+F48 -> 3668.5 | O48: =M48/D48 -> 305.70833 | P48: =M48-'INPUT DATA'!L41 -> 0
A49: ='INPUT DATA'!A42 -> 1002(6) | B49: ='INPUT DATA'!B42 -> WATERLINE PIPES & FITTINGS | D49: ='INPUT DATA'!C42 -> 1 | E49: ='INPUT DATA'!D42 -> L.S. | F49: ='INPUT DATA'!F42+'INPUT DATA'!G42+'INPUT DATA'!H42 -> 5200 | G49: ='INPUT DATA'!$C$62 -> 0.05 | H49: ='INPUT DATA'!$C$63 -> 0.1 | I49: =H49+G49 -> 0.15 | J49: =I49*F49 -> 780 | K49: ='INPUT DATA'!$C$64*(ABC!J49+ABC!F49) -> 0 | L49: =J49+K49 -> 780 | M49: =L49+F49 -> 5980 | O49: =M49/D49 -> 5980 | P49: =M49-'INPUT DATA'!L42 -> 0
A50: ='INPUT DATA'!A43 -> 1002(5) | B50: ='INPUT DATA'!B43 -> WATER CLOSET/ URINAL W/ COMPLETE ACCESSORIES | D50: ='INPUT DATA'!C43 -> 1 | E50: ='INPUT DATA'!D43 -> SET | F50: ='INPUT DATA'!F43+'INPUT DATA'!G43+'INPUT DATA'!H43 -> 7095 | G50: ='INPUT DATA'!$C$62 -> 0.05 | H50: ='INPUT DATA'!$C$63 -> 0.1 | I50: =H50+G50 -> 0.15 | J50: =I50*F50 -> 1064.25 | K50: ='INPUT DATA'!$C$64*(ABC!J50+ABC!F50) -> 0 | L50: =J50+K50 -> 1064.25 | M50: =L50+F50 -> 8159.25 | O50: =M50/D50 -> 8159.25 | P50: =M50-'INPUT DATA'!L43 -> 0
A51: ='INPUT DATA'!A44 -> 1002(5) | B51: ='INPUT DATA'!B44 -> KITCHEN SINK/ SCRUB/ SLOP SINK W/ COMPLETE ACCESSORIES | D51: ='INPUT DATA'!C44 -> 1 | E51: ='INPUT DATA'!D44 -> SET | F51: ='INPUT DATA'!F44+'INPUT DATA'!G44+'INPUT DATA'!H44 -> 5445 | G51: ='INPUT DATA'!$C$62 -> 0.05 | H51: ='INPUT DATA'!$C$63 -> 0.1 | I51: =H51+G51 -> 0.15 | J51: =I51*F51 -> 816.75 | K51: ='INPUT DATA'!$C$64*(ABC!J51+ABC!F51) -> 0 | L51: =J51+K51 -> 816.75 | M51: =L51+F51 -> 6261.75 | O51: =M51/D51 -> 6261.75 | P51: =M51-'INPUT DATA'!L44 -> 0
A52: ='INPUT DATA'!A45 -> 1002(5) | B52: ='INPUT DATA'!B45 -> WALL HANG/COUNTERTOP/ UNDER COUNTER LAVATORY W/ COMPLETE ACCESSORIES | D52: ='INPUT DATA'!C45 -> 1 | E52: ='INPUT DATA'!D45 -> SET | F52: ='INPUT DATA'!F45+'INPUT DATA'!G45+'INPUT DATA'!H45 -> 4345 | G52: ='INPUT DATA'!$C$62 -> 0.05 | H52: ='INPUT DATA'!$C$63 -> 0.1 | I52: =H52+G52 -> 0.15 | J52: =I52*F52 -> 651.75 | K52: ='INPUT DATA'!$C$64*(ABC!J52+ABC!F52) -> 0 | L52: =J52+K52 -> 651.75 | M52: =L52+F52 -> 4996.75 | O52: =M52/D52 -> 4996.75 | P52: =M52-'INPUT DATA'!L45 -> 0
A53: ='INPUT DATA'!A46 -> 1002(5) | B53: ='INPUT DATA'!B46 -> FLOOR DRAIN PLATES (ANY SIZE) | D53: ='INPUT DATA'!C46 -> 2 | E53: ='INPUT DATA'!D46 -> SET | F53: ='INPUT DATA'!F46+'INPUT DATA'!G46+'INPUT DATA'!H46 -> 968 | G53: ='INPUT DATA'!$C$62 -> 0.05 | H53: ='INPUT DATA'!$C$63 -> 0.1 | I53: =H53+G53 -> 0.15 | J53: =I53*F53 -> 145.2 | K53: ='INPUT DATA'!$C$64*(ABC!J53+ABC!F53) -> 0 | L53: =J53+K53 -> 145.2 | M53: =L53+F53 -> 1113.2 | O53: =M53/D53 -> 556.6 | P53: =M53-'INPUT DATA'!L46 -> 0
A54: ='INPUT DATA'!A47 -> 1002(5) | B54: ='INPUT DATA'!B47 -> SOAP HOLDER /TOILET SOAP/LIQUID SOAP/TISSUE HOLDER | D54: ='INPUT DATA'!C47 -> 1 | E54: ='INPUT DATA'!D47 -> SET | F54: ='INPUT DATA'!F47+'INPUT DATA'!G47+'INPUT DATA'!H47 -> 570.625 | G54: ='INPUT DATA'!$C$62 -> 0.05 | H54: ='INPUT DATA'!$C$63 -> 0.1 | I54: =H54+G54 -> 0.15 | J54: =I54*F54 -> 85.59375 | K54: ='INPUT DATA'!$C$64*(ABC!J54+ABC!F54) -> 0 | L54: =J54+K54 -> 85.59375 | M54: =L54+F54 -> 656.21875 | O54: =M54/D54 -> 656.21875 | P54: =M54-'INPUT DATA'!L47 -> 0
A55: ='INPUT DATA'!A48 -> 1002(5)p | B55: ='INPUT DATA'!B48 -> FACIAL MIRROR | D55: ='INPUT DATA'!C48 -> 0.5 | E55: ='INPUT DATA'!D48 -> SQ.M. | F55: ='INPUT DATA'!F48+'INPUT DATA'!G48+'INPUT DATA'!H48 -> 804.375 | G55: ='INPUT DATA'!$C$62 -> 0.05 | H55: ='INPUT DATA'!$C$63 -> 0.1 | I55: =H55+G55 -> 0.15 | J55: =I55*F55 -> 120.65625 | K55: ='INPUT DATA'!$C$64*(ABC!J55+ABC!F55) -> 0 | L55: =J55+K55 -> 120.65625 | M55: =L55+F55 -> 925.03125 | O55: =M55/D55 -> 1850.0625 | P55: =M55-'INPUT DATA'!L48 -> 0
A56: ='INPUT DATA'!A49 -> SPL- ? | B56: ='INPUT DATA'!B49 -> (INPUT OTHER PLUMBING WORK ITEM THAT IS NOT FOUND IN THIS SPREADSHEET) | D56: ='INPUT DATA'!C49 -> 1 | E56: ='INPUT DATA'!D49 -> L.S. | F56: ='INPUT DATA'!F49+'INPUT DATA'!G49+'INPUT DATA'!H49 -> 0 | G56: ='INPUT DATA'!$C$62 -> 0.05 | H56: ='INPUT DATA'!$C$63 -> 0.1 | I56: =H56+G56 -> 0.15 | J56: =I56*F56 -> 0 | K56: ='INPUT DATA'!$C$64*(ABC!J56+ABC!F56) -> 0 | L56: =J56+K56 -> 0 | M56: =L56+F56 -> 0 | O56: =M56/D56 -> 0 | P56: =M56-'INPUT DATA'!L49 -> 0
A57: ='INPUT DATA'!A50 -> ELECTRICAL WORKS | P57: =M57-'INPUT DATA'!L50 -> 0
A58: ='INPUT DATA'!A51 -> 1002(5) | B58: ='INPUT DATA'!B51 -> 15MM-25MM DIA. FLEXIBLE CONDUIT | D58: ='INPUT DATA'!C51 -> 200 | E58: ='INPUT DATA'!D51 -> M. | F58: ='INPUT DATA'!F51+'INPUT DATA'!G51+'INPUT DATA'!H51 -> 17306.795 | G58: ='INPUT DATA'!$C$62 -> 0.05 | H58: ='INPUT DATA'!$C$63 -> 0.1 | I58: =H58+G58 -> 0.15 | J58: =I58*F58 -> 2596.0193 | K58: ='INPUT DATA'!$C$64*(ABC!J58+ABC!F58) -> 0 | L58: =J58+K58 -> 2596.0193 | M58: =L58+F58 -> 19902.814 | O58: =M58/D58 -> 99.514071 | P58: =M58-'INPUT DATA'!L51 -> 0
A59: ='INPUT DATA'!A52 -> 1100 | B59: ='INPUT DATA'!B52 -> JUNCTION UTILITY/PULL / SQUARE BOX | D59: ='INPUT DATA'!C52 -> 33 | E59: ='INPUT DATA'!D52 -> PC. | F59: ='INPUT DATA'!F52+'INPUT DATA'!G52+'INPUT DATA'!H52 -> 4900.5 | G59: ='INPUT DATA'!$C$62 -> 0.05 | H59: ='INPUT DATA'!$C$63 -> 0.1 | I59: =H59+G59 -> 0.15 | J59: =I59*F59 -> 735.075 | K59: ='INPUT DATA'!$C$64*(ABC!J59+ABC!F59) -> 0 | L59: =J59+K59 -> 735.075 | M59: =L59+F59 -> 5635.575 | O59: =M59/D59 -> 170.775 | P59: =M59-'INPUT DATA'!L52 -> 0
A60: ='INPUT DATA'!A53 -> 1101(2) | B60: ='INPUT DATA'!B53 -> 1.6MM2 - 5.5MM2 ELECTRIC WIRE (TW/THHN/TWHN2) | D60: ='INPUT DATA'!C53 -> 600 | E60: ='INPUT DATA'!D53 -> M. | F60: ='INPUT DATA'!F53+'INPUT DATA'!G53+'INPUT DATA'!H53 -> 25080 | G60: ='INPUT DATA'!$C$62 -> 0.05 | H60: ='INPUT DATA'!$C$63 -> 0.1 | I60: =H60+G60 -> 0.15 | J60: =I60*F60 -> 3762 | K60: ='INPUT DATA'!$C$64*(ABC!J60+ABC!F60) -> 0 | L60: =J60+K60 -> 3762 | M60: =L60+F60 -> 28842 | O60: =M60/D60 -> 48.07 | P60: =M60-'INPUT DATA'!L53 -> 0
A61: ='INPUT DATA'!A54 -> 1101 | B61: ='INPUT DATA'!B54 -> SINGLE CONVINENCE OUTLET/ RECEPTACLE, GROUNDING TYPE/HEAVY DUTY CONVENIENCE OUTLET | D61: ='INPUT DATA'!C54 -> 13 | E61: ='INPUT DATA'!D54 -> SET | F61: ='INPUT DATA'!F54+'INPUT DATA'!G54+'INPUT DATA'!H54 -> 3305.25 | G61: ='INPUT DATA'!$C$62 -> 0.05 | H61: ='INPUT DATA'!$C$63 -> 0.1 | I61: =H61+G61 -> 0.15 | J61: =I61*F61 -> 495.7875 | K61: ='INPUT DATA'!$C$64*(ABC!J61+ABC!F61) -> 0 | L61: =J61+K61 -> 495.7875 | M61: =L61+F61 -> 3801.0375 | O61: =M61/D61 -> 292.3875 | P61: =M61-'INPUT DATA'!L54 -> 0
A62: ='INPUT DATA'!A55 -> 1101 | B62: ='INPUT DATA'!B55 -> DUPLEX CONVINENCE OUTLET/ RECEPTACLE, GROUNDING TYPE/HEAVY DUTY CONVENIENCE OUTLET | D62: ='INPUT DATA'!C55 -> 10 | E62: ='INPUT DATA'!D55 -> SET | F62: ='INPUT DATA'!F55+'INPUT DATA'!G55+'INPUT DATA'!H55 -> 3205 | G62: ='INPUT DATA'!$C$62 -> 0.05 | H62: ='INPUT DATA'!$C$63 -> 0.1 | I62: =H62+G62 -> 0.15 | J62: =I62*F62 -> 480.75 | K62: ='INPUT DATA'!$C$64*(ABC!J62+ABC!F62) -> 0 | L62: =J62+K62 -> 480.75 | M62: =L62+F62 -> 3685.75 | O62: =M62/D62 -> 368.575 | P62: =M62-'INPUT DATA'!L55 -> 0
A63: ='INPUT DATA'!A56 -> 1102 | B63: ='INPUT DATA'!B56 -> PANEL BOARD WITH MAIN BREAKER/BRANCHES, 3 WIRES, 1 NEUTRAL, 50AMP-200AMP | D63: ='INPUT DATA'!C56 -> 1 | E63: ='INPUT DATA'!D56 -> SET | F63: ='INPUT DATA'!F56+'INPUT DATA'!G56+'INPUT DATA'!H56 -> 8168.5 | G63: ='INPUT DATA'!$C$62 -> 0.05 | H63: ='INPUT DATA'!$C$63 -> 0.1 | I63: =H63+G63 -> 0.15 | J63: =I63*F63 -> 1225.275 | K63: ='INPUT DATA'!$C$64*(ABC!J63+ABC!F63) -> 0 | L63: =J63+K63 -> 1225.275 | M63: =L63+F63 -> 9393.775 | O63: =M63/D63 -> 9393.775 | P63: =M63-'INPUT DATA'!L56 -> 0
A64: ='INPUT DATA'!A57 -> 1103(2) | B64: ='INPUT DATA'!B57 -> FLOURESCENT LIGHTING FIXTURE WITH BALLAST/ LIGHT EMITTING DIODE (LED) BULB, 1 BULB | D64: ='INPUT DATA'!C57 -> 40 | E64: ='INPUT DATA'!D57 -> SET | F64: ='INPUT DATA'!F57+'INPUT DATA'!G57+'INPUT DATA'!H57 -> 17820 | G64: ='INPUT DATA'!$C$62 -> 0.05 | H64: ='INPUT DATA'!$C$63 -> 0.1 | I64: =H64+G64 -> 0.15 | J64: =I64*F64 -> 2673 | K64: ='INPUT DATA'!$C$64*(ABC!J64+ABC!F64) -> 0 | L64: =J64+K64 -> 2673 | M64: =L64+F64 -> 20493 | O64: =M64/D64 -> 512.325 | P64: =M64-'INPUT DATA'!L57 -> 0
...

Sheet 800(1) Clearing & Grab
B1: DETAILED UNIT PRICE ANALYSIS
B3: PROJECT NAME: | E3: ='INPUT DATA'!C4 -> PROPOSED ONE STOREY TWO BED ROOM RESIDENTIAL BUILDING
A5: ITEM NO. | B5: Item No./Description: | E5: 800(1) | G5: CLEARING AND GRUBBING
A6: UNIT | B6: Unit of Measurement: | E6: SQ.M.
B7: Output per day: | E7: 500 | G7: SQ.M./DAY
A8: QTY | B8: Quantity: | E8: ='INPUT DATA'!C10 -> 200 | G8: =E6 -> SQ.M.
B10: Designation | K10: No. Person | N10: No. of Days | Q10: Daily Rate | T10: Amount
B12: A. | C12: Labor
A13: DURATION | C13: a. | D13: Construction Foreman/Engineering Assistant | K13: 1 | N13: =E8/E7 -> 0.4 | Q13: 700 | T13: =K13*N13*Q13 -> 280
C14: b. | D14: Laborer | K14: 2 | N14: =N13 -> 0.4 | Q14: 400 | T14: =K14*N14*Q14 -> 320
Y19: Number of Teams:
A20: LABOR | C20: Sub-Total for A | S20: P | T20: =ROUND(SUM(T13:V18),2) -> 600 | Y20: 1
B21: Name and Capacity | K21: No. of Units | N21: No. of Days | Q21: Daily Rate | T21: Amount
B23: B. | C23: Equipment
C24: a. | D24: Dump Truck | K24: 2 | N24: =N14 -> 0.4 | Q24: 10816 | T24: =K24*N24*Q24 -> 8652.8
C25: b. | D25: Payloader | K25: 1 | N25: =N24 -> 0.4 | Q25: 13864 | T25: =K25*N25*Q25 -> 5545.6
C26: c. | D26: Bulldozer | K26: 1 | N26: =N25 -> 0.4 | Q26: 18392 | T26: =K26*N26*Q26 -> 7356.8
A29: EQUIPMENT | C29: Sub-Total for B | S29: P | T29: =ROUND(SUM(T24:V28),2) -> 21555.2
B30: C. | C30: Total (A+B) | T30: =T20+T29 -> 22155.2
B31: D. | C31: Output per day | G31: = | H31: =E7 -> 500 | J31: =G7 -> SQ.M./DAY | AK31: 2Ø 45° bend | AL31: 2Øx2Ø tee | AM31: 4Øx4Ø coupling
B32: Name and Specifications | K32: Quantity | N32: Unit | Q32: Unit Cost | T32: Amount
B34: E. | C34: Materials | AL34: 2
C35: N/A | AM35: 4
AK37: =SUM(AK32:AK35) -> 0 | AL37: =SUM(AL32:AL35) -> 2 | AM37: =SUM(AM32:AM35) -> 4
A46: MATERIAL | C46: Sub-Total for E | S46: P
B47: F. | C47: Direct Cost (C+E) | T47: =T30+T46 -> 22155.2
B48: G. | C48: Overhead, Contingencies & Miscellaneous | N48: ='INPUT DATA'!C62 -> 0.05 | T48: =T47*N48 -> 1107.76
B49: H. | C49: Contractor's Profit (CP) | N49: ='INPUT DATA'!C63 -> 0.1 | T49: =T47*N49 -> 2215.52
B50: I. | C50: Value Added Tax (VAT) | N50: ='INPUT DATA'!C64 -> 0 | T50: =(T47+T48+T49)*N50 -> 0
A51: CHECKING | B51: J. | C51: Total Cost | T51: =SUM(T47:V50) -> 25478.48
A52: ADJUSTED CHECKING | B52: k. | C52: Total Unit Cost | T52: =T51/E8 -> 127.3924

Sheet 800(3)a Ind Remov of Trees
B1: DETAILED UNIT PRICE ANALYSIS
B3: PROJECT NAME: | E3: ='INPUT DATA'!C4 -> PROPOSED ONE STOREY TWO BED ROOM RESIDENTIAL BUILDING
A5: ITEM NO. | B5: Item No./Description: | E5: 800(3)a | G5: INDIVIDUAL REMOVAL OF TREES (UPTO 300MM DIAMETER)
A6: UNIT | B6: Unit of Measurement: | E6: EACH
B7: Output per day: | E7: 8 | G7: EACH/DAY
A8: QTY | B8: Quantity: | E8: ='INPUT DATA'!C11 -> 2 | G8: =E6 -> EACH
B10: Designation | K10: No. Person | N10: No. of Days | Q10: Daily Rate | T10: Amount
B12: A. | C12: Labor
A13: DURATION | C13: a. | D13: Construction Foreman/Engineering Assistant | K13: 1 | N13: =E8/E7 -> 0.25 | Q13: 800 | T13: =K13*N13*Q13 -> 200
C14: b. | D14: Skilled Laborer | K14: 1 | N14: =N13 -> 0.25 | Q14: 600 | T14: =K14*N14*Q14 -> 150
C15: c. | D15: Laborer | K15: 2 | N15: =N14 -> 0.25 | Q15: 400 | T15: =K15*N15*Q15 -> 200
Y19: Number of Teams:
A20: LABOR | C20: Sub-Total for A | S20: P | T20: =ROUND(SUM(T13:V18),2) -> 550 | Y20: 1
B21: Name and Capacity | K21: No. of Units | N21: No. of Days | Q21: Daily Rate | T21: Amount
B23: B. | C23: Equipment
C24: a. | D24: Backhoe | K24: 1 | N24: =0.25*E8 -> 0.5 | Q24: 16599 | T24: =K24*N24*Q24 -> 8299.5
C25: b. | D25: Dump Truck | K25: 1 | N25: =0.17*E8 -> 0.34 | Q25: 10816 | T25: =K25*N25*Q25 -> 3677.44
C26: c. | D26: Chainsaw | K26: 1 | N26: =N25 -> 0.34 | Q26: 600 | T26: =K26*N26*Q26 -> 204
C27: Minor Tools (5% of Labor Cost) | K27: 1 | T27: =0.05*T20 -> 27.5
A30: EQUIPMENT | C30: Sub-Total for B | S30: P | T30: =ROUND(SUM(T25:V29),2) -> 3908.94
B31: C. | C31: Total (A+B) | T31: =T20+T30 -> 4458.94
B32: D. | C32: Output per day | G32: = | H32: =E7 -> 8 | J32: =G7 -> EACH/DAY | AK32: 2Ø 45° bend | AL32: 2Øx2Ø tee | AM32: 4Øx4Ø coupling
B33: Name and Specifications | K33: Quantity | N33: Unit | Q33: Unit Cost | T33: Amount
B35: E. | C35: Materials | AL35: 2
C36: N/A | AM36: 4
AK38: =SUM(AK33:AK36) -> 0 | AL38: =SUM(AL33:AL36) -> 2 | AM38: =SUM(AM33:AM36) -> 4
A47: MATERIAL | C47: Sub-Total for E | S47: P
B48: F. | C48: Direct Cost (C+E) | T48: =T31+T47 -> 4458.94
B49: G. | C49: Overhead, Contingencies & Miscellaneous | N49: ='INPUT DATA'!C62 -> 0.05 | T49: =T48*N49 -> 222.947
B50: H. | C50: Contractor's Profit (CP) | N50: ='INPUT DATA'!C63 -> 0.1 | T50: =T48*N50 -> 445.894
B51: I. | C51: Value Added Tax (VAT) | N51: ='INPUT DATA'!C64 -> 0 | T51: =(T48+T49+T50)*N51 -> 0
A52: CHECKING | B52: J. | C52: Total Cost | T52: =SUM(T48:V51) -> 5127.781
A53: ADJUSTED CHECKING | B53: k. | C53: Total Unit Cost | T53: =T52/E8 -> 2563.8905

Sheet 803(1)a-Struc Exca Common Soil
B1: DETAILED UNIT PRICE ANALYSIS
B3: PROJECT NAME: | E3: ='INPUT DATA'!C4 -> PROPOSED ONE STOREY TWO BED ROOM RESIDENTIAL BUILDING
A5: ITEM NO. | B5: Item No./Description: | E5: 803(1)a | G5: STRUCTURE EXCAVATION (COMMON SOIL) | X5: NO. OF TEAM: | Y5: 1
A6: UNIT | B6: Unit of Measurement: | E6: CU.M.
B7: Output per day: | E7: =20*8*Y5 -> 160 | G7: CU.M./DAY
A8: QTY | B8: Quantity: | E8: ='INPUT DATA'!C12 -> 23 | G8: =E6 -> CU.M.
B10: Designation | K10: No. Person | N10: No. of Days | Q10: Daily Rate | T10: Amount
B12: A. | C12: Labor
A13: DURATION | C13: a. | D13: Construction Foreman/Engineering Assistant | K13: 1 | N13: =E8/E7 -> 0.14375 | Q13: 800 | T13: =K13*N13*Q13 -> 115
C14: b. | D14: Laborer | K14: =3*Y5 -> 3 | N14: =E8/E7 -> 0.14375 | Q14: 400 | T14: =K14*N14*Q14 -> 172.5
A19: LABOR | C19: Sub-Total for A | S19: P | T19: =ROUND(SUM(T13:V14),2) -> 287.5
B20: Name and Capacity | K20: No. of Units | N20: No. of Days | Q20: Daily Rate | T20: Amount
B22: B. | C22: Equipment
C23: a. | D23: Dump Truck | K23: =2*Y5 -> 2 | N23: =N14 -> 0.14375 | Q23: 10816 | T23: =K23*N23*Q23 -> 3109.6
C24: b. | D24: Backhoe | K24: =1*Y5 -> 1 | N24: =N23 -> 0.14375 | Q24: 12296 | T24: =K24*N24*Q24 -> 1767.55
D25: Minor Tools (10%) | T25: =T19*0.1 -> 28.75
A29: EQUIPMENT | C29: Sub-Total for B | S29: P | T29: =ROUND(SUM(T23:V25),2) -> 4905.9
B30: C. | C30: Total (A+B) | T30: =T19+T29 -> 5193.4
B31: D. | C31: Output per day | G31: = | H31: =E7 -> 160 | J31: =G7 -> CU.M./DAY
B32: Name and Specifications | K32: Quantity | N32: Unit | Q32: Unit Cost | T32: Amount
B34: E. | C34: Materials
C35: N.A.
A42: MATERIAL | C42: Sub-Total for E | S42: P
B43: F. | C43: Direct Cost (C+E) | T43: =T30+T42 -> 5193.4
B44: G. | C44: Overhead, Contingencies & Miscellaneous | N44: ='INPUT DATA'!C62 -> 0.05 | T44: =T43*N44 -> 259.67
B45: H. | C45: Contractor's Profit (CP) | N45: ='INPUT DATA'!C63 -> 0.1 | T45: =T43*N45 -> 519.34
B46: I. | C46: Value Added Tax (VAT) | N46: ='INPUT DATA'!C64 -> 0 | T46: =(T43+T44+T45)*N46 -> 0
A47: CHECKING | B47: J. | C47: Total Cost | T47: =SUM(T43:V46) -> 5972.41
A48: ADJUSTED CHECKING | B48: k. | C48: Total Unit Cost | T48: =T47/E8 -> 259.67

Sheet 803(1)a-Struc Exca Soft Rock
B1: DETAILED UNIT PRICE ANALYSIS
B3: PROJECT NAME: | E3: ='INPUT DATA'!C4 -> PROPOSED ONE STOREY TWO BED ROOM RESIDENTIAL BUILDING
A5: ITEM NO. | B5: Item No./Description: | E5: 803(1)a | G5: STRUCTURE EXCAVATION (SOFT ROCK) | X5: NO. OF TEAM: | Y5: 1
A6: UNIT | B6: Unit of Measurement: | E6: CU.M.
B7: Output per day: | E7: =14*8*Y5 -> 112 | G7: CU.M./DAY
A8: QTY | B8: Quantity: | E8: ='INPUT DATA'!C13 -> 0 | G8: =E6 -> CU.M.
B10: Designation | K10: No. Person | N10: No. of Days | Q10: Daily Rate | T10: Amount
B12: A. | C12: Labor
A13: DURATION | C13: a. | D13: Construction Foreman/Engineering Assistant | K13: 1 | N13: =E8/E7 -> 0 | Q13: 800 | T13: =K13*N13*Q13 -> 0
C14: b. | D14: Laborer | K14: =3*Y5 -> 3 | N14: =E8/E7 -> 0 | Q14: 400 | T14: =K14*N14*Q14 -> 0
A19: LABOR | C19: Sub-Total for A | S19: P | T19: =ROUND(SUM(T13:V14),2) -> 0
B20: Name and Capacity | K20: No. of Units | N20: No. of Days | Q20: Daily Rate | T20: Amount
B22: B. | C22: Equipment
C23: a. | D23: Dump Truck | K23: =2*Y5 -> 2 | N23: =N14 -> 0 | Q23: 10816 | T23: =K23*N23*Q23 -> 0
C24: b. | D24: Backhoe | K24: =1*Y5 -> 1 | N24: =0.5*N23 -> 0 | Q24: 12296 | T24: =K24*N24*Q24 -> 0
C25: c. | D25: Backhoe with Breaker | K25: 1 | N25: =N24 -> 0 | Q25: 16599.6 | T25: =K25*N25*Q25 -> 0
D26: Minor Tools (10%) | T26: =T19*0.1 -> 0
A30: EQUIPMENT | C30: Sub-Total for B | S30: P | T30: =ROUND(SUM(T23:V26),2) -> 0
B31: C. | C31: Total (A+B) | T31: =T19+T30 -> 0
B32: D. | C32: Output per day | G32: = | H32: =E7 -> 112 | J32: =G7 -> CU.M./DAY
B33: Name and Specifications | K33: Quantity | N33: Unit | Q33: Unit Cost | T33: Amount
B35: E. | C35: Materials
C36: N.A.
A43: MATERIAL | C43: Sub-Total for E | S43: P
B44: F. | C44: Direct Cost (C+E) | T44: =T31+T43 -> 0
B45: G. | C45: Overhead, Contingencies & Miscellaneous | N45: ='INPUT DATA'!C62 -> 0.05 | T45: =T44*N45 -> 0
B46: H. | C46: Contractor's Profit (CP) | N46: ='INPUT DATA'!C63 -> 0.1 | T46: =T44*N46 -> 0
B47: I. | C47: Value Added Tax (VAT) | N47: ='INPUT DATA'!C64 -> 0 | T47: =(T44+T45+T46)*N47 -> 0
A48: CHECKING | B48: J. | C48: Total Cost | T48: =SUM(T44:V47) -> 0
A49: ADJUSTED CHECKING | B49: k. | C49: Total Unit Cost | T49: =T48/E8 -> #DIV/0!

Sheet 804(4) Gravel Bedding
B1: DETAILED UNIT PRICE ANALYSIS
B3: PROJECT NAME: | E3: ='INPUT DATA'!C4 -> PROPOSED ONE STOREY TWO BED ROOM RESIDENTIAL BUILDING
A5: ITEM NO. | B5: Item No./Description: | E5: 804(4) | G5: GRAVEL BEDDING | X5: NO. OF TEAM: | Y5: 1
A6: UNIT | B6: Unit of Measurement: | E6: CU.M.
B7: Output per day: | E7: =1.2*8*Y5 -> 9.6 | G7: CU.M./DAY
A8: QTY | B8: Quantity: | E8: ='INPUT DATA'!C14 -> 3 | G8: =E6 -> CU.M.
B10: Designation | K10: No. Person | N10: No. of Days | Q10: Daily Rate | T10: Amount
B12: A. | C12: Labor
A13: DURATION | C13: a. | D13: Construction Foreman/Engineering Assistant | K13: 1 | N13: =E8/E7 -> 0.3125 | Q13: 800 | T13: =K13*N13*Q13 -> 250
C14: b. | D14: Laborer | K14: =3*Y5 -> 3 | N14: =E8/E7 -> 0.3125 | Q14: 400 | T14: =K14*N14*Q14 -> 375
A19: LABOR | C19: Sub-Total for A | S19: P | T19: =ROUND(SUM(T13:V14),2) -> 625
B20: Name and Capacity | K20: No. of Units | N20: No. of Days | Q20: Daily Rate | T20: Amount
B22: B. | C22: Equipment
C23: a. | D23: Plate Compactor | K23: =2*Y5 -> 2 | N23: =N14 -> 0.3125 | Q23: 984 | T23: =K23*N23*Q23 -> 615
D24: Minor Tools (10%) | T24: =T19*0.1 -> 62.5
A28: EQUIPMENT | C28: Sub-Total for B | S28: P | T28: =ROUND(SUM(T23:V24),2) -> 677.5
B29: C. | C29: Total (A+B) | T29: =T19+T28 -> 1302.5
B30: D. | C30: Output per day | G30: = | H30: =E7 -> 9.6 | J30: =G7 -> CU.M./DAY
B31: Name and Specifications | K31: Quantity | N31: Unit | Q31: Unit Cost | T31: Amount
B33: E. | C33: Materials
C34: a. | D34: Gravel Bedding | K34: =E8 -> 3 | N34: cu.m. | Q34: 1400 | T34: =Q34*K34 -> 4200
A41: MATERIAL | C41: Sub-Total for E | S41: P | T41: =SUM(T34:V40) -> 4200
B42: F. | C42: Direct Cost (C+E) | T42: =T29+T41 -> 5502.5
B43: G. | C43: Overhead, Contingencies & Miscellaneous | N43: ='INPUT DATA'!C62 -> 0.05 | T43: =T42*N43 -> 275.125
B44: H. | C44: Contractor's Profit (CP) | N44: ='INPUT DATA'!C63 -> 0.1 | T44: =T42*N44 -> 550.25
B45: I. | C45: Value Added Tax (VAT) | N45: ='INPUT DATA'!C64 -> 0 | T45: =(T42+T43+T44)*N45 -> 0
A46: CHECKING | B46: J. | C46: Total Cost | T46: =SUM(T42:V45) -> 6327.875
A47: ADJUSTED CHECKING | B47: k. | C47: Total Unit Cost | T47: =T46/E8 -> 2109.2917

Sheet 902(1)-Reinforced S for 1Storey
B1: DETAILED UNIT PRICE ANALYSIS
B3: PROJECT NAME: | E3: ='INPUT DATA'!C4 -> PROPOSED ONE STOREY TWO BED ROOM RESIDENTIAL BUILDING
A5: ITEM NO. | B5: Item No./Description: | E5: 902(1) | G5: REINFORCING STEEL OF REINFORCED CONCRETE STRUCTURES FOR ONE-STOREY, GRADE 40/60
A6: UNIT | B6: Unit of Measurement: | E6: KGS.
B7: Output per day: | E7: =143.438*8*Y11 -> 1147.504 | G7: KGS./DAY
A8: QTY | B8: Quantity: | E8: ='INPUT DATA'!C15 -> 1200 | G8: =E6 -> KGS.
B10: Designation | K10: No. Person | N10: No. of Days | Q10: Daily Rate | T10: Amount | Y10: NO. OF TEAM
Y11: 1
B12: A. | C12: Labor
A13: DURATION | C13: a. | D13: Construction Foreman/Engineering Assistant | K13: 1 | N13: =E8/E7 -> 1.045748 | Q13: 800 | T13: =K13*N13*Q13 -> 836.59839
C14: b. | D14: Skilled Laborer | K14: 3 | N14: =N13 -> 1.045748 | Q14: 600 | T14: =K14*N14*Q14 -> 1882.3464
C15: b. | D15: Laborer | K15: 12 | N15: =N14 -> 1.045748 | Q15: 400 | T15: =K15*N15*Q15 -> 5019.5903
A17: LABOR | C17: Sub-Total for A | S17: P | T17: =ROUND(SUM(T13:V15),2) -> 7738.54
B18: Name and Capacity | K18: No. of Units | N18: No. of Days | Q18: Daily Rate | T18: Amount
B20: B. | C20: Equipment
C21: a. | D21: Bar Cutter | K21: =Y11 -> 1 | N21: =N13/2 -> 0.52287399 | Q21: 1758 | T21: =K21*N21*Q21 -> 919.21248
C22: b. | D22: Bar Bender | K22: =K21 -> 1 | N22: =N21 -> 0.52287399 | Q22: 2812 | T22: =K22*N22*Q22 -> 1470.3217
C23: c. | D23: Cargo Truck/Hauling Truck | K23: =K22 -> 1 | N23: =N15*0.15 -> 0.1568622 | Q23: 8816 | T23: =K23*N23*Q23 -> 1382.8971
A26: EQUIPMENT | C26: Sub-Total for B | S26: P | T26: =ROUND(SUM(T21:V25),2) -> 3772.43
B27: C. | C27: Total (A+B) | T27: =T17+T26 -> 11510.97
B28: D. | C28: Output per day | G28: = | H28: =E7 -> 1147.504 | J28: =G7 -> KGS./DAY
B29: Name and Specifications | K29: Quantity | N29: Unit | Q29: Unit Cost | T29: Amount
B31: E. | C31: Materials
C32: a. | D32: Deformed Reinforcing Steel Bar (Grade 40) | K32: =E8 -> 1200 | N32: =IF(K32>1,"kgs.","kg.") -> kgs. | Q32: 75 | T32: =K32*Q32 -> 90000
C33: b. | D33: #16 G.I. Tie-wire | K33: =E8*0.015 -> 18 | N33: =IF(K33>1,"kgs.","kg.") -> kgs. | Q33: 90 | T33: =K33*Q33 -> 1620
D34: Consumables (5% of Materials Cost) | T34: =0.05*SUM(T32:V33) -> 4581
A38: MATERIAL | C38: Sub-Total for E | S38: P | T38: =ROUND(SUM(T32:V37),2) -> 96201
B39: F. | C39: Direct Cost (C+E) | T39: =T27+T38 -> 107711.97
B40: G. | C40: Overhead, Contingencies & Miscellaneous | N40: ='INPUT DATA'!C62 -> 0.05 | T40: =T39*N40 -> 5385.5985
B41: H. | C41: Contractor's Profit (CP) | N41: ='INPUT DATA'!C63 -> 0.1 | T41: =T39*N41 -> 10771.197
B42: I. | C42: Value Added Tax (VAT) | N42: ='INPUT DATA'!C64 -> 0 | T42: =(T39+T40+T41)*N42 -> 0
A43: CHECKING | B43: J. | C43: Total Cost | T43: =SUM(T39:V42) -> 123868.77
A44: ADJUSTED CHECKING | B44: k. | C44: Total Unit Cost | T44: =T43/E8 -> 103.22397
F49: Input here the quantity of Steel Bars:
K50: Unit Wt. | M50: Total kgs
C51: *25mmØ x 6.00m Deformed Reinforcing Steel Bar | J51: 1 | K51: 3.855 | M51: =J51*K51*6 -> 23.13
C52: *20mmØ x 6.00m Deformed Reinforcing Steel Bar | J52: 1 | K52: 2.467 | M52: =J52*K52*6 -> 14.802
C53: *16mmØ x 6.00m Deformed Reinforcing Steel Bar | J53: 1 | K53: 1.579 | M53: =J53*K53*6 -> 9.474
C54: *12mmØ x 6.00m Deformed Reinforcing Steel Bar | J54: 1 | K54: 0.888 | M54: =J54*K54*6 -> 5.328
C55: *10mmØ x 6.00m Deformed Reinforcing Steel Bar | J55: 1 | K55: 0.616 | M55: =J55*K55*6 -> 3.696
...

Sheet 902(1)-Rein St for 2-5storey
B1: DETAILED UNIT PRICE ANALYSIS
B3: PROJECT NAME: | E3: ='INPUT DATA'!C4 -> PROPOSED ONE STOREY TWO BED ROOM RESIDENTIAL BUILDING
A5: ITEM NO. | B5: Item No./Description: | E5: 902(1) | G5: REINFORCING STEEL OF REINFORCED CONCRETE STRUCTURES FOR TWO UPTO FIVE STOREY
A6: UNIT | B6: Unit of Measurement: | E6: KGS.
B7: Output per day: | E7: =129.094*8*Y11 -> 1032.752 | G7: KGS./DAY
A8: QTY | B8: Quantity: | E8: ='INPUT DATA'!C16 -> 50 | G8: =E6 -> KGS.
B10: Designation | K10: No. Person | N10: No. of Days | Q10: Daily Rate | T10: Amount | Y10: NO. OF TEAM
Y11: 1
B12: A. | C12: Labor
A13: DURATION | C13: a. | D13: Construction Foreman/Engineering Assistant | K13: 1 | N13: =E8/E7 -> 0.048414334 | Q13: 800 | T13: =K13*N13*Q13 -> 38.731467
C14: b. | D14: Skilled Laborer | K14: 3 | N14: =N13 -> 0.048414334 | Q14: 600 | T14: =K14*N14*Q14 -> 87.145801
C15: b. | D15: Laborer | K15: 12 | N15: =N14 -> 0.048414334 | Q15: 400 | T15: =K15*N15*Q15 -> 232.3888
A17: LABOR | C17: Sub-Total for A | S17: P | T17: =ROUND(SUM(T13:V15),2) -> 358.27
B18: Name and Capacity | K18: No. of Units | N18: No. of Days | Q18: Daily Rate | T18: Amount
B20: B. | C20: Equipment
C21: a. | D21: Bar Cutter | K21: =Y11 -> 1 | N21: =N13/2 -> 0.024207167 | Q21: 1758 | T21: =K21*N21*Q21 -> 42.556199
C22: b. | D22: Bar Bender | K22: =K21 -> 1 | N22: =N21 -> 0.024207167 | Q22: 2812 | T22: =K22*N22*Q22 -> 68.070553
C23: Minor Tools (10% of Labor Cost) | T23: =0.1*T17 -> 35.827
A26: EQUIPMENT | C26: Sub-Total for B | S26: P | T26: =ROUND(SUM(T21:V25),2) -> 146.45
B27: C. | C27: Total (A+B) | T27: =T17+T26 -> 504.72
B28: D. | C28: Output per day | G28: = | H28: =E7 -> 1032.752 | J28: =G7 -> KGS./DAY
B29: Name and Specifications | K29: Quantity | N29: Unit | Q29: Unit Cost | T29: Amount
B31: E. | C31: Materials
C32: a. | D32: Deformed Reinforcing Steel Bar (Grade 40) | K32: =E8 -> 50 | N32: =IF(K32>1,"kgs.","kg.") -> kgs. | Q32: 75 | T32: =K32*Q32 -> 3750
C33: b. | D33: #16 G.I. Tie-wire | K33: =E8*0.015 -> 0.75 | N33: =IF(K33>1,"kgs.","kg.") -> kg. | Q33: 90 | T33: =K33*Q33 -> 67.5
D34: Consumables (5% of Materials Cost) | T34: =0.05*SUM(T32:V33) -> 190.875
A38: MATERIAL | C38: Sub-Total for E | S38: P | T38: =ROUND(SUM(T32:V37),2) -> 4008.38
B39: F. | C39: Direct Cost (C+E) | T39: =T27+T38 -> 4513.1
B40: G. | C40: Overhead, Contingencies & Miscellaneous | N40: ='INPUT DATA'!C62 -> 0.05 | T40: =T39*N40 -> 225.655
B41: H. | C41: Contractor's Profit (CP) | N41: ='INPUT DATA'!C63 -> 0.1 | T41: =T39*N41 -> 451.31
B42: I. | C42: Value Added Tax (VAT) | N42: ='INPUT DATA'!C64 -> 0 | T42: =(T39+T40+T41)*N42 -> 0
A43: CHECKING | B43: J. | C43: Total Cost | T43: =SUM(T39:V42) -> 5190.065
A44: ADJUSTED CHECKING | B44: k. | C44: Total Unit Cost | T44: =T43/E8 -> 103.8013
F49: Input here the quantity of Steel Bars:
K50: Unit Wt. | M50: Total kgs
C51: *25mmØ x 6.00m Deformed Reinforcing Steel Bar | J51: 1 | K51: 3.855 | M51: =J51*K51*6 -> 23.13
C52: *20mmØ x 6.00m Deformed Reinforcing Steel Bar | J52: 1 | K52: 2.467 | M52: =J52*K52*6 -> 14.802
C53: *16mmØ x 6.00m Deformed Reinforcing Steel Bar | J53: 1 | K53: 1.579 | M53: =J53*K53*6 -> 9.474
C54: *12mmØ x 6.00m Deformed Reinforcing Steel Bar | J54: 1 | K54: 0.888 | M54: =J54*K54*6 -> 5.328
C55: *10mmØ x 6.00m Deformed Reinforcing Steel Bar | J55: 1 | K55: 0.616 | M55: =J55*K55*6 -> 3.696
...

Sheet 900(1)c2 Struc Con for footing
B1: DETAILED UNIT PRICE ANALYSIS
B3: PROJECT NAME: | E3: ='INPUT DATA'!C4 -> PROPOSED ONE STOREY TWO BED ROOM RESIDENTIAL BUILDING
A5: ITEM NO. | B5: Item No./Description: | E5: 900(1)c2 | G5: STRUCTURAL CONCRETE FOR FOOTING AND SLAB ON FILL (CLASS A, 28 DAYS)
A6: UNIT | B6: Unit of Measurement: | E6: CU.M.
B7: Output per day: | E7: =0.357*8*Y11 -> 2.856 | G7: CU.M./DAY
A8: QTY | B8: Quantity: | E8: ='INPUT DATA'!C17 -> 12.4 | G8: =E6 -> CU.M.
B10: Designation | K10: No. Person | N10: No. of Days | Q10: Daily Rate | T10: Amount | Y10: NO. OF TEAM
Y11: 1
B12: A. | C12: Labor
C13: Concrete Pouring Works
A14: DURATION | C14: a. | D14: Construction Foreman/Engineering Assistant | K14: 1 | N14: =E8/E7 -> 4.3417367 | Q14: 800 | T14: =K14*N14*Q14 -> 3473.3894
C15: b. | D15: Skilled Laborer | K15: 1 | N15: =N14 -> 4.3417367 | Q15: 600 | T15: =K15*N15*Q15 -> 2605.042
C16: c. | D16: Laborer | K16: 4 | N16: =N15 -> 4.3417367 | Q16: 400 | T16: =K16*N16*Q16 -> 6946.7787
A21: LABOR | C21: Sub-Total for A | S21: P | T21: =ROUND(SUM(T13:V19),2) -> 13025.21
B22: Name and Capacity | K22: No. of Units | N22: No. of Days | Q22: Daily Rate | T22: Amount
B24: B. | C24: Equipment
C25: a. | D25: One Bagger Mixer | K25: =Y11 -> 1 | N25: =N14 -> 4.3417367 | Q25: 1376 | T25: =K25*N25*Q25 -> 5974.2297
C26: Minor Tools (10% of Labor Cost) | T26: =0.1*T21 -> 1302.521
A30: EQUIPMENT | C30: Sub-Total for B | S30: P | T30: =ROUND(SUM(T25:V29),2) -> 7276.75
B31: C. | C31: Total (A+B) | T31: =T21+T30 -> 20301.96
B32: D. | C32: Output per day | G32: = | H32: =E7 -> 2.856 | J32: =G7 -> CU.M./DAY
B33: Name and Specifications | K33: Quantity | N33: Unit | Q33: Unit Cost | T33: Amount
B35: E. | C35: Materials
